Workbook

Sheet Resumen
B2: Resumen de Ponderacion y Horas
B4: Curso | C4: 785 - Análisis y Diseño de Sistemas 2
B5: Semestre que aplica | C5: Segundo Semestre 2026
B6: Total de Puntos del Laboratorio
A8: * Esta sección se auto completa al momento en que se llene a la información de la planificación
A9: ** Tomar como base la distribución realizada por el coordinador del area del curso en el documento de criterios y expectativas
A10: Tipo de Actividad | B10: Ponderacion | C10: Horas utilizadas | D10: Aspectos clave que debe abordar | G10: Valor Maximo Recomendado
A11: Actividades durante el peridodo de laboratorio | B11: 10 | C11: 6 | G11: 10
A12: Proyectos | B12: 60 | C12: =Proyectos!C5 -> 155 | G12: 60
A13: Prácticas | B13: 20 | C13: =Practicas!C5 -> 40 | G13: 20
A14: Tareas | B14: 10 | C14: =Tareas!C5 -> 5 | G14: 10
A15: Total | B15: =SUM(B11:B14) -> 100 | C15: =SUM(C11:C14) -> 206 | D15: Validacion | E15: =IFERROR(__xludf.DUMMYFUNCTION("LET( nombres,A11:A14, p,B11:B14, m,G11:G14, t,SUM(p), exceden, IFERROR(TEXTJOIN(""; "", TRUE, FILTER(nombres&"" (""&p&"">""&m&"")"", p>m)), """"), negs, IF(COUNTIF(p,""<0"")>0, ""Hay valores negativos"", """"), totalmsg, IF(t<>100, ""Total ≠"&" 100 (actual ""&t&"")"", """"), excesomsg, IF(exceden<>"""", ""Exceden: ""&exceden, """"), msg, TEXTJOIN("" | "", TRUE, totalmsg, negs, excesomsg), IF(msg="""", ""✅ Distribución válida"", ""❌ Revisar: ""&msg) )"),"✅ Distribución válida") -> ✅ Distribución válida

Sheet Competencias
B1: Competencias que se formaran en el Segundo Semestre 2026
B2: Curso | C2: 785 - Análisis y Diseño de Sistemas 2
B3: Semestre que aplica | C3: Segundo Semestre 2026
B5: Competencias relacionadas al perfil del egresado (Especifica) | I5: Competencias relacionadas al perfil del egresado (General)
B6: 1 | C6: Aplica los conocimientos de su disciplina en la elaboración, fundamentación y defensa de argumentos para prevenir y resolver problemas complejos en su campo profesional, identificando y aplicando innovaciones. | I6: 1 | J6: Aplica estándares de calidad, eficiencia y seguridad en la implementación adecuada de soluciones de software, hardware y TIC en general.
B7: 2 | C7: Toma decisiones profesionales con base en fundamentos teóricos, datos e información pertinente, válida y confiable. | I7: 2 | J7: Construye soluciones integrales trabajando en forma colaborativa y propositiva en equipos interdisciplinarios, en forma presencial o utilizando plataformas virtuales.
B8: 3 | C8: Demuestra destreza y habilidad en la selección, uso y adaptación de herramientas metodológicas, tecnológicas, equipos especializados y en la lectura e interpretación de datos, pertinentes al contexto de su ejercicio profesional. | I8: 3 | J8: Aplica principios básicos de ingeniería, ciencias de computación y sistemas de información y comunicación, en la formulación y resolución adecuada de problemas complejos.
B11: No | C11: Tipo | D11: Verbo en Presente | E11: Objeto de la acción | G11: [Palabras conectoreas] Herramientas o metodología | H11: [Palabras conectoreas] Condiciones específicas | J11: Nivel
B12: 1 | C12: Especifica | D12: Define | E12: conceptos de frameworks de desarrollo | G12: por medio de especificaciones técnicas | H12: para proporcionar un entendimiento preciso de su estructura, componentes y funcionamiento | J12: Comprender
C13: Define conceptos de frameworks de desarrollo por medio de especificaciones técnicas para proporcionar un entendimiento preciso de su estructura, componentes y funcionamiento.
B14: 2 | C14: Especifica | D14: Identifica | E14: patrones de diseño | G14: por medio del análisis de las diferentes necesidades | H14: para resolver un problema específico que se adapta a la solución propuesta por el patrón seleccionado. | J14: Comprender
C15: =D14 & " " & E14 & " " &G14& " " &H14& " " -> Identifica patrones de diseño por medio del análisis de las diferentes necesidades para resolver un problema específico que se adapta a la solución propuesta por el patrón seleccionado.
B16: 3 | C16: Especifica | D16: Integra | E16: catalogos de estilo | G16: mediante aspectos relacionados con la identidad de la marca u organización | H16: para crear interfaces adecuadas dentro del sistema. | J16: Aplicar
C17: =D16 & " " & E16 & " " &G16& " " &H16& " " -> Integra catalogos de estilo mediante aspectos relacionados con la identidad de la marca u organización para crear interfaces adecuadas dentro del sistema.
B18: 4 | C18: Especifica | D18: Organiza | E18: la información del sistema | G18: mediante esquemas jerárquicos y categorizados | H18: para facilitar la navegación y la comprensión por parte del usuario. | J18: Analizar
C19: =D18 & " " & E18 & " " &G18& " " &H18& " " -> Organiza la información del sistema mediante esquemas jerárquicos y categorizados para facilitar la navegación y la comprensión por parte del usuario.
B20: 5 | C20: Especifica | D20: Diseña | E20: arquitecturas de software | G20: mediante la definición de componentes, conexiones y capas del sistema | H20: para asegurar la funcionalidad, rendimiento y escalabilidad del producto final | J20: Analizar
C21: =D20 & " " & E20 & " " &G20& " " &H20& " " -> Diseña arquitecturas de software mediante la definición de componentes, conexiones y capas del sistema para asegurar la funcionalidad, rendimiento y escalabilidad del producto final
B22: 6 | C22: General | D22: Aplica | E22: principios y técnicas de análisis y diseño de sistemas | G22: mediante metodologías, modelos y herramientas de ingeniería de software | H22: para desarrollar sistemas eficientes, mantenibles y alineados con los requisitos del usuario | J22: Aplicar
C23: =D22 & " " & E22 & " " &G22& " " &H22& " " -> Aplica principios y técnicas de análisis y diseño de sistemas mediante metodologías, modelos y herramientas de ingeniería de software para desarrollar sistemas eficientes, mantenibles y alineados con los requisitos del usuario
B24: 7 | C24: General | D24: Recuerda | E24: la importancia de las decisiones de diseño y arquitectura | G24: mediante el análisis de casos prácticos y ejemplos de sistemas reales | H24: para fortalecer la capacidad de aplicar soluciones coherentes y efectivas en proyectos de software | J24: Recordar
C25: =D24 & " " & E24 & " " &G24& " " &H24& " " -> Recuerda la importancia de las decisiones de diseño y arquitectura mediante el análisis de casos prácticos y ejemplos de sistemas reales para fortalecer la capacidad de aplicar soluciones coherentes y efectivas en proyectos de software | L25: Manual de competencias: https://drive.google.com/file/d/1n5es0M20vXxa7i4eLN7pbgTXc2C1dmCQ/view?usp=sharing
L26: Video de como hacer competencias: https://youtu.be/C8Q9dKo4t-w?si=yErgF_ihe1tsaHM0
B28: Si las competencias son las misma que el semetre anterior compartenos tu opinion de porque no se cambiaron

Sheet Diseño
B2: Diseño de Contenido Curricular
B4: Curso | C4: 785 - Análisis y Diseño de Sistemas 2
B5: semestre que aplica | C5: Segundo Semestre 2026
B8: No. | C8: Competencia | D8: Nombre de la Unidad | E8: Tema | F8: Subtema | G8: Mes | H8: Semana
B9: 1 | C9: Identifica patrones de diseño por medio del análisis de las diferentes necesidades para resolver un problema específico que se adapta a la solución propuesta por el patrón seleccionado. | D9: Patrones de diseño | E9: Elementos de diseño | F9: Patrones de diseño | G9: Julio | H9: 2
B10: 2 | C10: Identifica patrones de diseño por medio del análisis de las diferentes necesidades para resolver un problema específico que se adapta a la solución propuesta por el patrón seleccionado. | D10: Patrones de diseño | E10: Elementos de diseño | F10: Definición de patrones de diseño | G10: Julio | H10: 2
B11: 3 | C11: Identifica patrones de diseño por medio del análisis de las diferentes necesidades para resolver un problema específico que se adapta a la solución propuesta por el patrón seleccionado. | D11: Patrones de diseño | E11: Elementos de diseño | F11: Importancia y Aplicabilidad de Patrones de diseño | G11: Julio | H11: 2
B12: 4 | C12: Identifica patrones de diseño por medio del análisis de las diferentes necesidades para resolver un problema específico que se adapta a la solución propuesta por el patrón seleccionado. | D12: Patrones de diseño | E12: Elementos de diseño | F12: Notaciones de patrones de diseño | G12: Julio | H12: 2
B13: 5 | C13: Identifica patrones de diseño por medio del análisis de las diferentes necesidades para resolver un problema específico que se adapta a la solución propuesta por el patrón seleccionado. | D13: Patrones de diseño | E13: Elementos de diseño | F13: Contexto de diseño | G13: Julio | H13: 2
B14: 6 | C14: Identifica patrones de diseño por medio del análisis de las diferentes necesidades para resolver un problema específico que se adapta a la solución propuesta por el patrón seleccionado. | D14: Patrones de diseño | E14: Elementos de diseño | F14: Principios de diseño de software | G14: Julio | H14: 2
B15: 7 | C15: Identifica patrones de diseño por medio del análisis de las diferentes necesidades para resolver un problema específico que se adapta a la solución propuesta por el patrón seleccionado. | D15: Patrones de diseño | E15: Elementos de diseño | F15: Creacional | G15: Agosto | H15: 3
B16: 8 | C16: Identifica patrones de diseño por medio del análisis de las diferentes necesidades para resolver un problema específico que se adapta a la solución propuesta por el patrón seleccionado. | D16: Patrones de diseño | E16: Elementos de diseño | F16: Factory Method | G16: Agosto | H16: 3
B17: 9 | C17: Identifica patrones de diseño por medio del análisis de las diferentes necesidades para resolver un problema específico que se adapta a la solución propuesta por el patrón seleccionado. | D17: Patrones de diseño | E17: Elementos de diseño | F17: Abstact Factory | G17: Agosto | H17: 3
B18: 10 | C18: Identifica patrones de diseño por medio del análisis de las diferentes necesidades para resolver un problema específico que se adapta a la solución propuesta por el patrón seleccionado. | D18: Patrones de diseño | E18: Elementos de diseño | F18: Singleton | G18: Agosto | H18: 3
B19: 11 | C19: Identifica patrones de diseño por medio del análisis de las diferentes necesidades para resolver un problema específico que se adapta a la solución propuesta por el patrón seleccionado. | D19: Patrones de diseño | E19: Elementos de diseño | F19: Creacional | G19: Agosto | H19: 3
B20: 12 | C20: Identifica patrones de diseño por medio del análisis de las diferentes necesidades para resolver un problema específico que se adapta a la solución propuesta por el patrón seleccionado. | D20: Patrones de diseño | E20: Elementos de diseño | F20: Builder | G20: Agosto | H20: 3
... B67: 59 | C67: Recuerda la importancia de las decisiones de diseño y arquitectura mediante el análisis de casos prácticos y ejemplos de sistemas reales para fortalecer la capacidad de aplicar soluciones coherentes y efectivas en proyectos de software | D67: Despliegue en la nube (Cloud) | E67: Despligue en la nube (cloud) | F67: Ansible Playbooks y Roles para Automatización Compleja | G67: Octubre | H67: 11

Sheet Semana Diagnostico
B2: Diseño de Contenido Curricular
B4: Curso | C4: ='Diseño'!C4 -> 785 - Análisis y Diseño de Sistemas 2
B5: Semana | C5: 1
B6: Tiempo | C6: =B15+B22+B29+B41+B47+C48 -> 106
K8: Estos puntos son recomendaciones de los puntos a tratar durante tu presentacion, si no usaras estos eres libre de agregar mas filas para indicar que haras. En los recuadros de la derecha colocar breve resumen de lo que planeas decir. No debes ser muy especifico seran pequeñas anotaciones que te ayudaran a recordar lo que planeaste
A9: 1. Bienvenida y Presentación | G9: Tiempo Aproximado | H9: =B15 -> 15
G10: No puedes excederte mas de 15 minutos
A11: Nombre y Formacion Academica | B11: En este punto los tutores se presentarán indicando su nombre completo y semestre en el que se encuentran
A12: Experiencia docente y profecional | B12: Aquí se especificará la experiencia laboral que se tiene, indicando la relación que tiene con el curso y cual ha sido su experiencia como docente del curso actual.
A13: Rol del auxiliar dentro del curso (funciones, actividades y apoyo a los estudiantes). | B13: Ayudar a los estudiantes a entender cada uno de los temas que se darán en el laboraotiro, se tendrán 2 prácticas y 1 proyecto de 3 fases, el apoyo será a traves de foro y cuando se requerira se podrá tener sesiones personalizadas
A14: Expectativas sobre la dinámica del curso | B14: Participación Activa: "Espero una participación activa de todos. El curso se basará en el diálogo, no solo en la escucha. Pregunten, compartan y debatan sus ideas." Ambiente de Aprendizaje Mutuo: "Quiero que construyamos un ambiente de respeto y confianza donde todos nos sintamos cómodos al cometer errores y aprender unos de otros. Su experiencia es tan valiosa como el material." Colaboración en Equipo: "Las actividades prácticas y proyectos requerirán trabajo en equipo. Espero una distribución equitativa de las tareas y el desarrollo de habilidades de colaboración."
A15: Tiempo que emplearas | B15: 15
A18: 2. Evaluación de Conocimientos Previos | G18: Tiempo Aproximado | H18: =B22 -> 25
G19: No puedes excederte mas de 45 minutos | K19: En los recuadors de la derecha deberas colocar las preguntas que planeas realizar con sus respectivas respuestas. En el segundo recuadro deberas colocar un breve resumne de lo que tines planificado para la parte practica del curso previo al que estas impartiendo.
A20: Redactaras de 15 a 20 preguntas con sus respectivas respuestas , por lo que debes escoge los temas que evaluaras | B20: 1. ¿La ingeniería de software es la disciplina que aplica principios de ingeniería para el desarrollo, mantenimiento y gestión de software de forma sistemática y eficiente? Verdadero 2. Es un conjunto estructurado de prácticas, procesos y reglas que guían cómo se planifica, desarrolla, prueba y mantiene un software. Metodología de desarrollo 3. Es un modelo de desarrollo de software: Modelo ágil 4. Las metodologías ágiles se centran en la documentación de los requerimientos, por sobre las entregas rápidas y flexibles. Falso 5. ¿Cuáles son las cuatro fases principales del modelo RUP? Inicio, Elaboración, Construcción, Transición 6. Parte del desarrollo de software que identifica, analiza, documenta y gestiona lo que debe hacer un producto de software. Ingeniería de requerimientos 7. Técnica utilizada por la metodología Extreme Programming Pair Programming 8. La metodología Kanban se caracteriza por Uso de tarjetas visuales y columnas de estados. 9. Representa todo lo que el proyecto debe entregar Alcance 10. No es una característica de un buen objetivo de software. Rentable
A21: Redactaras una parte practica para realizar la evaluacion de conocimientos previos | B21: -
A22: Tiempo que emplearas | B22: 25
A25: 3. Presentación de los Estudiantes | G25: Tiempo Aproximado | H25: =B29 -> 10
G26: No puedes excederte mas de 30 minutos
A27: Seleccion al Azar de 5 Estudiantes | B27: Selección de 5 estudiantes mediante una ruleta en la herramienta online Wooclap, se tomará como fuente las respuestas del formulario de asistencia | K27: En el primer recuadro colocaras la metodollogia que adoptaras para la eleccion de los estudiantes. En el segundo recuadro colocaras la redaccion de las preguntas que comprendan los siguientes puntos respecto al estudiante: Nombre. Intereses y expectativas sobre el curso. Experiencia previa relacionada con el curso (si aplica). Un dato curioso sobre sí mismo. Consideras que la prueba de conociminetos previos esta acorde al conocimiento que se te brindo en su momento Que tan comodo se sintio con la prueba anterior.
A28: Indica las preguntas que responderan los estudiantes afortunados | B28: Nombre completo Espectativas del curso Experiencia con temas del curso Algún dato acerca de su persona
A29: Tiempo que emplearas | B29: 10
A32: 4. Senso de Horarios de Calificación | G32: Tiempo Aproximado | H32: =B36 -> 0
A33: Deberas estar recordando que deben contestar el formulario asi mismo dejar el link fijado en la llamada | G33: Esta actividad quedara abierta hasta el fin de la clase. pero emplearas 5 min especificos para la actividad
A34: Link de google forms donde este el cuestionario | B34: NO APLICA | K34: Esta actividad te ayudara a realizar un senso de posibles horarios de calificacion y que tus estudiantes esten enterados y puedan preveer los dias de calificacion y asi mismo el horario. Deberas colocar en los reacuadros de la derecha link de Google form libre para correos intitucionales, esto para garantizar una sola respuesta por estudiante. TAmbien deberas colocar los posibles horarios y dias que tentativamente tendrias disponibles. para colocarlos en el google form.
A35: Dias y posibles Horarios de calificacion | B35: Sábados
A36: Tiempo que emplearas | B36: 0
A39: 5. Mostrar Programa del Curso | G39: Tiempo Aproximado | H39: =B41 -> 41
G40: No puedes excederte mas de 30 minutos
A41: Tiempo que emplearas | B41: 41
A44: 6. Evaluación de Conocimientos del Curso Actual | G44: Tiempo Aproximado | H44: =B46 -> 1. Es un framework de desarrollo Angular 2. No es un tipo de patrón de diseño Inspiracional 3. Representa principios fundamentales de diseño orientado a objetos SOLID 4. ¿Los patrones de diseño son técnicas para resolver problemas recurrentes de diseño de software? Verdadero 5. ¿Qué es el diseño UX? Diseño de experiencia de usuario 6. ¿El diseño UI se enfoca en el despliegue en la nube? Falso 7. Ventaja de realizar pruebas de software Garantizar la calidad del software 8. Las pruebas funcionales se centran en aspectos como el rendimiento, seguridad, usabilidad, etc. Falso 9. Es una prueba no funcional Prueba de carga 10. ¿Qué equipos involucra DevOps? Desarrollo y operaciones
G45: No puedes excederte mas de 15 minutos
A46: Redactaras 20 preguntas con sus respectivas respuestas | B46: 1. Es un framework de desarrollo Angular 2. No es un tipo de patrón de diseño Inspiracional 3. Representa principios fundamentales de diseño orientado a objetos SOLID 4. ¿Los patrones de diseño son técnicas para resolver problemas recurrentes de diseño de software? Verdadero 5. ¿Qué es el diseño UX? Diseño de experiencia de usuario 6. ¿El diseño UI se enfoca en el despliegue en la nube? Falso 7. Ventaja de realizar pruebas de software Garantizar la calidad del software 8. Las pruebas funcionales se centran en aspectos como el rendimiento, seguridad, usabilidad, etc. Falso 9. Es una prueba no funcional Prueba de carga 10. ¿Qué equipos involucra DevOps? Desarrollo y operaciones
A47: Tiempo que emplearas | B47: 15

Sheet S.2
B2: Diseño de la Sesión de Laboratorio
B4: Curso | C4: ='Diseño'!C4 -> 785 - Análisis y Diseño de Sistemas 2
B5: Semana | C5: 2
B6: Tiempo | C6: =H10+H21+H44+H68 -> 100
B7: Ponderación | C7: =B49+B60 -> 1
B8: Validación de Tiempo | C8: =IF(H44<=0, "❌ ERROR: La Actividad 1 debe tener un tiempo mayor a 0.", IF(H21>60, "❌ ERROR: El 'Área de Conocimiento' no puede exceder los 60 min.", IF((H10+H21+H44+H68)<100, "❌ ERROR: El tiempo total debe ser de al menos 100 min.", "✅ VALIDACIÓN CORRECTA"))) -> ✅ VALIDACIÓN CORRECTA
A10: 1. Área Actitudinal (Saber Ser) | G10: Tiempo Aproximado | H10: =B13 -> 5
G11: Tiene que estar en un rango de 3 a 5 minutos
A12: Nombre del Valor | B12: Compromiso
A13: Tiempo Aproximado | B13: 5
A14: Descripcion
A15: El compromiso permite al estudiante asumir con seriedad el diseño de soluciones eficientes y sostenibles, entendiendo que la correcta aplicación de patrones y principios de diseño impacta directamente en la calidad del software. Diseñar bien no solo es una habilidad técnica, sino una muestra de responsabilidad profesional con los usuarios, el equipo y el producto final.
A17: Como se relaciona con los conocimientos de la sesion y se aplicaria
A18: La dinámica del curso y el compromiso del estudiante se aplicarán directamente en el Análisis y la Justificación de los Patrones de Diseño.
A21: 2. Área Conocimiento (Saber) | G21: Tiempo Aproximado | H21: 60
G22: No puede exceder los 60 minutos
A23: Competencia a desarrollar | B23: Identifica y describe conceptos de frameworks aplicando casos de uso y características comunes para seleccionar adecuadamente un framework de acuerdo al proyecto.
A24: Competencia a desarrollar
A26: 2.1 Contenido
A27: No. | B27: Unidad | D27: Tema | F27: Sub Tema
A28: 1 | B28: 2. Patrones de Diseño | D28: Elementos de diseño | F28: Patrones de diseño
A29: 2 | B29: 2. Patrones de Diseño | D29: Elementos de diseño | F29: Definición de patrones de diseño
A30: 3 | B30: 2. Patrones de Diseño | D30: Elementos de diseño | F30: Importancia y Aplicabilidad de Patrones de diseño
A31: 4 | B31: 2. Patrones de Diseño | D31: Elementos de diseño | F31: Notaciones de patrones de diseño
A32: 5 | B32: 2. Patrones de Diseño | D32: Elementos de diseño | F32: Contexto de diseño
A33: 6 | B33: 2. Patrones de Diseño | D33: Elementos de diseño | F33: Principios de diseño de software
A34: 7
A36: 2.2 Recursos Educativos
A38: Tipo de Recurso a utilizar | B38: Tipo | C38: Valor maximo recomendado en Minutos | D38: Tiempo Aproximado ( unicamente el valor de minutos ) | I38: Validacion
A39: Presentacion | B39: Obligatorio | C39: 30 | D39: 35 | I39: =IF(D39<=C39,"Correcto", "Corregir") -> Corregir
A40: Video | B40: Obligatorio | C40: 6 | D40: 6 | I40: =IF(D40<=C40,"Correcto", "Corregir") -> Correcto
A41: Lectura | B41: Optativo | C41: 10 | D41: 0 | I41: =IF(D41<=C41,"Correcto", "Corregir") -> Correcto
A42: Ejercicio Demostrativo | B42: Obligatorio | C42: 30 | D42: 30 | I42: =IF(D42<=C42,"Correcto", "Corregir") -> Correcto
A44: 3. Área de Habilidades (Saber Hacer) | G44: Tiempo Aproximado | H44: =B50 -> 30
G45: Tiene que estar en un rango de 30 a 50 minutos
A46: Actividad 1 (Obligatoria)
A47: Competencia que predomina en la actividad | B47: Define conceptos de frameworks de desarrollo por medio de especificaciones técnicas para proporcionar un entendimiento preciso de su estructura, componentes y funcionamiento.
A48: Tipo de Actividad | B48: actividades
A49: Ponderación | B49: 1
A50: Tiempo Aproximado | B50: 30
...

Sheet S.3
B2: Diseño de la Sesión de Laboratorio
B4: Curso | C4: ='Diseño'!C4 -> 785 - Análisis y Diseño de Sistemas 2
B5: Semana | C5: 3
B6: Tiempo | C6: =H10+H21+H44+H68 -> 100
B7: Ponderación | C7: =B49+B60 -> 1
B8: Validación de Tiempo | C8: =IF(H44<=0, "❌ ERROR: La Actividad 1 debe tener un tiempo mayor a 0.", IF(H21>60, "❌ ERROR: El 'Área de Conocimiento' no puede exceder los 60 min.", IF((H10+H21+H44+H68)<100, "❌ ERROR: El tiempo total debe ser de al menos 100 min.", "✅ VALIDACIÓN CORRECTA"))) -> ✅ VALIDACIÓN CORRECTA
A10: 1. Área Actitudinal (Saber Ser) | G10: Tiempo Aproximado | H10: =B13 -> 5
G11: Tiene que estar en un rango de 3 a 5 minutos
A12: Nombre del Valor | B12: Responsabilidad
A13: Tiempo Aproximado | B13: 5
A14: Descripcion
A15: La responsabilidad implica cumplir compromisos, asumir consecuencias de acciones propias y actuar con ética, compromiso y conciencia, garantizando confianza y respeto en todos los ámbitos.
A17: Como se relaciona con los conocimientos de la sesion y se aplicaria
A18: La responsabilidad se ve relacionada con los conocimientos de la sesión ya que se debe estudiar y reforzar lo aprendido de manera autónoma.
A21: 2. Área Conocimiento (Saber) | G21: Tiempo Aproximado | H21: =SUM(D39:H42) -> 55
G22: No puede exceder los 60 minutos
A23: Competencia a desarrollar | B23: Identifica patrones de diseño por medio del análisis de las diferentes necesidades para resolver un problema específico que se adapta a la solución propuesta por el patrón seleccionado.
A24: Competencia a desarrollar
A26: 2.1 Contenido
A27: No. | B27: Unidad | D27: Tema | F27: Sub Tema
A28: 1 | B28: =IFERROR(__xludf.DUMMYFUNCTION("FILTER('Diseño'!D:D,'Diseño'!H:H=$C$5)"),"Patrones de diseño") -> Patrones de diseño | D28: =IFERROR(__xludf.DUMMYFUNCTION("FILTER('Diseño'!E:E,'Diseño'!H:H=$C$5)"),"Elementos de diseño") -> Elementos de diseño | F28: =IFERROR(__xludf.DUMMYFUNCTION("FILTER('Diseño'!F:F,'Diseño'!H:H=$C$5)"),"Creacional") -> Creacional
A29: 2 | B29: =IFERROR(__xludf.DUMMYFUNCTION("""COMPUTED_VALUE"""),"Patrones de diseño") -> Patrones de diseño | D29: =IFERROR(__xludf.DUMMYFUNCTION("""COMPUTED_VALUE"""),"Elementos de diseño") -> Elementos de diseño | F29: =IFERROR(__xludf.DUMMYFUNCTION("""COMPUTED_VALUE"""),"Factory Method") -> Factory Method
A30: 3 | B30: =IFERROR(__xludf.DUMMYFUNCTION("""COMPUTED_VALUE"""),"Patrones de diseño") -> Patrones de diseño | D30: =IFERROR(__xludf.DUMMYFUNCTION("""COMPUTED_VALUE"""),"Elementos de diseño") -> Elementos de diseño | F30: =IFERROR(__xludf.DUMMYFUNCTION("""COMPUTED_VALUE"""),"Abstact Factory") -> Abstact Factory
A31: 4 | B31: =IFERROR(__xludf.DUMMYFUNCTION("""COMPUTED_VALUE"""),"Patrones de diseño") -> Patrones de diseño | D31: =IFERROR(__xludf.DUMMYFUNCTION("""COMPUTED_VALUE"""),"Elementos de diseño") -> Elementos de diseño | F31: =IFERROR(__xludf.DUMMYFUNCTION("""COMPUTED_VALUE"""),"Singleton") -> Singleton
A32: 5 | B32: =IFERROR(__xludf.DUMMYFUNCTION("""COMPUTED_VALUE"""),"Patrones de diseño") -> Patrones de diseño | D32: =IFERROR(__xludf.DUMMYFUNCTION("""COMPUTED_VALUE"""),"Elementos de diseño") -> Elementos de diseño | F32: =IFERROR(__xludf.DUMMYFUNCTION("""COMPUTED_VALUE"""),"Creacional") -> Creacional
A33: 6 | B33: =IFERROR(__xludf.DUMMYFUNCTION("""COMPUTED_VALUE"""),"Patrones de diseño") -> Patrones de diseño | D33: =IFERROR(__xludf.DUMMYFUNCTION("""COMPUTED_VALUE"""),"Elementos de diseño") -> Elementos de diseño | F33: =IFERROR(__xludf.DUMMYFUNCTION("""COMPUTED_VALUE"""),"Builder") -> Builder
A34: 7 | B34: =IFERROR(__xludf.DUMMYFUNCTION("""COMPUTED_VALUE"""),"Patrones de diseño") -> Patrones de diseño | D34: =IFERROR(__xludf.DUMMYFUNCTION("""COMPUTED_VALUE"""),"Elementos de diseño") -> Elementos de diseño | F34: =IFERROR(__xludf.DUMMYFUNCTION("""COMPUTED_VALUE"""),"Prototype") -> Prototype
A36: 2.2 Recursos Educativos
A38: Tipo de Recurso a utilizar | B38: Tipo | C38: Valor maximo recomendado en Minutos | D38: Tiempo Aproximado ( unicamente el valor de minutos ) | I38: Validacion
A39: Presentacion | B39: Obligatorio | C39: 30 | D39: 20 | I39: =IF(D39<=C39,"Correcto", "Corregir") -> Correcto
A40: Video | B40: Obligatorio | C40: 6 | D40: 5 | I40: =IF(D40<=C40,"Correcto", "Corregir") -> Correcto
A41: Lectura | B41: Optativo | C41: 10 | D41: 10 | I41: =IF(D41<=C41,"Correcto", "Corregir") -> Correcto
A42: Ejercicio Demostrativo | B42: Obligatorio | C42: 30 | D42: 20 | I42: =IF(D42<=C42,"Correcto", "Corregir") -> Correcto
A44: 3. Área de Habilidades (Saber Hacer) | G44: Tiempo Aproximado | H44: =B50 -> 30
G45: Tiene que estar en un rango de 30 a 50 minutos
A46: Actividad 1 (Obligatoria)
A47: Competencia que predomina en la actividad | B47: Identifica patrones de diseño por medio del análisis de las diferentes necesidades para resolver un problema específico que se adapta a la solución propuesta por el patrón seleccionado.
A48: Tipo de Actividad | B48: Ejercicio practico
A49: Ponderación | B49: 1
A50: Tiempo Aproximado | B50: 30
...

Sheet S.4
B2: Diseño de la Sesión de Laboratorio
B4: Curso | C4: ='Diseño'!C4 -> 785 - Análisis y Diseño de Sistemas 2
B5: Semana | C5: 4
B6: Tiempo | C6: =H10+H21+H44+H68 -> 110
B7: Ponderación | C7: =B49+B60 -> 1
B8: Validación de Tiempo | C8: =IF(H44<=0, "❌ ERROR: La Actividad 1 debe tener un tiempo mayor a 0.", IF(H21>60, "❌ ERROR: El 'Área de Conocimiento' no puede exceder los 60 min.", IF((H10+H21+H44)<100, "❌ ERROR: El tiempo total debe ser de al menos 100 min.", "✅ VALIDACIÓN CORRECTA"))) -> ✅ VALIDACIÓN CORRECTA
A10: 1. Área Actitudinal (Saber Ser) | G10: Tiempo Aproximado | H10: =B13 -> 5
G11: Tiene que estar en un rango de 3 a 5 minutos
A12: Nombre del Valor | B12: Disciplina
A13: Tiempo Aproximado | B13: 5
A14: Descripcion
A15: La disciplina es la capacidad de mantener hábitos de estudio, organización y esfuerzo constante, siguiendo normas y objetivos para alcanzar metas académicas y personales efectivamente.
A17: Como se relaciona con los conocimientos de la sesion y se aplicaria
A18: La disciplina se relaciona directamente con el estudio y aplicación de patrones de diseño estructurales porque requiere constancia, organización y práctica para comprenderlos y utilizarlos correctamente.
A21: 2. Área Conocimiento (Saber) | G21: Tiempo Aproximado | H21: =SUM(D39:H42) -> 60
G22: No puede exceder los 60 minutos
A23: Competencia a desarrollar | B23: Identifica patrones de diseño por medio del análisis de las diferentes necesidades para resolver un problema específico que se adapta a la solución propuesta por el patrón seleccionado.
A24: Competencia a desarrollar | B24: Organiza la información del sistema mediante esquemas jerárquicos y categorizados para facilitar la navegación y la comprensión por parte del usuario.
A26: 2.1 Contenido
A27: No. | B27: Unidad | D27: Tema | F27: Sub Tema
A28: 1 | B28: =IFERROR(__xludf.DUMMYFUNCTION("FILTER('Diseño'!D:D,'Diseño'!H:H=$C$5)"),"Patrones de diseño") -> Patrones de diseño | D28: =IFERROR(__xludf.DUMMYFUNCTION("FILTER('Diseño'!E:E,'Diseño'!H:H=$C$5)"),"Elementos de diseño") -> Elementos de diseño | F28: =IFERROR(__xludf.DUMMYFUNCTION("FILTER('Diseño'!F:F,'Diseño'!H:H=$C$5)"),"Estructurales") -> Estructurales
A29: 2 | B29: =IFERROR(__xludf.DUMMYFUNCTION("""COMPUTED_VALUE"""),"Patrones de diseño") -> Patrones de diseño | D29: =IFERROR(__xludf.DUMMYFUNCTION("""COMPUTED_VALUE"""),"Elementos de diseño") -> Elementos de diseño | F29: =IFERROR(__xludf.DUMMYFUNCTION("""COMPUTED_VALUE"""),"Adapter") -> Adapter
A30: 3 | B30: =IFERROR(__xludf.DUMMYFUNCTION("""COMPUTED_VALUE"""),"Patrones de diseño") -> Patrones de diseño | D30: =IFERROR(__xludf.DUMMYFUNCTION("""COMPUTED_VALUE"""),"Elementos de diseño") -> Elementos de diseño | F30: =IFERROR(__xludf.DUMMYFUNCTION("""COMPUTED_VALUE"""),"Proxy") -> Proxy
A31: 4
A32: 5
A33: 6
A34: 7
A36: 2.2 Recursos Educativos
A38: Tipo de Recurso a utilizar | B38: Tipo | C38: Valor maximo recomendado en Minutos | D38: Tiempo Aproximado ( unicamente el valor de minutos ) | I38: Validacion
A39: Presentacion | B39: Obligatorio | C39: 30 | D39: 30 | I39: =IF(D39<=C39,"Correcto", "Corregir") -> Correcto
A40: Video | B40: Obligatorio | C40: 6 | D40: 5 | I40: =IF(D40<=C40,"Correcto", "Corregir") -> Correcto
A41: Lectura | B41: Optativo | C41: 10 | D41: 0 | I41: =IF(D41<=C41,"Correcto", "Corregir") -> Correcto
A42: Ejercicio Demostrativo | B42: Obligatorio | C42: 30 | D42: 25 | I42: =IF(D42<=C42,"Correcto", "Corregir") -> Correcto
A44: 3. Área de Habilidades (Saber Hacer) | G44: Tiempo Aproximado | H44: =B50 -> 35
G45: Tiene que estar en un rango de 30 a 50 minutos
A46: Actividad 1 (Obligatoria)
A47: Competencia que predomina en la actividad | B47: El estudiante Crea ..
A48: Tipo de Actividad | B48: actividades
A49: Ponderación | B49: 1
A50: Tiempo Aproximado | B50: 35
...

Sheet S.5
B2: Diseño de la Sesión de Laboratorio
B4: Curso | C4: ='Diseño'!C4 -> 785 - Análisis y Diseño de Sistemas 2
B5: Semana | C5: 5
B6: Tiempo | C6: =H10+H21+H44+H68 -> 105
B7: Ponderación | C7: =B49+B60 -> 1
B8: Validación de Tiempo | C8: =IF(H44<=0, "❌ ERROR: La Actividad 1 debe tener un tiempo mayor a 0.", IF(H21>60, "❌ ERROR: El 'Área de Conocimiento' no puede exceder los 60 min.", IF((H10+H21+H44+H68)<100, "❌ ERROR: El tiempo total debe ser de al menos 100 min.", "✅ VALIDACIÓN CORRECTA"))) -> ✅ VALIDACIÓN CORRECTA
A10: 1. Área Actitudinal (Saber Ser) | G10: Tiempo Aproximado | H10: =B13 -> 5
G11: Tiene que estar en un rango de 3 a 5 minutos
A12: Nombre del Valor | B12: Adaptabilidad
A13: Tiempo Aproximado | B13: 5
A14: Descripcion
A15: La adaptabilidad es esencial al aplicar patrones de comportamiento, ya que estos se centran en la forma en que los objetos se comunican y reaccionan ante los cambios. Desarrollar esta cualidad permite a los estudiantes diseñar soluciones más flexibles y preparadas para entornos dinámicos y cambiantes.
A17: Como se relaciona con los conocimientos de la sesion y se aplicaria
A18: La adaptabilidad es el valor clave para dominar los patrones de comportamiento. Estos patrones (Observer, Strategy, Command) buscan desacoplar y flexibilizar el código, haciendo que el sistema pueda cambiar y evolucionar sin grandes modificaciones.
A21: 2. Área Conocimiento (Saber) | G21: Tiempo Aproximado | H21: =SUM(D39:H42) -> 60
G22: No puede exceder los 60 minutos
A23: Competencia a desarrollar | B23: Define conceptos de frameworks de desarrollo por medio de especificaciones técnicas para proporcionar un entendimiento preciso de su estructura, componentes y funcionamiento.
A24: Competencia a desarrollar | B24: Identifica patrones de diseño por medio del análisis de las diferentes necesidades para resolver un problema específico que se adapta a la solución propuesta por el patrón seleccionado.
A26: 2.1 Contenido
A27: No. | B27: Unidad | D27: Tema | F27: Sub Tema
A28: 1 | B28: Patrones de Diseño | D28: Elementos de diseño | F28: Patrones de comportamiento
A29: 2 | B29: Patrones de Diseño | D29: Elementos de diseño | F29: Observer
A30: 3 | B30: Patrones de Diseño | D30: Elementos de diseño | F30: Strategy
A31: 4 | B31: Patrones de Diseño | D31: Elementos de diseño | F31: Command
A32: 5
A33: 6
A34: 7
A36: 2.2 Recursos Educativos
A38: Tipo de Recurso a utilizar | B38: Tipo | C38: Valor maximo recomendado en Minutos | D38: Tiempo Aproximado ( unicamente el valor de minutos ) | I38: Validacion
A39: Presentacion | B39: Obligatorio | C39: 30 | D39: 25 | I39: =IF(D39<=C39,"Correcto", "Corregir") -> Correcto
A40: Video | B40: Obligatorio | C40: 6 | D40: 5 | I40: =IF(D40<=C40,"Correcto", "Corregir") -> Correcto
A41: Lectura | B41: Optativo | C41: 10 | D41: 15 | I41: =IF(D41<=C41,"Correcto", "Corregir") -> Corregir
A42: Ejercicio Demostrativo | B42: Obligatorio | C42: 30 | D42: 15 | I42: =IF(D42<=C42,"Correcto", "Corregir") -> Correcto
A44: 3. Área de Habilidades (Saber Hacer) | G44: Tiempo Aproximado | H44: =B50 -> 30
G45: Tiene que estar en un rango de 30 a 50 minutos
A46: Actividad 1 (Obligatoria)
A47: Competencia que predomina en la actividad | B47: Identifica patrones de diseño por medio del análisis de las diferentes necesidades para resolver un problema específico que se adapta a la solución propuesta por el patrón seleccionado.
A48: Tipo de Actividad | B48: actividades
A49: Ponderación | B49: 1
A50: Tiempo Aproximado | B50: 30
...

Sheet S.6
B2: Diseño de la Sesión de Laboratorio
B4: Curso | C4: ='Diseño'!C4 -> 785 - Análisis y Diseño de Sistemas 2
B5: Semana | C5: 6
B6: Tiempo | C6: =H10+H21+H44+H68 -> 100
B7: Ponderación | C7: =B49+B60 -> 1
B8: Validación de Tiempo | C8: =IF(H44<=0, "❌ ERROR: La Actividad 1 debe tener un tiempo mayor a 0.", IF(H21>60, "❌ ERROR: El 'Área de Conocimiento' no puede exceder los 60 min.", IF((H10+H21+H44+H68)<100, "❌ ERROR: El tiempo total debe ser de al menos 100 min.", "✅ VALIDACIÓN CORRECTA"))) -> ✅ VALIDACIÓN CORRECTA
A10: 1. Área Actitudinal (Saber Ser) | G10: Tiempo Aproximado | H10: =B13 -> 5
G11: Tiene que estar en un rango de 3 a 5 minutos
A12: Nombre del Valor | B12: Perseverancia
A13: Tiempo Aproximado | B13: 5
A14: Descripcion
A15: La perseverancia es la capacidad de mantener el esfuerzo y la constancia frente a dificultades, superando obstáculos para alcanzar objetivos académicos y personales con determinación.
A17: Como se relaciona con los conocimientos de la sesion y se aplicaria
A18: La perseverancia se relaciona con el aprendizaje de estrategias de diseño de interfaces y arquitectura de la información porque permite que el estudiante siga practicando y refinando sus habilidades pese a la complejidad de los conceptos y la iteración constante que requiere un buen diseño.
A21: 2. Área Conocimiento (Saber) | G21: Tiempo Aproximado | H21: =SUM(D39:H42) -> 55
G22: No puede exceder los 60 minutos
A23: Competencia a desarrollar | B23: Integra catalogos de estilo mediante aspectos relacionados con la identidad de la marca u organización para crear interfaces adecuadas dentro del sistema.
A24: Competencia a desarrollar | B24: Identifica patrones de diseño por medio del análisis de las diferentes necesidades para resolver un problema específico que se adapta a la solución propuesta por el patrón seleccionado.
A26: 2.1 Contenido
A27: No. | B27: Unidad | D27: Tema | F27: Sub Tema
A28: 1 | B28: =IFERROR(__xludf.DUMMYFUNCTION("FILTER('Diseño'!D:D,'Diseño'!H:H=$C$5)")," Elementos de Diseño") -> Elementos de Diseño | D28: =IFERROR(__xludf.DUMMYFUNCTION("FILTER('Diseño'!E:E,'Diseño'!H:H=$C$5)"),"Estrategias en Diseño de Interfaces y Arquitectura de la Información") -> Estrategias en Diseño de Interfaces y Arquitectura de la Información | F28: =IFERROR(__xludf.DUMMYFUNCTION("FILTER('Diseño'!F:F,'Diseño'!H:H=$C$5)"),"Catálogode estilos") -> Catálogode estilos
A29: 2 | B29: =IFERROR(__xludf.DUMMYFUNCTION("""COMPUTED_VALUE""")," Elementos de Diseño") -> Elementos de Diseño | D29: =IFERROR(__xludf.DUMMYFUNCTION("""COMPUTED_VALUE"""),"Estrategias en Diseño de Interfaces y Arquitectura de la Información") -> Estrategias en Diseño de Interfaces y Arquitectura de la Información | F29: =IFERROR(__xludf.DUMMYFUNCTION("""COMPUTED_VALUE"""),"Arquitectura de la información") -> Arquitectura de la información
A30: 3 | B30: =IFERROR(__xludf.DUMMYFUNCTION("""COMPUTED_VALUE""")," Elementos de Diseño") -> Elementos de Diseño | D30: =IFERROR(__xludf.DUMMYFUNCTION("""COMPUTED_VALUE"""),"Estrategias en Diseño de Interfaces y Arquitectura de la Información") -> Estrategias en Diseño de Interfaces y Arquitectura de la Información | F30: =IFERROR(__xludf.DUMMYFUNCTION("""COMPUTED_VALUE"""),"Experiencia de usuario (UX)") -> Experiencia de usuario (UX)
A31: 4 | B31: =IFERROR(__xludf.DUMMYFUNCTION("""COMPUTED_VALUE""")," Elementos de Diseño") -> Elementos de Diseño | D31: =IFERROR(__xludf.DUMMYFUNCTION("""COMPUTED_VALUE"""),"Estrategias en Diseño de Interfaces y Arquitectura de la Información") -> Estrategias en Diseño de Interfaces y Arquitectura de la Información | F31: =IFERROR(__xludf.DUMMYFUNCTION("""COMPUTED_VALUE"""),"Diseño de interfaces de usuario (UI)") -> Diseño de interfaces de usuario (UI)
A32: 5
A33: 6
A34: 7
A36: 2.2 Recursos Educativos
A38: Tipo de Recurso a utilizar | B38: Tipo | C38: Valor maximo recomendado en Minutos | D38: Tiempo Aproximado ( unicamente el valor de minutos ) | I38: Validacion
A39: Presentacion | B39: Obligatorio | C39: 30 | D39: 20 | I39: =IF(D39<=C39,"Correcto", "Corregir") -> Correcto
A40: Video | B40: Obligatorio | C40: 6 | D40: 5 | I40: =IF(D40<=C40,"Correcto", "Corregir") -> Correcto
A41: Lectura | B41: Optativo | C41: 10 | D41: 10 | I41: =IF(D41<=C41,"Correcto", "Corregir") -> Correcto
A42: Ejercicio Demostrativo | B42: Obligatorio | C42: 30 | D42: 20 | I42: =IF(D42<=C42,"Correcto", "Corregir") -> Correcto
A44: 3. Área de Habilidades (Saber Hacer) | G44: Tiempo Aproximado | H44: =B50 -> 30
G45: Tiene que estar en un rango de 30 a 50 minutos
A46: Actividad 1 (Obligatoria)
A47: Competencia que predomina en la actividad | B47: Integra catalogos de estilo mediante aspectos relacionados con la identidad de la marca u organización para crear interfaces adecuadas dentro del sistema.
A48: Tipo de Actividad | B48: Ejercicio practico
A49: Ponderación | B49: 1
A50: Tiempo Aproximado | B50: 30
...

Sheet S.7
B2: Diseño de la Sesión de Laboratorio
B4: Curso | C4: ='Diseño'!C4 -> 785 - Análisis y Diseño de Sistemas 2
B5: Semana | C5: 7
B6: Tiempo | C6: =H10+H21+H44+H68 -> 110
B7: Ponderación | C7: =B49+B60 -> 1
B8: Validación de Tiempo | C8: =IF(H44<=0, "❌ ERROR: La Actividad 1 debe tener un tiempo mayor a 0.", IF(H21>60, "❌ ERROR: El 'Área de Conocimiento' no puede exceder los 60 min.", IF((H10+H21+H44)<100, "❌ ERROR: El tiempo total debe ser de al menos 100 min.", "✅ VALIDACIÓN CORRECTA"))) -> ✅ VALIDACIÓN CORRECTA
A10: 1. Área Actitudinal (Saber Ser) | G10: Tiempo Aproximado | H10: =B13 -> 5
G11: Tiene que estar en un rango de 3 a 5 minutos
A12: Nombre del Valor | B12: Pensamiento crítico
A13: Tiempo Aproximado | B13: 5
A14: Descripcion
A15: El pensamiento crítico es esencial al seleccionar y aplicar patrones de arquitectura, ya que permite evaluar de forma objetiva los requerimientos del sistema, las ventajas y desventajas de cada enfoque arquitectónico, y tomar decisiones informadas que impactan en la escalabilidad, flexibilidad y mantenibilidad de las soluciones tecnológicas.
A17: Como se relaciona con los conocimientos de la sesion y se aplicaria
A18: El pensamiento crítico es indispensable para la evaluación, selección y justificación de los Patrones de Arquitectura. La elección de una arquitectura (Centrada en Datos, EDA, SOA, etc.) es la decisión de diseño más costosa de revertir, por lo que requiere un análisis objetivo.
A21: 2. Área Conocimiento (Saber) | G21: Tiempo Aproximado | H21: =SUM(D39:H42) -> 60
G22: No puede exceder los 60 minutos
A23: Competencia a desarrollar | B23: Organiza la información del sistema mediante esquemas jerárquicos y categorizados para facilitar la navegación y la comprensión por parte del usuario.
A24: Competencia a desarrollar | B24: Recuerda la importancia de las decisiones de diseño y arquitectura mediante el análisis de casos prácticos y ejemplos de sistemas reales para fortalecer la capacidad de aplicar soluciones coherentes y efectivas en proyectos de software
A26: 2.1 Contenido
A27: No. | B27: Unidad | D27: Tema | F27: Sub Tema
A28: 1 | B28: =IFERROR(__xludf.DUMMYFUNCTION("FILTER('Diseño'!D:D,'Diseño'!H:H=$C$5)")," Elementos de Diseño") -> Elementos de Diseño | D28: =IFERROR(__xludf.DUMMYFUNCTION("FILTER('Diseño'!E:E,'Diseño'!H:H=$C$5)"),"Patrones de arquitectura") -> Patrones de arquitectura | F28: =IFERROR(__xludf.DUMMYFUNCTION("FILTER('Diseño'!F:F,'Diseño'!H:H=$C$5)"),"Centrada en Datos") -> Centrada en Datos
A29: 2 | B29: =IFERROR(__xludf.DUMMYFUNCTION("""COMPUTED_VALUE""")," Elementos de Diseño") -> Elementos de Diseño | D29: =IFERROR(__xludf.DUMMYFUNCTION("""COMPUTED_VALUE"""),"Patrones de arquitectura") -> Patrones de arquitectura | F29: =IFERROR(__xludf.DUMMYFUNCTION("""COMPUTED_VALUE"""),"Centrada en el flujo de datos") -> Centrada en el flujo de datos
A30: 3 | B30: =IFERROR(__xludf.DUMMYFUNCTION("""COMPUTED_VALUE""")," Elementos de Diseño") -> Elementos de Diseño | D30: =IFERROR(__xludf.DUMMYFUNCTION("""COMPUTED_VALUE"""),"Patrones de arquitectura") -> Patrones de arquitectura | F30: =IFERROR(__xludf.DUMMYFUNCTION("""COMPUTED_VALUE"""),"Arquitectura orientada a eventos") -> Arquitectura orientada a eventos
A31: 4 | B31: =IFERROR(__xludf.DUMMYFUNCTION("""COMPUTED_VALUE""")," Elementos de Diseño") -> Elementos de Diseño | D31: =IFERROR(__xludf.DUMMYFUNCTION("""COMPUTED_VALUE"""),"Patrones de arquitectura") -> Patrones de arquitectura | F31: =IFERROR(__xludf.DUMMYFUNCTION("""COMPUTED_VALUE"""),"Patrones de arquitectura empresarial") -> Patrones de arquitectura empresarial
A32: 5 | B32: =IFERROR(__xludf.DUMMYFUNCTION("""COMPUTED_VALUE""")," Elementos de Diseño") -> Elementos de Diseño | D32: =IFERROR(__xludf.DUMMYFUNCTION("""COMPUTED_VALUE"""),"Patrones de arquitectura") -> Patrones de arquitectura | F32: =IFERROR(__xludf.DUMMYFUNCTION("""COMPUTED_VALUE"""),"SOA (Service-Oriented Architecture)") -> SOA (Service-Oriented Architecture)
A33: 6 | B33: =IFERROR(__xludf.DUMMYFUNCTION("""COMPUTED_VALUE""")," Elementos de Diseño") -> Elementos de Diseño | D33: =IFERROR(__xludf.DUMMYFUNCTION("""COMPUTED_VALUE"""),"Patrones de arquitectura") -> Patrones de arquitectura | F33: =IFERROR(__xludf.DUMMYFUNCTION("""COMPUTED_VALUE"""),"EDA (Event-Driven Architecture)") -> EDA (Event-Driven Architecture)
A34: 7 | B34: =IFERROR(__xludf.DUMMYFUNCTION("""COMPUTED_VALUE""")," Elementos de Diseño") -> Elementos de Diseño | D34: =IFERROR(__xludf.DUMMYFUNCTION("""COMPUTED_VALUE"""),"Patrones de arquitectura") -> Patrones de arquitectura | F34: =IFERROR(__xludf.DUMMYFUNCTION("""COMPUTED_VALUE"""),"Arquitecturas híbridas") -> Arquitecturas híbridas
A36: 2.2 Recursos Educativos
A38: Tipo de Recurso a utilizar | B38: Tipo | C38: Valor maximo recomendado en Minutos | D38: Tiempo Aproximado ( unicamente el valor de minutos ) | I38: Validacion
A39: Presentacion | B39: Obligatorio | C39: 30 | D39: 25 | I39: =IF(D39<=C39,"Correcto", "Corregir") -> Correcto
A40: Video | B40: Obligatorio | C40: 6 | D40: 5 | I40: =IF(D40<=C40,"Correcto", "Corregir") -> Correcto
A41: Lectura | B41: Optativo | C41: 10 | D41: 10 | I41: =IF(D41<=C41,"Correcto", "Corregir") -> Correcto
A42: Ejercicio Demostrativo | B42: Obligatorio | C42: 30 | D42: 20 | I42: =IF(D42<=C42,"Correcto", "Corregir") -> Correcto
A44: 3. Área de Habilidades (Saber Hacer) | G44: Tiempo Aproximado | H44: =B50 -> 35
G45: Tiene que estar en un rango de 30 a 50 minutos
A46: Actividad 1 (Obligatoria)
A47: Competencia que predomina en la actividad | B47: Identifica patrones de diseño por medio del análisis de las diferentes necesidades para resolver un problema específico que se adapta a la solución propuesta por el patrón seleccionado.
A48: Tipo de Actividad | B48: actividades
A49: Ponderación | B49: 1
A50: Tiempo Aproximado | B50: 35
...

Sheet S.8
B2: Diseño de la Sesión de Laboratorio
B4: Curso | C4: ='Diseño'!C4 -> 785 - Análisis y Diseño de Sistemas 2
B5: Semana | C5: 8
B6: Tiempo | C6: =H10+H21+H44+H68 -> 100
B7: Ponderación | C7: =B49+B60 -> 1
B8: Validación de Tiempo | C8: =IF(H44<=0, "❌ ERROR: La Actividad 1 debe tener un tiempo mayor a 0.", IF(H21>60, "❌ ERROR: El 'Área de Conocimiento' no puede exceder los 60 min.", IF((H10+H21+H44+H68)<100, "❌ ERROR: El tiempo total debe ser de al menos 100 min.", "✅ VALIDACIÓN CORRECTA"))) -> ✅ VALIDACIÓN CORRECTA
A10: 1. Área Actitudinal (Saber Ser) | G10: Tiempo Aproximado | H10: 5
G11: Tiene que estar en un rango de 3 a 5 minutos
A12: Nombre del Valor | B12: Constancia
A13: Tiempo Aproximado | B13: 5
A14: Descripcion
A15: La constancia es la habilidad de mantener un esfuerzo continuo y regular en el aprendizaje y práctica académica, asegurando progreso constante y dominio de los contenidos a lo largo del tiempo.
A17: Como se relaciona con los conocimientos de la sesion y se aplicaria
A18: La constancia se relaciona con el aprendizaje y aplicación de pruebas funcionales porque permite al estudiante practicar, ejecutar y evaluar pruebas de manera sostenida, asegurando calidad y comprensión profunda.
A21: 2. Área Conocimiento (Saber) | G21: Tiempo Aproximado | H21: =SUM(D39:H42) -> 55
G22: No puede exceder los 60 minutos
A23: Competencia a desarrollar | B23: Organiza la información del sistema mediante esquemas jerárquicos y categorizados para facilitar la navegación y la comprensión por parte del usuario.
A24: Competencia a desarrollar | B24: Recuerda la importancia de las decisiones de diseño y arquitectura mediante el análisis de casos prácticos y ejemplos de sistemas reales para fortalecer la capacidad de aplicar soluciones coherentes y efectivas en proyectos de software
A26: 2.1 Contenido
A27: No. | B27: Unidad | D27: Tema | F27: Sub Tema
A28: 1 | B28: =IFERROR(__xludf.DUMMYFUNCTION("FILTER('Diseño'!D:D,'Diseño'!H:H=$C$5)"),"Pruebas de Software") -> Pruebas de Software | D28: =IFERROR(__xludf.DUMMYFUNCTION("FILTER('Diseño'!E:E,'Diseño'!H:H=$C$5)"),"Pruebas funcionales") -> Pruebas funcionales | F28: =IFERROR(__xludf.DUMMYFUNCTION("FILTER('Diseño'!F:F,'Diseño'!H:H=$C$5)"),"¿Qué son las pruebas funcionales?") -> ¿Qué son las pruebas funcionales?
A29: 2 | B29: =IFERROR(__xludf.DUMMYFUNCTION("""COMPUTED_VALUE"""),"Pruebas de Software") -> Pruebas de Software | D29: =IFERROR(__xludf.DUMMYFUNCTION("""COMPUTED_VALUE"""),"Pruebas funcionales") -> Pruebas funcionales | F29: =IFERROR(__xludf.DUMMYFUNCTION("""COMPUTED_VALUE"""),"Conceptos y principios de las pruebas funcionales") -> Conceptos y principios de las pruebas funcionales
A30: 3 | B30: =IFERROR(__xludf.DUMMYFUNCTION("""COMPUTED_VALUE"""),"Pruebas de Software") -> Pruebas de Software | D30: =IFERROR(__xludf.DUMMYFUNCTION("""COMPUTED_VALUE"""),"Pruebas funcionales") -> Pruebas funcionales | F30: =IFERROR(__xludf.DUMMYFUNCTION("""COMPUTED_VALUE"""),"Importancia y aplicabilidad dentro de una arquitectura de software") -> Importancia y aplicabilidad dentro de una arquitectura de software
A31: 4 | B31: =IFERROR(__xludf.DUMMYFUNCTION("""COMPUTED_VALUE"""),"Pruebas de Software") -> Pruebas de Software | D31: =IFERROR(__xludf.DUMMYFUNCTION("""COMPUTED_VALUE"""),"Pruebas funcionales") -> Pruebas funcionales | F31: =IFERROR(__xludf.DUMMYFUNCTION("""COMPUTED_VALUE"""),"¿Qué son las pruebas unitarias?") -> ¿Qué son las pruebas unitarias?
A32: 5 | B32: =IFERROR(__xludf.DUMMYFUNCTION("""COMPUTED_VALUE"""),"Pruebas de Software") -> Pruebas de Software | D32: =IFERROR(__xludf.DUMMYFUNCTION("""COMPUTED_VALUE"""),"Pruebas funcionales") -> Pruebas funcionales | F32: =IFERROR(__xludf.DUMMYFUNCTION("""COMPUTED_VALUE"""),"¿Qué son pruebas de aceptación?") -> ¿Qué son pruebas de aceptación?
A33: 6 | B33: =IFERROR(__xludf.DUMMYFUNCTION("""COMPUTED_VALUE"""),"Pruebas de Software") -> Pruebas de Software | D33: =IFERROR(__xludf.DUMMYFUNCTION("""COMPUTED_VALUE"""),"Pruebas funcionales") -> Pruebas funcionales | F33: =IFERROR(__xludf.DUMMYFUNCTION("""COMPUTED_VALUE"""),"¿Qué son las pruebas de integración?") -> ¿Qué son las pruebas de integración?
A34: 7 | B34: =IFERROR(__xludf.DUMMYFUNCTION("""COMPUTED_VALUE"""),"Pruebas de Software") -> Pruebas de Software | D34: =IFERROR(__xludf.DUMMYFUNCTION("""COMPUTED_VALUE"""),"Pruebas funcionales") -> Pruebas funcionales | F34: =IFERROR(__xludf.DUMMYFUNCTION("""COMPUTED_VALUE"""),"¿Qué son las pruebas de regresión?") -> ¿Qué son las pruebas de regresión?
A36: 2.2 Recursos Educativos
A38: Tipo de Recurso a utilizar | B38: Tipo | C38: Valor maximo recomendado en Minutos | D38: Tiempo Aproximado ( unicamente el valor de minutos ) | I38: Validacion
A39: Presentacion | B39: Obligatorio | C39: 30 | D39: 24 | I39: =IF(D39<=C39,"Correcto", "Corregir") -> Correcto
A40: Video | B40: Obligatorio | C40: 6 | D40: 6 | I40: =IF(D40<=C40,"Correcto", "Corregir") -> Correcto
A41: Lectura | B41: Optativo | C41: 10 | D41: 0 | I41: =IF(D41<=C41,"Correcto", "Corregir") -> Correcto
A42: Ejercicio Demostrativo | B42: Obligatorio | C42: 30 | D42: 25 | I42: =IF(D42<=C42,"Correcto", "Corregir") -> Correcto
A44: 3. Área de Habilidades (Saber Hacer) | G44: Tiempo Aproximado | H44: =B50 -> 30
G45: Tiene que estar en un rango de 30 a 50 minutos
A46: Actividad 1 (Obligatoria)
A47: Competencia que predomina en la actividad | B47: Organiza la información del sistema mediante esquemas jerárquicos y categorizados para facilitar la navegación y la comprensión por parte del usuario.
A48: Tipo de Actividad | B48: actividades
A49: Ponderación | B49: 1
A50: Tiempo Aproximado | B50: 30
...

Sheet S.9
B2: Diseño de la Sesión de Laboratorio
B4: Curso | C4: ='Diseño'!C4 -> 785 - Análisis y Diseño de Sistemas 2
B5: Semana | C5: 9
B6: Tiempo | C6: =H10+H21+H44+H68 -> 100
B7: Ponderación | C7: =B49+B60 -> 1
B8: Validación de Tiempo | C8: =IF(H44<=0, "❌ ERROR: La Actividad 1 debe tener un tiempo mayor a 0.", IF(H21>60, "❌ ERROR: El 'Área de Conocimiento' no puede exceder los 60 min.", IF((H10+H21+H44+H68)<100, "❌ ERROR: El tiempo total debe ser de al menos 100 min.", "✅ VALIDACIÓN CORRECTA"))) -> ✅ VALIDACIÓN CORRECTA
A10: 1. Área Actitudinal (Saber Ser) | G10: Tiempo Aproximado | H10: =B13 -> 5
G11: Tiene que estar en un rango de 3 a 5 minutos
A12: Nombre del Valor | B12: Rigor técnico
A13: Tiempo Aproximado | B13: 5
A14: Descripcion
A15: El rigor técnico permite ejecutar pruebas no funcionales con precisión, objetividad y atención al detalle. Este valor es esencial para garantizar la calidad del sistema en aspectos críticos como rendimiento, escalabilidad, portabilidad y estabilidad, más allá de que simplemente "funcione"
A17: Como se relaciona con los conocimientos de la sesion y se aplicaria
A18: El rigor técnico es la base para ejecutar y analizar correctamente las Pruebas No Funcionales (carga, estrés, escalabilidad, portabilidad). Estas pruebas se centran en la calidad del sistema más allá de su funcionalidad básica ("que simplemente funcione").
A21: 2. Área Conocimiento (Saber) | G21: Tiempo Aproximado | H21: =SUM(D39:H42) -> 55
G22: No puede exceder los 60 minutos
A23: Competencia a desarrollar | B23: Aplica principios y técnicas de análisis y diseño de sistemas mediante metodologías, modelos y herramientas de ingeniería de software para desarrollar sistemas eficientes, mantenibles y alineados con los requisitos del usuario
A24: Competencia a desarrollar | B24: Recuerda la importancia de las decisiones de diseño y arquitectura mediante el análisis de casos prácticos y ejemplos de sistemas reales para fortalecer la capacidad de aplicar soluciones coherentes y efectivas en proyectos de software
A26: 2.1 Contenido
A27: No. | B27: Unidad | D27: Tema | F27: Sub Tema
A28: 1 | B28: =IFERROR(__xludf.DUMMYFUNCTION("FILTER('Diseño'!D:D,'Diseño'!H:H=$C$5)"),"Pruebas de Software") -> Pruebas de Software | D28: =IFERROR(__xludf.DUMMYFUNCTION("FILTER('Diseño'!E:E,'Diseño'!H:H=$C$5)"),"Pruebas no funcionales") -> Pruebas no funcionales | F28: =IFERROR(__xludf.DUMMYFUNCTION("FILTER('Diseño'!F:F,'Diseño'!H:H=$C$5)"),"¿Qué son las pruebas no funcionales?") -> ¿Qué son las pruebas no funcionales?
A29: 2 | B29: =IFERROR(__xludf.DUMMYFUNCTION("""COMPUTED_VALUE"""),"Pruebas de Software") -> Pruebas de Software | D29: =IFERROR(__xludf.DUMMYFUNCTION("""COMPUTED_VALUE"""),"Pruebas no funcionales") -> Pruebas no funcionales | F29: =IFERROR(__xludf.DUMMYFUNCTION("""COMPUTED_VALUE"""),"Conceptos y principios de las pruebas no funcionales") -> Conceptos y principios de las pruebas no funcionales
A30: 3 | B30: =IFERROR(__xludf.DUMMYFUNCTION("""COMPUTED_VALUE"""),"Pruebas de Software") -> Pruebas de Software | D30: =IFERROR(__xludf.DUMMYFUNCTION("""COMPUTED_VALUE"""),"Pruebas no funcionales") -> Pruebas no funcionales | F30: =IFERROR(__xludf.DUMMYFUNCTION("""COMPUTED_VALUE"""),"Importancia y aplicabilidad dentro de una arquitectura de software") -> Importancia y aplicabilidad dentro de una arquitectura de software
A31: 4 | B31: =IFERROR(__xludf.DUMMYFUNCTION("""COMPUTED_VALUE"""),"Pruebas de Software") -> Pruebas de Software | D31: =IFERROR(__xludf.DUMMYFUNCTION("""COMPUTED_VALUE"""),"Pruebas no funcionales") -> Pruebas no funcionales | F31: =IFERROR(__xludf.DUMMYFUNCTION("""COMPUTED_VALUE"""),"¿Qué son las pruebas de carga?") -> ¿Qué son las pruebas de carga?
A32: 5 | B32: =IFERROR(__xludf.DUMMYFUNCTION("""COMPUTED_VALUE"""),"Pruebas de Software") -> Pruebas de Software | D32: =IFERROR(__xludf.DUMMYFUNCTION("""COMPUTED_VALUE"""),"Pruebas no funcionales") -> Pruebas no funcionales | F32: =IFERROR(__xludf.DUMMYFUNCTION("""COMPUTED_VALUE"""),"¿Qué son las pruebas de estres?") -> ¿Qué son las pruebas de estres?
A33: 6 | B33: =IFERROR(__xludf.DUMMYFUNCTION("""COMPUTED_VALUE"""),"Pruebas de Software") -> Pruebas de Software | D33: =IFERROR(__xludf.DUMMYFUNCTION("""COMPUTED_VALUE"""),"Pruebas no funcionales") -> Pruebas no funcionales | F33: =IFERROR(__xludf.DUMMYFUNCTION("""COMPUTED_VALUE"""),"¿Qué son las pruebas de escalabilidad?") -> ¿Qué son las pruebas de escalabilidad?
A34: 7 | B34: =IFERROR(__xludf.DUMMYFUNCTION("""COMPUTED_VALUE"""),"Pruebas de Software") -> Pruebas de Software | D34: =IFERROR(__xludf.DUMMYFUNCTION("""COMPUTED_VALUE"""),"Pruebas no funcionales") -> Pruebas no funcionales | F34: =IFERROR(__xludf.DUMMYFUNCTION("""COMPUTED_VALUE"""),"¿Qué son las pruebas de portabilidad?") -> ¿Qué son las pruebas de portabilidad?
A36: 2.2 Recursos Educativos
A38: Tipo de Recurso a utilizar | B38: Tipo | C38: Valor maximo recomendado en Minutos | D38: Tiempo Aproximado ( unicamente el valor de minutos ) | I38: Validacion
A39: Presentacion | B39: Obligatorio | C39: 30 | D39: 20 | I39: =IF(D39<=C39,"Correcto", "Corregir") -> Correcto
A40: Video | B40: Obligatorio | C40: 6 | D40: 5 | I40: =IF(D40<=C40,"Correcto", "Corregir") -> Correcto
A41: Lectura | B41: Optativo | C41: 10 | D41: 10 | I41: =IF(D41<=C41,"Correcto", "Corregir") -> Correcto
A42: Ejercicio Demostrativo | B42: Obligatorio | C42: 30 | D42: 20 | I42: =IF(D42<=C42,"Correcto", "Corregir") -> Correcto
A44: 3. Área de Habilidades (Saber Hacer) | G44: Tiempo Aproximado | H44: =B50 -> 30
G45: Tiene que estar en un rango de 30 a 50 minutos
A46: Actividad 1 (Obligatoria)
A47: Competencia que predomina en la actividad | B47: Aplica principios y técnicas de análisis y diseño de sistemas mediante metodologías, modelos y herramientas de ingeniería de software para desarrollar sistemas eficientes, mantenibles y alineados con los requisitos del usuario
A48: Tipo de Actividad | B48: Cuestionario
A49: Ponderación | B49: 1
A50: Tiempo Aproximado | B50: 30
...

Sheet S.10
B2: Diseño de la Sesión de Laboratorio
B4: Curso | C4: ='Diseño'!C4 -> 785 - Análisis y Diseño de Sistemas 2
B5: Semana | C5: 10
B6: Tiempo | C6: =H10+H21+H44+H68 -> 110
B7: Ponderación | C7: =B49+B60 -> 1
B8: Validación de Tiempo | C8: =IF(H44<=0, "❌ ERROR: La Actividad 1 debe tener un tiempo mayor a 0.", IF(H21>60, "❌ ERROR: El 'Área de Conocimiento' no puede exceder los 60 min.", IF((H10+H21+H44)<100, "❌ ERROR: El tiempo total debe ser de al menos 100 min.", "✅ VALIDACIÓN CORRECTA"))) -> ✅ VALIDACIÓN CORRECTA
A10: 1. Área Actitudinal (Saber Ser) | G10: Tiempo Aproximado | H10: =B13 -> 5
G11: Tiene que estar en un rango de 3 a 5 minutos
A12: Nombre del Valor | B12: Liderazgo
A13: Tiempo Aproximado | B13: 5
A14: Descripcion
A15: El liderazgo es la capacidad de influir, guiar y motivar a un grupo de personas para alcanzar objetivos comunes, promoviendo colaboración, compromiso y desarrollo del equipo.
A17: Como se relaciona con los conocimientos de la sesion y se aplicaria
A18: El liderazgo se relaciona con los temas de pruebas no funcionales y seguridad de sistemas porque implica guiar, coordinar y motivar a un equipo para garantizar la implementación efectiva de medidas de seguridad y estándares de calidad.
A21: 2. Área Conocimiento (Saber) | G21: Tiempo Aproximado | H21: =SUM(D39:H42) -> 60
G22: No puede exceder los 60 minutos
A23: Competencia a desarrollar | B23: Identifica patrones de diseño por medio del análisis de las diferentes necesidades para resolver un problema específico que se adapta a la solución propuesta por el patrón seleccionado.
A24: Competencia a desarrollar | B24: Diseña arquitecturas de software mediante la definición de componentes, conexiones y capas del sistema para asegurar la funcionalidad, rendimiento y escalabilidad del producto final
A26: 2.1 Contenido
A27: No. | B27: Unidad | D27: Tema | F27: Sub Tema
A28: 1 | B28: =IFERROR(__xludf.DUMMYFUNCTION("FILTER('Diseño'!D:D,'Diseño'!H:H=$C$5)"),"Seguridad") -> Seguridad | D28: =IFERROR(__xludf.DUMMYFUNCTION("FILTER('Diseño'!E:E,'Diseño'!H:H=$C$5)"),"Pruebas no funcionales") -> Pruebas no funcionales | F28: =IFERROR(__xludf.DUMMYFUNCTION("FILTER('Diseño'!F:F,'Diseño'!H:H=$C$5)"),"Introducción a la seguridad de sistemas") -> Introducción a la seguridad de sistemas
A29: 2 | B29: =IFERROR(__xludf.DUMMYFUNCTION("""COMPUTED_VALUE"""),"Seguridad") -> Seguridad | D29: =IFERROR(__xludf.DUMMYFUNCTION("""COMPUTED_VALUE"""),"Introducción a la seguridad de sistemas") -> Introducción a la seguridad de sistemas | F29: =IFERROR(__xludf.DUMMYFUNCTION("""COMPUTED_VALUE"""),"Modelado de Amenazas") -> Modelado de Amenazas
A30: 3 | B30: =IFERROR(__xludf.DUMMYFUNCTION("""COMPUTED_VALUE"""),"Seguridad") -> Seguridad | D30: =IFERROR(__xludf.DUMMYFUNCTION("""COMPUTED_VALUE"""),"Introducción a la seguridad de sistemas") -> Introducción a la seguridad de sistemas | F30: =IFERROR(__xludf.DUMMYFUNCTION("""COMPUTED_VALUE"""),"Diseño seguro de Software") -> Diseño seguro de Software
