Workbook

Sheet Diseño
A2: =VALUE(LEFT(C4,FIND(" - ",C4)-1)) -> 283 | B2: Diseño de Contenido Curricular
B4: Curso | C4: 283 - Análisis y Diseño de Sistemas 1
B5: Periodo al que aplica | C5: Primer Semestre 2026
B8: No. | C8: Competencia | D8: Nombre de la Unidad | E8: Tema | F8: Subtema | G8: Mes | H8: Semana
B9: 1 | C9: Genera soluciones de software aplicando buenas prácticas de análisis, control de versiones y metodologías ágiles para garantizar proyectos eficientes y colaborativos en entornos virtuales de trabajo | D9: 1. Control de Versiones | E9: Git | F9: Introducción | G9: Enero | H9: 2
B10: 2 | C10: Genera soluciones de software aplicando buenas prácticas de análisis, control de versiones y metodologías ágiles para garantizar proyectos eficientes y colaborativos en entornos virtuales de trabajo | D10: 1. Control de Versiones | E10: Git | F10: Fases de Git | G10: Enero | H10: 2
B11: 3 | C11: Genera soluciones de software aplicando buenas prácticas de análisis, control de versiones y metodologías ágiles para garantizar proyectos eficientes y colaborativos en entornos virtuales de trabajo | D11: 1. Control de Versiones | E11: Git | F11: Buenas Prácticas en Git | G11: Enero | H11: 2
B12: 4 | C12: Genera soluciones de software aplicando buenas prácticas de análisis, control de versiones y metodologías ágiles para garantizar proyectos eficientes y colaborativos en entornos virtuales de trabajo | D12: 1. Control de Versiones | E12: Git | F12: Estructura de commits | G12: Enero | H12: 2
B13: 5 | C13: Genera soluciones de software aplicando buenas prácticas de análisis, control de versiones y metodologías ágiles para garantizar proyectos eficientes y colaborativos en entornos virtuales de trabajo | D13: 1. Control de Versiones | E13: Git | F13: Comandos | G13: Enero | H13: 2
B14: 6 | C14: Genera soluciones de software aplicando buenas prácticas de análisis, control de versiones y metodologías ágiles para garantizar proyectos eficientes y colaborativos en entornos virtuales de trabajo | D14: 1. Control de Versiones | E14: Git | F14: Ramas | G14: Enero | H14: 2
B15: 7 | C15: Genera soluciones de software aplicando buenas prácticas de análisis, control de versiones y metodologías ágiles para garantizar proyectos eficientes y colaborativos en entornos virtuales de trabajo | D15: 1. Control de Versiones | E15: GitFlow y Versionamiento Semántico | F15: Introducción | G15: Febrero | H15: 3
B16: 8 | C16: Genera soluciones de software aplicando buenas prácticas de análisis, control de versiones y metodologías ágiles para garantizar proyectos eficientes y colaborativos en entornos virtuales de trabajo | D16: 1. Control de Versiones | E16: GitFlow y Versionamiento Semántico | F16: Ramas principales | G16: Febrero | H16: 3
B17: 9 | C17: Genera soluciones de software aplicando buenas prácticas de análisis, control de versiones y metodologías ágiles para garantizar proyectos eficientes y colaborativos en entornos virtuales de trabajo | D17: 1. Control de Versiones | E17: GitFlow y Versionamiento Semántico | F17: Ramas desarrollo | G17: Febrero | H17: 3
B18: 10 | C18: Genera soluciones de software aplicando buenas prácticas de análisis, control de versiones y metodologías ágiles para garantizar proyectos eficientes y colaborativos en entornos virtuales de trabajo | D18: 1. Control de Versiones | E18: GitFlow y Versionamiento Semántico | F18: Flujo de trabajo | G18: Febrero | H18: 3
B19: 11 | C19: Genera soluciones de software aplicando buenas prácticas de análisis, control de versiones y metodologías ágiles para garantizar proyectos eficientes y colaborativos en entornos virtuales de trabajo | D19: 1. Control de Versiones | E19: GitFlow y Versionamiento Semántico | F19: Versionamiento semántico | G19: Febrero | H19: 3
B20: 12 | C20: Genera soluciones de software aplicando buenas prácticas de análisis, control de versiones y metodologías ágiles para garantizar proyectos eficientes y colaborativos en entornos virtuales de trabajo | D20: 1. Control de Versiones | E20: GitFlow y Versionamiento Semántico | F20: Releases | G20: Febrero | H20: 3
... B62: 54 | C62: Integra herramientas de gestión de requerimientos, pruebas y despliegue continuo utilizando estándares de calidad de software y herramientas como Jira, Git y CI/CD con el fin de asegurar la trazabilidad, confiabilidad y funcionalidad del sistema | D62: 4. Automatizacion de ciclos de vida del software | E62: DevOps | F62: Ejecucion de pruebas automatizadas | G62: Abril | H62: 11

Sheet Semana Diagnostico
B2: Diseño de Contenido Curricular
B4: Curso | C4: ='Diseño'!C4 -> 283 - Análisis y Diseño de Sistemas 1
B5: Semana | C5: 1
B6: Tiempo | C6: =B15+B22+B29+B41+B47+C48+H32 -> 90
K8: Estos puntos son recomendaciones de los puntos a tratar durante tu presentacion, si no usaras estos eres libre de agregar mas filas para indicar que haras. En los recuadros de la derecha colocar breve resumen de lo que planeas decir. No debes ser muy especifico seran pequeñas anotaciones que te ayudaran a recordar lo que planeaste
A9: 1. Bienvenida y Presentación | G9: Tiempo Aproximado | H9: =B15 -> 15
G10: No puedes excederte mas de 15 minutos
A11: Nombre y Formacion Academica | B11: Hablar de mi persona, semestre en el que voy y si trabajo o no y que puedo ofrecer como tutor
A12: Experiencia docente y profesional | B12: Dar a conocer experiencia laboral si trabajo
A13: Rol del auxiliar dentro del curso (funciones, actividades y apoyo a los estudiantes). | B13: Describir cuales son las funciones de ser auxiliar y preguntar que esperan de mi.
A14: Expectativas sobre la dinámica del curso | B14: Explicar que espero de mis alumnos durante el semestre
A15: Tiempo que emplearas | B15: 15
A18: 2. Evaluación de Conocimientos Previos | G18: Tiempo Aproximado | H18: 20
G19: No puedes excederte mas de 45 minutos | K19: En los recuadors de la derecha deberas colocar las preguntas que planeas realizar con sus respectivas respuestas. En el segundo recuadro deberas colocar un breve resumne de lo que tines planificado para la parte practica del curso previo al que estas impartiendo.
A20: Redactaras de 15 a 20 preguntas con sus respectivas respuestas , por lo que debes escoge los temas que evaluaras | B20: Las preguntas estan abajo del documento
A21: Redactaras una parte practica | B21: Deberan de implementar las bases de datos relacionales para hacer un sistema completo de frontend, backend y bd
A22: Tiempo que emplearas | B22: 15
A25: 3. Presentación de los Estudiantes | G25: Tiempo Aproximado | H25: =B29 -> 10
G26: No puedes excederte mas de 30 minutos
A27: Seleccion al Azar de 5 Estudiantes | B27: Elegir del chat de forma aleatoria | K27: En el primer recuadro colocaras la metodollogia que adoptaras para la eleccion de los estudiantes. En el segundo recuadro colocaras la redaccion de las preguntas que comprendan los siguientes puntos respecto al estudiante: Nombre. Intereses y expectativas sobre el curso. Experiencia previa relacionada con el curso (si aplica). Un dato curioso sobre sí mismo. Consideras que la prueba de conociminetos previos esta acorde al conocimiento que se te brindo en su momento Que tan comodo se sintio con la prueba anterior.
A28: Preguntas que responderan los estudiantes afortunados | B28: Nombre Intereses y expectativas sobre el curso. Experiencia previa relacionada con el curso (si aplica). Un dato curioso sobre sí mismo. Consideras que la prueba de conociminetos previos esta acorde al conocimiento que se te brindo en su momento Que tan comodo se sintio con la prueba anterior.
A29: Tiempo que emplearas | B29: 10
A32: 4. Senso de Horarios de Calificación | G32: Tiempo Aproximado | H32: =B36 -> 5
A33: Deberas estar recordando que deben contestar el formulario asi mismo dejar el link fijado en la llamada | G33: Esta actividad quedara abierta hasta el fin de la clase. pero emplearas 5 min especificos para la actividad
A34: Link de google forms donde este el cuestionario | K34: Esta actividad te ayudara a realizar un senso de posibles horarios de calificacion y que tus estudiantes esten enterados y puedan preveer los dias de calificacion y asi mismo el horario. Deberas colocar en los reacuadros de la derecha link de Google form libre para correos intitucionales, esto para garantizar una sola respuesta por estudiante. TAmbien deberas colocar los posibles horarios y dias que tentativamente tendrias disponibles. para colocarlos en el google form.
A35: Dias y posibles Horarios de calificacion | B35: Sábado, de 10 am en adelante dependiendo el numero de estudiantes asignados en el semestre
A36: Tiempo que emplearas | B36: 5
A39: 4. Mostrar Programa del Curso | G39: Tiempo Aproximado | H39: =B41 -> 30
G40: No puedes excederte mas de 30 minutos
A41: Tiempo que emplearas | B41: 30
A44: 2. Evaluación de Conocimientos del Curso Actual | G44: Tiempo Aproximado | H44: =B47 -> 15
G45: No puedes excederte mas de 15 minutos
A46: Redactaras 20 preguntas con sus respectivas respuestas
A47: Tiempo que emplearas | B47: 15
A52: PREGUNTAS DE CONOCIMIENTOS PREVIOS
A53: ¿Cuál es el lenguaje más utilizado para manejar bases de datos relacionales?
A54: A) HTML
A55: B) SQL
A56: C) CSS
A58: ¿Qué tipo de clave garantiza que cada registro en una tabla sea único?
...

Sheet S.2
B2: Diseño de la Sesión de Laboratorio
B4: Curso | C4: ='Diseño'!C4 -> 283 - Análisis y Diseño de Sistemas 1
B5: Semana | C5: 2
B6: Tiempo | C6: =H10+H21+H44+H68 -> 103
B7: Ponderación | C7: =B49+B60 -> 1
B8: Validación de Tiempo | C8: =IF(H44<=0, "❌ ERROR: La Actividad 1 debe tener un tiempo mayor a 0.", IF(H21>60, "❌ ERROR: El 'Área de Conocimiento' no puede exceder los 60 min.", IF((H10+H21+H44+H68)<100, "❌ ERROR: El tiempo total debe ser de al menos 100 min.", "✅ VALIDACIÓN CORRECTA"))) -> ✅ VALIDACIÓN CORRECTA
A10: 1. Área Actitudinal (Saber Ser) | G10: Tiempo Aproximado | H10: =B13 -> 3
G11: Tiene que estar en un rango de 3 a 5 minutos
A12: Nombre del Valor | B12: Honestidad
A13: Tiempo Aproximado | B13: 3
A14: Descripcion
A15: Se mostrará una imagen donde se muestre la honestidad cuando se trabaja en grupos.
A17: Como se relaciona con los conocimientos de la sesion y se aplicaria
A18: Cada estudiante debe ser honesto al documentar sus commits, explicar claramente qué hizo y no atribuirse trabajo ajeno.
A21: 2. Área Conocimiento (Saber) | G21: Tiempo Aproximado | H21: =SUM(D39:H42) -> 60
G22: No puede exceder los 60 minutos
A23: Competencia a desarrollar | B23: Genera soluciones de software aplicando buenas prácticas de análisis, control de versiones y metodologías ágiles para garantizar proyectos eficientes y colaborativos en entornos virtuales de trabajo
A24: Competencia a desarrollar
A26: 2.1 Contenido
A27: No. | B27: Unidad | D27: Tema | F27: Sub Tema
A28: 1 | B28: 1. Control de Versiones | D28: Git | F28: Introducción
A29: 2 | B29: 1. Control de Versiones | D29: Git | F29: Fases de Git
A30: 3 | B30: 1. Control de Versiones | D30: Git | F30: Buenas Prácticas en Git
A31: 4 | B31: 1. Control de Versiones | D31: Git | F31: Estructura de commits
A32: 5 | B32: 1. Control de Versiones | D32: Git | F32: Comandos
A33: 6 | B33: 1. Control de Versiones | D33: Git | F33: Ramas
A34: 7
A36: 2.2 Recursos Educativos
A38: Tipo de Recurso a utilizar | B38: Tipo | C38: Rango Aproximando | D38: Tiempo Aproximado
A39: Presentacion | B39: Obligatorio | C39: 20 a 30 minutos | D39: 30
A40: Video | B40: Obligatorio | C40: 3 a 6 minutos | D40: 5
A41: Lectura | B41: Optativo | D41: 0
A42: Ejercicio Demostrativo | B42: Obligatorio | C42: 20 a 25 minutos | D42: 25
A44: 3. Área de Habilidades (Saber Hacer) | G44: Tiempo Aproximado | H44: =B50 -> 30
G45: Tiene que estar en un rango de 30 a 50 minutos
A46: Actividad 1 (Obligatoria)
A47: Competencia que predomina en la actividad | B47: Genera soluciones de software aplicando buenas prácticas de análisis, control de versiones y metodologías ágiles para garantizar proyectos eficientes y colaborativos en entornos virtuales de trabajo
A48: Tipo de Actividad | B48: Cuestionario
A49: Ponderación | B49: 1
A50: Tiempo Aproximado | B50: 30
...

Sheet S.3
B2: Diseño de la Sesión de Laboratorio
B4: Curso | C4: ='Diseño'!C4 -> 283 - Análisis y Diseño de Sistemas 1
B5: Semana | C5: 3
B6: Tiempo | C6: =H10+H21+H44+H68 -> 103
B7: Ponderación | C7: =B49+B60 -> 1
B8: Validación de Tiempo | C8: =IF(H44<=0, "❌ ERROR: La Actividad 1 debe tener un tiempo mayor a 0.", IF(H21>60, "❌ ERROR: El 'Área de Conocimiento' no puede exceder los 60 min.", IF((H10+H21+H44+H68)<100, "❌ ERROR: El tiempo total debe ser de al menos 100 min.", "✅ VALIDACIÓN CORRECTA"))) -> ✅ VALIDACIÓN CORRECTA
A10: 1. Área Actitudinal (Saber Ser) | G10: Tiempo Aproximado | H10: =B13 -> 3
G11: Tiene que estar en un rango de 3 a 5 minutos
A12: Nombre del Valor | B12: Tolerancia
A13: Tiempo Aproximado | B13: 3
A14: Descripcion
A15: Se manifiesta al trabajar en equipo, ya que no todos los miembros programan igual ni cometen la misma cantidad de errores.
A17: Como se relaciona con los conocimientos de la sesion y se aplicaria
A18: La herramienta facilita esa tolerancia porque permite experimentar, corregir y aprender sin perder el trabajo de otros, promoviendo un ambiente de tolerancia.
A21: 2. Área Conocimiento (Saber) | G21: Tiempo Aproximado | H21: =SUM(D39:H42) -> 60
G22: No puede exceder los 60 minutos
A23: Competencia a desarrollar | B23: Genera soluciones de software aplicando buenas prácticas de análisis, control de versiones y metodologías ágiles para garantizar proyectos eficientes y colaborativos en entornos virtuales de trabajo
A24: Competencia a desarrollar
A26: 2.1 Contenido
A27: No. | B27: Unidad | D27: Tema | F27: Sub Tema
A28: 1 | B28: 1. Control de Versiones | D28: GitFlow y Versionamiento Semántico | F28: Introducción
A29: 2 | B29: 1. Control de Versiones | D29: GitFlow y Versionamiento Semántico | F29: Ramas principales
A30: 3 | B30: 1. Control de Versiones | D30: GitFlow y Versionamiento Semántico | F30: Ramas desarrollo
A31: 4 | B31: 1. Control de Versiones | D31: GitFlow y Versionamiento Semántico | F31: Flujo de trabajo
A32: 5 | B32: 1. Control de Versiones | D32: GitFlow y Versionamiento Semántico | F32: Versionamiento semántico
A33: 6 | B33: 1. Control de Versiones | D33: GitFlow y Versionamiento Semántico | F33: Releases
A34: 7
A36: 2.2 Recursos Educativos
A38: Tipo de Recurso a utilizar | B38: Tipo | C38: Rango Aproximando | D38: Tiempo Aproximado
A39: Presentacion | B39: Obligatorio | C39: 20 a 30 minutos | D39: 30
A40: Video | B40: Obligatorio | C40: 3 a 6 minutos | D40: 5
A41: Lectura | B41: Optativo | D41: 0
A42: Ejercicio Demostrativo | B42: Obligatorio | C42: 20 a 25 minutos | D42: 25
A44: 3. Área de Habilidades (Saber Hacer) | G44: Tiempo Aproximado | H44: =B50 -> 30
G45: Tiene que estar en un rango de 30 a 50 minutos
A46: Actividad 1 (Obligatoria)
A47: Competencia que predomina en la actividad | B47: Genera soluciones de software aplicando buenas prácticas de análisis, control de versiones y metodologías ágiles para garantizar proyectos eficientes y colaborativos en entornos virtuales de trabajo
A48: Tipo de Actividad | B48: Cuestionario
A49: Ponderación | B49: 1
A50: Tiempo Aproximado | B50: 30
...

Sheet S.4
B2: Diseño de la Sesión de Laboratorio
B4: Curso | C4: ='Diseño'!C4 -> 283 - Análisis y Diseño de Sistemas 1
B5: Semana | C5: 4
B6: Tiempo | C6: =H10+H21+H44+H68 -> 103
B7: Ponderación | C7: =B49+B60 -> 1
B8: Validación de Tiempo | C8: =IF(H44<=0, "❌ ERROR: La Actividad 1 debe tener un tiempo mayor a 0.", IF(H21>60, "❌ ERROR: El 'Área de Conocimiento' no puede exceder los 60 min.", IF((H10+H21+H44+H68)<100, "❌ ERROR: El tiempo total debe ser de al menos 100 min.", "✅ VALIDACIÓN CORRECTA"))) -> ✅ VALIDACIÓN CORRECTA
A10: 1. Área Actitudinal (Saber Ser) | G10: Tiempo Aproximado | H10: =B13 -> 3
G11: Tiene que estar en un rango de 3 a 5 minutos
A12: Nombre del Valor | B12: Empatia
A13: Tiempo Aproximado | B13: 3
A14: Descripcion
A15: El diseñador identifica frustraciones y expectativas reales.
A17: Como se relaciona con los conocimientos de la sesion y se aplicaria
A18: Es la capacidad de comprender las necesidades, emociones y limitaciones de los usuarios para diseñar interfaces que realmente resuelvan sus problemas
A21: 2. Área Conocimiento (Saber) | G21: Tiempo Aproximado | H21: =SUM(D39:H42) -> 60
G22: No puede exceder los 60 minutos
A23: Competencia a desarrollar | B23: Genera soluciones de software aplicando buenas prácticas de análisis, control de versiones y metodologías ágiles para garantizar proyectos eficientes y colaborativos en entornos virtuales de trabajo
A24: Competencia a desarrollar
A26: 2.1 Contenido
A27: No. | B27: Unidad | D27: Tema | F27: Sub Tema
A28: 1 | B28: 2. Diseño y Desarrollo de Sistemas | D28: UX/UI | F28: Introducción
A29: 2 | B29: 2. Diseño y Desarrollo de Sistemas | D29: UX/UI | F29: 10 Principios de Jakob Nielsen
A30: 3 | B30: 2. Diseño y Desarrollo de Sistemas | D30: UX/UI | F30: Evolución de las interfaces de usuario
A31: 4 | B31: 2. Diseño y Desarrollo de Sistemas | D31: UX/UI | F31: Herramientas para UX/UI
A32: 5 | B32: 2. Diseño y Desarrollo de Sistemas | D32: UX/UI | F32: UX/UI con Frameworks
A33: 6
A34: 7
A36: 2.2 Recursos Educativos
A38: Tipo de Recurso a utilizar | B38: Tipo | C38: Rango Aproximando | D38: Tiempo Aproximado
A39: Presentacion | B39: Obligatorio | C39: 20 a 30 minutos | D39: 30
A40: Video | B40: Obligatorio | C40: 3 a 6 minutos | D40: 5
A41: Lectura | B41: Optativo | D41: 0
A42: Ejercicio Demostrativo | B42: Obligatorio | C42: 20 a 25 minutos | D42: 25
A44: 3. Área de Habilidades (Saber Hacer) | G44: Tiempo Aproximado | H44: =B50 -> 30
G45: Tiene que estar en un rango de 30 a 50 minutos
A46: Actividad 1 (Obligatoria)
A47: Competencia que predomina en la actividad | B47: Identifica requerimientos funcionales y no funcionales mediante análisis de procesos actuales, revisión de documentación y elaboración de casos de uso para asegurar que el sistema cumpla con las necesidades del usuario
A48: Tipo de Actividad | B48: Ejercicio practico
A49: Ponderación | B49: 1
A50: Tiempo Aproximado | B50: 30
...

Sheet S.5
B2: Diseño de la Sesión de Laboratorio
B4: Curso | C4: ='Diseño'!C4 -> 283 - Análisis y Diseño de Sistemas 1
B5: Semana | C5: 5
B6: Tiempo | C6: =H10+H21+H44+H68 -> 103
B7: Ponderación | C7: =B49+B60 -> 3
B8: Validación de Tiempo | C8: =IF(H44<=0, "❌ ERROR: La Actividad 1 debe tener un tiempo mayor a 0.", IF(H21>60, "❌ ERROR: El 'Área de Conocimiento' no puede exceder los 60 min.", IF((H10+H21+H44+H68)<100, "❌ ERROR: El tiempo total debe ser de al menos 100 min.", "✅ VALIDACIÓN CORRECTA"))) -> ✅ VALIDACIÓN CORRECTA
A10: 1. Área Actitudinal (Saber Ser) | G10: Tiempo Aproximado | H10: =B13 -> 3
G11: Tiene que estar en un rango de 3 a 5 minutos
A12: Nombre del Valor | B12: Responsabilidad
A13: Tiempo Aproximado | B13: 3
A14: Descripcion
A15: La responsabilidad es la capacidad de cumplir con los compromisos adquiridos, asumir las consecuencias de las propias acciones y actuar de manera confiable y ética.
A17: Como se relaciona con los conocimientos de la sesion y se aplicaria
A18: En metodologías ágiles como Scrum o Kanban, la responsabilidad se refleja en que cada miembro del equipo cumple con sus tareas asignadas, documenta adecuadamente su trabajo en Git, informa sobre retrasos o problemas, y participa activamente en las reuniones de planificación y retrospectivas.
A21: 2. Área Conocimiento (Saber) | G21: Tiempo Aproximado | H21: =SUM(D39:H42) -> 60
G22: No puede exceder los 60 minutos
A23: Competencia a desarrollar | B23: Utiliza metodologias agiles como scrum y tableros Kanban para entregar software funcional en cortos periodos de tiempo
A24: Competencia a desarrollar
A26: 2.1 Contenido
A27: No. | B27: Unidad | D27: Tema | F27: Sub Tema
A28: 1 | B28: 3. Metodologias de Desarrollo | D28: Introducción a las Metodologías de Desarrollo | F28: Introducción
A29: 2 | B29: 3. Metodologias de Desarrollo | D29: Introducción a las Metodologías de Desarrollo | F29: Historia
A30: 3 | B30: 3. Metodologias de Desarrollo | D30: Introducción a las Metodologías de Desarrollo | F30: Metodologias robustas
A31: 4 | B31: 3. Metodologias de Desarrollo | D31: Introducción a las Metodologías de Desarrollo | F31: Metodologias Agiles
A32: 5 | B32: 3. Metodologias de Desarrollo | D32: Introducción a las Metodologías de Desarrollo | F32: Factores para la Selección de una Metodología
A33: 6 | B33: 3. Metodologias de Desarrollo | D33: Introducción a las Metodologías de Desarrollo | F33: Tendencias Actuales y Futuras
A34: 7
A36: 2.2 Recursos Educativos
A38: Tipo de Recurso a utilizar | B38: Tipo | C38: Rango Aproximando | D38: Tiempo Aproximado
A39: Presentacion | B39: Obligatorio | C39: 20 a 30 minutos | D39: 30
A40: Video | B40: Obligatorio | C40: 3 a 6 minutos | D40: 5
A41: Lectura | B41: Optativo | D41: 0
A42: Ejercicio Demostrativo | B42: Obligatorio | C42: 20 a 25 minutos | D42: 25
A44: 3. Área de Habilidades (Saber Hacer) | G44: Tiempo Aproximado | H44: =B50 -> 30
G45: Tiene que estar en un rango de 30 a 50 minutos
A46: Actividad 1 (Obligatoria)
A47: Competencia que predomina en la actividad | B47: Coordina el desarrollo de soluciones grupales empleando metodologias agiles y plataformas colaborativas para organizar y ejecutar reuniones que favorezcan la toma de decisiones y el cumplimiento de objetivos en entornos de trabajo en equipo.
A48: Tipo de Actividad | B48: Cuestionario
A49: Ponderación | B49: 3
A50: Tiempo Aproximado | B50: 30
...

Sheet S.6
B2: Diseño de la Sesión de Laboratorio
B4: Curso | C4: ='Diseño'!C4 -> 283 - Análisis y Diseño de Sistemas 1
B5: Semana | C5: 6
B6: Tiempo | C6: =H10+H21+H44+H68 -> 103
B7: Ponderación | C7: =B49+B60 -> 1
B8: Validación de Tiempo | C8: =IF(H44<=0, "❌ ERROR: La Actividad 1 debe tener un tiempo mayor a 0.", IF(H21>60, "❌ ERROR: El 'Área de Conocimiento' no puede exceder los 60 min.", IF((H10+H21+H44+H68)<100, "❌ ERROR: El tiempo total debe ser de al menos 100 min.", "✅ VALIDACIÓN CORRECTA"))) -> ✅ VALIDACIÓN CORRECTA
A10: 1. Área Actitudinal (Saber Ser) | G10: Tiempo Aproximado | H10: =B13 -> 3
G11: Tiene que estar en un rango de 3 a 5 minutos
A12: Nombre del Valor | B12: Solidaridad
A13: Tiempo Aproximado | B13: 3
A14: Descripcion
A15: La solidaridad es la disposición a colaborar, apoyar y compartir conocimientos o recursos con los demás, especialmente en momentos de dificultad, buscando el bien común por encima del interés individual
A17: Como se relaciona con los conocimientos de la sesion y se aplicaria
A18: La solidaridad se manifiesta cuando los miembros del equipo se apoyan entre sí para cumplir los objetivos del sprint.
A21: 2. Área Conocimiento (Saber) | G21: Tiempo Aproximado | H21: =SUM(D39:H42) -> 60
G22: No puede exceder los 60 minutos
A23: Competencia a desarrollar | B23: Utiliza metodologias agiles como scrum y tableros Kanban para entregar software funcional en cortos periodos de tiempo
A24: Competencia a desarrollar | B24: Coordina el desarrollo de soluciones grupales empleando metodologias agiles y plataformas colaborativas para organizar y ejecutar reuniones que favorezcan la toma de decisiones y el cumplimiento de objetivos en entornos de trabajo en equipo.
A26: 2.1 Contenido
A27: No. | B27: Unidad | D27: Tema | F27: Sub Tema
A28: 1 | B28: 3. Metodologias de Desarrollo | D28: Scrum | F28: Introducción
A29: 2 | B29: 3. Metodologias de Desarrollo | D29: Scrum | F29: Roles
A30: 3 | B30: 3. Metodologias de Desarrollo | D30: Scrum | F30: Artefactos
A31: 4 | B31: 3. Metodologias de Desarrollo | D31: Scrum | F31: Eventos
A32: 5 | B32: 3. Metodologias de Desarrollo | D32: Scrum | F32: Pilares
A33: 6 | B33: 3. Metodologias de Desarrollo | D33: Scrum | F33: Técnicas de Estimación
A34: 7
A36: 2.2 Recursos Educativos
A38: Tipo de Recurso a utilizar | B38: Tipo | C38: Rango Aproximando | D38: Tiempo Aproximado
A39: Presentacion | B39: Obligatorio | C39: 20 a 30 minutos | D39: 30
A40: Video | B40: Obligatorio | C40: 3 a 6 minutos | D40: 5
A41: Lectura | B41: Optativo | D41: 0
A42: Ejercicio Demostrativo | B42: Obligatorio | C42: 20 a 25 minutos | D42: 25
A44: 3. Área de Habilidades (Saber Hacer) | G44: Tiempo Aproximado | H44: =B50 -> 30
G45: Tiene que estar en un rango de 30 a 50 minutos
A46: Actividad 1 (Obligatoria)
A47: Competencia que predomina en la actividad | B47: Integra herramientas de gestión de requerimientos, pruebas y despliegue continuo utilizando estándares de calidad de software y herramientas como Jira, Git y CI/CD con el fin de asegurar la trazabilidad, confiabilidad y funcionalidad del sistema
A48: Tipo de Actividad | B48: Ejercicio practico
A49: Ponderación | B49: 1
A50: Tiempo Aproximado | B50: 30
...

Sheet S.7
B2: Diseño de la Sesión de Laboratorio
B4: Curso | C4: ='Diseño'!C4 -> 283 - Análisis y Diseño de Sistemas 1
B5: Semana | C5: 7
B6: Tiempo | C6: =H10+H21+H44+H68 -> 103
B7: Ponderación | C7: =B49+B60 -> 1
B8: Validación de Tiempo | C8: =IF(H44<=0, "❌ ERROR: La Actividad 1 debe tener un tiempo mayor a 0.", IF(H21>60, "❌ ERROR: El 'Área de Conocimiento' no puede exceder los 60 min.", IF((H10+H21+H44+H68)<100, "❌ ERROR: El tiempo total debe ser de al menos 100 min.", "✅ VALIDACIÓN CORRECTA"))) -> ✅ VALIDACIÓN CORRECTA
A10: 1. Área Actitudinal (Saber Ser) | G10: Tiempo Aproximado | H10: =B13 -> 3
G11: Tiene que estar en un rango de 3 a 5 minutos
A12: Nombre del Valor | B12: Disciplina
A13: Tiempo Aproximado | B13: 3
A14: Descripcion
A15: La disciplina es la capacidad de actuar de manera ordenada, constante y responsable, cumpliendo con normas, procesos y compromisos sin necesidad de supervisión constante
A17: Como se relaciona con los conocimientos de la sesion y se aplicaria
A18: En Kanban, la disciplina se refleja en la gestión estricta del flujo de trabajo: mantener las tarjetas actualizadas en el tablero, respetar los límites de trabajo en curso, priorizar tareas correctamente y moverlas a las columnas correspondientes según su estado.
A21: 2. Área Conocimiento (Saber) | G21: Tiempo Aproximado | H21: =SUM(D39:H42) -> 60
G22: No puede exceder los 60 minutos
A23: Competencia a desarrollar | B23: Integra herramientas de gestión de requerimientos, pruebas y despliegue continuo utilizando estándares de calidad de software y herramientas como Jira, Git y CI/CD con el fin de asegurar la trazabilidad, confiabilidad y funcionalidad del sistema
A24: Competencia a desarrollar | B24: Utiliza metodologias agiles como scrum y tableros Kanban para entregar software funcional en cortos periodos de tiempo
A26: 2.1 Contenido
A27: No. | B27: Unidad | D27: Tema | F27: Sub Tema
A28: 1 | B28: 3. Metodologias de Desarrollo | D28: Agilidad y Organización de Proyectos | F28: Introduccion
A29: 2 | B29: 3. Metodologias de Desarrollo | D29: Agilidad y Organización de Proyectos | F29: Jira
A30: 3 | B30: 3. Metodologias de Desarrollo | D30: Agilidad y Organización de Proyectos | F30: Trello
A31: 4 | B31: 3. Metodologias de Desarrollo | D31: Agilidad y Organización de Proyectos | F31: Fundamentos de la Gestión Visual
A32: 5
A33: 6
A34: 7
A36: 2.2 Recursos Educativos
A38: Tipo de Recurso a utilizar | B38: Tipo | C38: Rango Aproximando | D38: Tiempo Aproximado
A39: Presentacion | B39: Obligatorio | C39: 20 a 30 minutos | D39: 30
A40: Video | B40: Obligatorio | C40: 3 a 6 minutos | D40: 5
A41: Lectura | B41: Optativo | D41: 0
A42: Ejercicio Demostrativo | B42: Obligatorio | C42: 20 a 25 minutos | D42: 25
A44: 3. Área de Habilidades (Saber Hacer) | G44: Tiempo Aproximado | H44: =B50 -> 30
G45: Tiene que estar en un rango de 30 a 50 minutos
A46: Actividad 1 (Obligatoria)
A47: Competencia que predomina en la actividad | B47: Utiliza metodologias agiles como scrum y tableros Kanban para entregar software funcional en cortos periodos de tiempo
A48: Tipo de Actividad | B48: actividades
A49: Ponderación | B49: 1
A50: Tiempo Aproximado | B50: 30
...

Sheet S.8
B2: Diseño de la Sesión de Laboratorio
B4: Curso | C4: ='Diseño'!C4 -> 283 - Análisis y Diseño de Sistemas 1
B5: Semana | C5: 8
B6: Tiempo | C6: =H10+H21+H44+H68 -> 103
B7: Ponderación | C7: =B49+B60 -> 1
B8: Validación de Tiempo | C8: =IF(H44<=0, "❌ ERROR: La Actividad 1 debe tener un tiempo mayor a 0.", IF(H21>60, "❌ ERROR: El 'Área de Conocimiento' no puede exceder los 60 min.", IF((H10+H21+H44+H68)<100, "❌ ERROR: El tiempo total debe ser de al menos 100 min.", "✅ VALIDACIÓN CORRECTA"))) -> ✅ VALIDACIÓN CORRECTA
A10: 1. Área Actitudinal (Saber Ser) | G10: Tiempo Aproximado | H10: =B13 -> 3
G11: Tiene que estar en un rango de 3 a 5 minutos
A12: Nombre del Valor | B12: Responsabilidad
A13: Tiempo Aproximado | B13: 3
A14: Descripcion
A15: La responsabilidad es la capacidad de cumplir con los compromisos adquiridos y asumir las consecuencias de las propias acciones, asegurando que el trabajo realizado sea confiable
A17: Como se relaciona con los conocimientos de la sesion y se aplicaria
A18: La responsabilidad se refleja en la creación y ejecución de pruebas unitarias para verificar que cada componente funcione correctamente
A21: 2. Área Conocimiento (Saber) | G21: Tiempo Aproximado | H21: =SUM(D39:H42) -> 60
G22: No puede exceder los 60 minutos
A23: Competencia a desarrollar | B23: Identifica requerimientos funcionales y no funcionales mediante análisis de procesos actuales, revisión de documentación y elaboración de casos de uso para asegurar que el sistema cumpla con las necesidades del usuario
A24: Competencia a desarrollar | B24: Valida la calidad del software mediante pruebas unitarias, pruebas E2E y herramientas de cobertura de código para detectar errores tempranos y mejorar la confiabilidad del sistema
A26: 2.1 Contenido
A27: No. | B27: Unidad | D27: Tema | F27: Sub Tema
A28: 1 | B28: 2. Diseño y Desarrollo de Sistemas | D28: Garantía de Calidad del Software | F28: Pruebas funcionales y no funcionales
A29: 2 | B29: 2. Diseño y Desarrollo de Sistemas | D29: Garantía de Calidad del Software | F29: Piramide de pruebas
A30: 3 | B30: 2. Diseño y Desarrollo de Sistemas | D30: Garantía de Calidad del Software | F30: Pruebas unitarias
A31: 4 | B31: 2. Diseño y Desarrollo de Sistemas | D31: Garantía de Calidad del Software | F31: Mocks, stubs y fakes
A32: 5 | B32: 2. Diseño y Desarrollo de Sistemas | D32: Garantía de Calidad del Software | F32: Cobertura de código y métricas
A33: 6
A34: 7
A36: 2.2 Recursos Educativos
A38: Tipo de Recurso a utilizar | B38: Tipo | C38: Rango Aproximando | D38: Tiempo Aproximado
A39: Presentacion | B39: Obligatorio | C39: 20 a 30 minutos | D39: 30
A40: Video | B40: Obligatorio | C40: 3 a 6 minutos | D40: 5
A41: Lectura | B41: Optativo | D41: 0
A42: Ejercicio Demostrativo | B42: Obligatorio | C42: 20 a 25 minutos | D42: 25
A44: 3. Área de Habilidades (Saber Hacer) | G44: Tiempo Aproximado | H44: =B50 -> 30
G45: Tiene que estar en un rango de 30 a 50 minutos
A46: Actividad 1 (Obligatoria)
A47: Competencia que predomina en la actividad | B47: Crea ..
A48: Tipo de Actividad | B48: Analisis
A49: Ponderación | B49: 1
A50: Tiempo Aproximado | B50: 30
...

Sheet S.9
B2: Diseño de la Sesión de Laboratorio
B4: Curso | C4: ='Diseño'!C4 -> 283 - Análisis y Diseño de Sistemas 1
B5: Semana | C5: 9
B6: Tiempo | C6: =H10+H21+H44+H68 -> 103
B7: Ponderación | C7: =B49+B60 -> 1
B8: Validación de Tiempo | C8: =IF(H44<=0, "❌ ERROR: La Actividad 1 debe tener un tiempo mayor a 0.", IF(H21>60, "❌ ERROR: El 'Área de Conocimiento' no puede exceder los 60 min.", IF((H10+H21+H44+H68)<100, "❌ ERROR: El tiempo total debe ser de al menos 100 min.", "✅ VALIDACIÓN CORRECTA"))) -> ✅ VALIDACIÓN CORRECTA
A10: 1. Área Actitudinal (Saber Ser) | G10: Tiempo Aproximado | H10: =B13 -> 3
G11: Tiene que estar en un rango de 3 a 5 minutos
A12: Nombre del Valor | B12: Integridad
A13: Tiempo Aproximado | B13: 3
A14: Descripcion
A15: La integridad es la capacidad de actuar con honestidad, coherencia y ética, asegurando que las acciones se alineen con principios claros y responsables.
A17: Como se relaciona con los conocimientos de la sesion y se aplicaria
A18: La integridad se refleja en diseñar y ejecutar pruebas que validen completamente el flujo del sistema tal como lo experimentaría el usuario final.
A21: 2. Área Conocimiento (Saber) | G21: Tiempo Aproximado | H21: =SUM(D39:H42) -> 60
G22: No puede exceder los 60 minutos
A23: Competencia a desarrollar | B23: Valida la calidad del software mediante pruebas unitarias, pruebas E2E y herramientas de cobertura de código para detectar errores tempranos y mejorar la confiabilidad del sistema
A24: Competencia a desarrollar | B24: Genera soluciones de software aplicando buenas prácticas de análisis, control de versiones y metodologías ágiles para garantizar proyectos eficientes y colaborativos en entornos virtuales de trabajo
A26: 2.1 Contenido
A27: No. | B27: Unidad | D27: Tema | F27: Sub Tema
A28: 1 | B28: 2. Diseño y Desarrollo de Sistemas | D28: Garantía de Calidad del Software | F28: Pruebas No Funcionales
A29: 2 | B29: 2. Diseño y Desarrollo de Sistemas | D29: Garantía de Calidad del Software | F29: Tipos de Pruebas
A30: 3 | B30: 2. Diseño y Desarrollo de Sistemas | D30: Garantía de Calidad del Software | F30: Pruebas End to End
A31: 4 | B31: 2. Diseño y Desarrollo de Sistemas | D31: Garantía de Calidad del Software | F31: Cypress
A32: 5
A33: 6
A34: 7
A36: 2.2 Recursos Educativos
A38: Tipo de Recurso a utilizar | B38: Tipo | C38: Rango Aproximando | D38: Tiempo Aproximado
A39: Presentacion | B39: Obligatorio | C39: 20 a 30 minutos | D39: 30
A40: Video | B40: Obligatorio | C40: 3 a 6 minutos | D40: 5
A41: Lectura | B41: Optativo | D41: 0
A42: Ejercicio Demostrativo | B42: Obligatorio | C42: 20 a 25 minutos | D42: 25
A44: 3. Área de Habilidades (Saber Hacer) | G44: Tiempo Aproximado | H44: =B50 -> 30
G45: Tiene que estar en un rango de 30 a 50 minutos
A46: Actividad 1 (Obligatoria)
A47: Competencia que predomina en la actividad | B47: Valida la calidad del software mediante pruebas unitarias, pruebas E2E y herramientas de cobertura de código para detectar errores tempranos y mejorar la confiabilidad del sistema
A48: Tipo de Actividad | B48: Ejercicio practico
A49: Ponderación | B49: 1
A50: Tiempo Aproximado | B50: 30
...

Sheet S.10
B2: Diseño de la Sesión de Laboratorio
B4: Curso | C4: ='Diseño'!C4 -> 283 - Análisis y Diseño de Sistemas 1
B5: Semana | C5: 10
B6: Tiempo | C6: =H10+H21+H44+H68 -> 103
B7: Ponderación | C7: =B49+B60 -> 3
B8: Validación de Tiempo | C8: =IF(H44<=0, "❌ ERROR: La Actividad 1 debe tener un tiempo mayor a 0.", IF(H21>60, "❌ ERROR: El 'Área de Conocimiento' no puede exceder los 60 min.", IF((H10+H21+H44+H68)<100, "❌ ERROR: El tiempo total debe ser de al menos 100 min.", "✅ VALIDACIÓN CORRECTA"))) -> ✅ VALIDACIÓN CORRECTA
A10: 1. Área Actitudinal (Saber Ser) | G10: Tiempo Aproximado | H10: =B13 -> 3
G11: Tiene que estar en un rango de 3 a 5 minutos
A12: Nombre del Valor | B12: Responsabilidad
A13: Tiempo Aproximado | B13: 3
A14: Descripcion
A15: La responsabilidad implica cumplir con los compromisos asumidos, actuar de manera consciente sobre el impacto de las propias acciones
A17: Como se relaciona con los conocimientos de la sesion y se aplicaria
A18: Un desarrollador responsable documenta las imágenes y gestiona versiones para que todo el equipo pueda reproducir el entorno de desarrollo o despliegue sin errores.
A21: 2. Área Conocimiento (Saber) | G21: Tiempo Aproximado | H21: =SUM(D39:H42) -> 60
G22: No puede exceder los 60 minutos
A23: Competencia a desarrollar | B23: Integra herramientas de gestión de requerimientos, pruebas y despliegue continuo utilizando estándares de calidad de software y herramientas como Jira, Git y CI/CD con el fin de asegurar la trazabilidad, confiabilidad y funcionalidad del sistema
A24: Competencia a desarrollar | B24: Identifica requerimientos funcionales y no funcionales mediante análisis de procesos actuales, revisión de documentación y elaboración de casos de uso para asegurar que el sistema cumpla con las necesidades del usuario
A26: 2.1 Contenido
A27: No. | B27: Unidad | D27: Tema | F27: Sub Tema
A28: 1 | B28: 4. Automatizacion de ciclos de vida del software | D28: Orquestador de contenedores | F28: Introducción a docker
A29: 2 | B29: 4. Automatizacion de ciclos de vida del software | D29: Orquestador de contenedores | F29: Creación y gestión de imágenes
A30: 3 | B30: 4. Automatizacion de ciclos de vida del software | D30: Orquestador de contenedores | F30: Creación y gestión de contenedores
A31: 4 | B31: 4. Automatizacion de ciclos de vida del software | D31: Orquestador de contenedores | F31: Docker compose
A32: 5 | B32: 4. Automatizacion de ciclos de vida del software | D32: Orquestador de contenedores | F32: Container Registry
A33: 6
A34: 7
A36: 2.2 Recursos Educativos
A38: Tipo de Recurso a utilizar | B38: Tipo | C38: Rango Aproximando | D38: Tiempo Aproximado
A39: Presentacion | B39: Obligatorio | C39: 20 a 30 minutos | D39: 30
A40: Video | B40: Obligatorio | C40: 3 a 6 minutos | D40: 5
A41: Lectura | B41: Optativo | D41: 0
A42: Ejercicio Demostrativo | B42: Obligatorio | C42: 20 a 25 minutos | D42: 25
A44: 3. Área de Habilidades (Saber Hacer) | G44: Tiempo Aproximado | H44: =B50 -> 30
G45: Tiene que estar en un rango de 30 a 50 minutos
A46: Actividad 1 (Obligatoria)
A47: Competencia que predomina en la actividad | B47: Integra herramientas de gestión de requerimientos, pruebas y despliegue continuo utilizando estándares de calidad de software y herramientas como Jira, Git y CI/CD con el fin de asegurar la trazabilidad, confiabilidad y funcionalidad del sistema
A48: Tipo de Actividad | B48: Cuestionario
A49: Ponderación | B49: 3
A50: Tiempo Aproximado | B50: 30
...

Sheet S.11
B2: Diseño de la Sesión de Laboratorio
B4: Curso | C4: ='Diseño'!C4 -> 283 - Análisis y Diseño de Sistemas 1
B5: Semana | C5: 11
B6: Tiempo | C6: =H10+H21+H44+H68 -> 103
B7: Ponderación | C7: =B49+B60 -> 3
B8: Validación de Tiempo | C8: =IF(H44<=0, "❌ ERROR: La Actividad 1 debe tener un tiempo mayor a 0.", IF(H21>60, "❌ ERROR: El 'Área de Conocimiento' no puede exceder los 60 min.", IF((H10+H21+H44+H68)<100, "❌ ERROR: El tiempo total debe ser de al menos 100 min.", "✅ VALIDACIÓN CORRECTA"))) -> ✅ VALIDACIÓN CORRECTA
A10: 1. Área Actitudinal (Saber Ser) | G10: Tiempo Aproximado | H10: =B13 -> 3
G11: Tiene que estar en un rango de 3 a 5 minutos
A12: Nombre del Valor | B12: Colaboración
A13: Tiempo Aproximado | B13: 3
A14: Descripcion
A15: La colaboración es la disposición a trabajar en conjunto, compartir conocimientos y apoyar a los demás para lograr objetivos comunes.
A17: Como se relaciona con los conocimientos de la sesion y se aplicaria
A18: La colaboración es esencial porque unifica a los equipos de desarrollo y operaciones. Se refleja en prácticas como integración continua, despliegues automatizados y monitoreo conjunto
A21: 2. Área Conocimiento (Saber) | G21: Tiempo Aproximado | H21: =SUM(D39:H42) -> 60
G22: No puede exceder los 60 minutos
A23: Competencia a desarrollar | B23: Integra herramientas de gestión de requerimientos, pruebas y despliegue continuo utilizando estándares de calidad de software y herramientas como Jira, Git y CI/CD con el fin de asegurar la trazabilidad, confiabilidad y funcionalidad del sistema
A24: Competencia a desarrollar | B24: Identifica requerimientos funcionales y no funcionales mediante análisis de procesos actuales, revisión de documentación y elaboración de casos de uso para asegurar que el sistema cumpla con las necesidades del usuario
A26: 2.1 Contenido
A27: No. | B27: Unidad | D27: Tema | F27: Sub Tema
A28: 1 | B28: 4. Automatizacion de ciclos de vida del software | D28: DevOps | F28: Introducción
A29: 2 | B29: 4. Automatizacion de ciclos de vida del software | D29: DevOps | F29: Componentes de CI/CD
A30: 3 | B30: 4. Automatizacion de ciclos de vida del software | D30: DevOps | F30: Principios de integracion continua
A31: 4 | B31: 4. Automatizacion de ciclos de vida del software | D31: DevOps | F31: Beneficios de entrega continua
A32: 5 | B32: 4. Automatizacion de ciclos de vida del software | D32: DevOps | F32: Herramientas de integracion continua
A33: 6 | B33: 4. Automatizacion de ciclos de vida del software | D33: DevOps | F33: Configuracion de pipelines CI
A34: 7 | B34: 4. Automatizacion de ciclos de vida del software | D34: DevOps | F34: Ejecucion de pruebas automatizadas
A36: 2.2 Recursos Educativos
A38: Tipo de Recurso a utilizar | B38: Tipo | C38: Rango Aproximando | D38: Tiempo Aproximado
A39: Presentacion | B39: Obligatorio | C39: 20 a 30 minutos | D39: 30
A40: Video | B40: Obligatorio | C40: 3 a 6 minutos | D40: 5
A41: Lectura | B41: Optativo | D41: 0
A42: Ejercicio Demostrativo | B42: Obligatorio | C42: 20 a 25 minutos | D42: 25
A44: 3. Área de Habilidades (Saber Hacer) | G44: Tiempo Aproximado | H44: =B50 -> 30
G45: Tiene que estar en un rango de 30 a 50 minutos
A46: Actividad 1 (Obligatoria)
A47: Competencia que predomina en la actividad | B47: Integra herramientas de gestión de requerimientos, pruebas y despliegue continuo utilizando estándares de calidad de software y herramientas como Jira, Git y CI/CD con el fin de asegurar la trazabilidad, confiabilidad y funcionalidad del sistema
A48: Tipo de Actividad | B48: Cuestionario
A49: Ponderación | B49: 3
A50: Tiempo Aproximado | B50: 30
...

Sheet Proyectos
B2: Proyectos
B4: Curso | C4: ='Diseño'!C4 -> 283 - Análisis y Diseño de Sistemas 1
B5: Tiempo | C5: =H9+H26+H43 -> 160
B6: Ponderación | C6: =F9+F26+F43 -> 50
B7: La sumatoria de los puntos de los proyectos debe superar el 70% del total de la nota, no puede ser un 100%
A9: 1. Primer Proyecto | E9: Ponderación | F9: 23 | G9: Horas para realizarlo | H9: 50
A10: Obligatorio
A11: Competencia a desarrollar | B11: Utiliza metodologias agiles como scrum y tableros Kanban para entregar software funcional en cortos periodos de tiempo
A12: Competencia a desarrollar | B12: Valida la calidad del software mediante pruebas unitarias, pruebas E2E y herramientas de cobertura de código para detectar errores tempranos y mejorar la confiabilidad del sistema
A13: Competencia a desarrollar | B13: Identifica requerimientos funcionales y no funcionales mediante análisis de procesos actuales, revisión de documentación y elaboración de casos de uso para asegurar que el sistema cumpla con las necesidades del usuario
A14: Titulo | B14: Sistema Integral de Gestión y Automatización de Bibliotecas
A15: Qué tecnologías, lenguajes de programación, plataformas, hardware o software se utilizaran
A16: Bases de datos SQL, Trello, Cypress, Git
A19: Descripción de lo que se realizara
A20: El proyecto consiste en desarrollar un sistema integral para bibliotecas que permita la administración completa de recursos, usuarios y servicios. Debe incluir módulos de registro y búsqueda avanzada de libros, gestión de préstamos y devoluciones, control de disponibilidad, y administración de usuarios con roles (administrador, bibliotecario, lector). Además, se requiere implementar funcionalidades adicionales como historial de préstamos, reservas en línea, notificaciones automáticas, generación de reportes estadísticos, integración con códigos de barras o QR, y recomendaciones inteligentes de libros según preferencias del usuario.
A26: 2. Segundo Proyecto | E26: Ponderación | F26: 27 | G26: Horas para realizarlo | H26: 60
A27: Obligatorio
A28: Competencia a desarrollar | B28: Integra herramientas de gestión de requerimientos, pruebas y despliegue continuo utilizando estándares de calidad de software y herramientas como Jira, Git y CI/CD con el fin de asegurar la trazabilidad, confiabilidad y funcionalidad del sistema
A29: Competencia a desarrollar | B29: Coordina el desarrollo de soluciones grupales empleando metodologias agiles y plataformas colaborativas para organizar y ejecutar reuniones que favorezcan la toma de decisiones y el cumplimiento de objetivos en entornos de trabajo en equipo.
A30: Competencia a desarrollar | B30: Identifica requerimientos funcionales y no funcionales mediante análisis de procesos actuales, revisión de documentación y elaboración de casos de uso para asegurar que el sistema cumpla con las necesidades del usuario
A31: Titulo | B31: Sistema Integral de Gestión y Automatización de Bibliotecas
A32: Qué tecnologías, lenguajes de programación, plataformas, hardware o software se utilizaran
A33: Bases de datos SQL, Trello, Cypress, Docker, Cloud, Git
A36: Descripción de lo que se realizara
A37: Se agregaran mas funcionalidades al sistema como la gestión de inventario multimedia como audiolibros, revistas digitales y material audiovisual, soporte multilenguaje para ampliar el alcance de la plataforma y un panel de monitoreo con métricas en tiempo real sobre disponibilidad. Todo desde un pipeline CI/CD avanzado que incluya pruebas unitarias, de integración y e2e, junto con despliegues automatizados en entornos cloud
A43: 3. Tercer Proyecto | E43: Ponderación | G43: Horas para realizarlo | H43: 50
A44: Optativa
A45: Competencia a desarrollar
A46: Competencia a desarrollar
A47: Competencia a desarrollar
A48: Titulo
A49: Qué tecnologías, lenguajes de programación, plataformas, hardware o software se utilizaran
A53: Descripción de lo que se realizara

Sheet Practicas
B2: Practicas
B4: Curso | C4: ='Diseño'!C4 -> 283 - Análisis y Diseño de Sistemas 1
B5: Tiempo | C5: =H9+H26+H43+H60+H77+H94+H111 -> 40
B6: Ponderación | C6: 26
B7: La sumatoria de los puntos de los practicas debe no debe super el 20%
A9: 1. Primera Practica | E9: Ponderación | F9: 16 | G9: Horas para realizarlo | H9: 40
A10: Obligatoria
A11: Competencia a desarrollar | B11: Coordina el desarrollo de soluciones grupales empleando metodologias agiles y plataformas colaborativas para organizar y ejecutar reuniones que favorezcan la toma de decisiones y el cumplimiento de objetivos en entornos de trabajo en equipo.
A12: Competencia a desarrollar | B12: Identifica requerimientos funcionales y no funcionales mediante análisis de procesos actuales, revisión de documentación y elaboración de casos de uso para asegurar que el sistema cumpla con las necesidades del usuario
A13: Competencia a desarrollar
A14: Titulo | B14: Plataforma de reservas y citas con software generico
A15: Qué tecnologías, lenguajes de programación, plataformas, hardware o software se utilizaran
A16: Git, Tailwind, Gitkraken
A19: Descripción de lo que se realizara
A20: Se desarrollara una plataforma genérica de reservas y gestión de citas que pueda aplicarse a distintos escenarios sin necesidad de recompilar el código, únicamente mediante configuraciones y parametrización. El sistema debe incluir registro y autenticación de usuarios, con diferentes roles como administrador, empleado y cliente. Los administradores podrán configurar horarios de atención, disponibilidad de personal o recursos, tiempos de servicio, políticas de cancelación y límites de capacidad. Los clientes tendrán la posibilidad de consultar disponibilidad en tiempo real, agendar, modificar o cancelar citas, así como realizar pagos en línea si el negocio lo requiere. El sistema deberá generar notificaciones automáticas por correo para confirmar citas, enviar recordatorios o avisar sobre cambios, y ofrecer reportes personalizables con métricas de ocupación, servicios más solicitados y estadísticas de clientes. Además, deberá contar con interfaz adaptable con herramientas de UX/UI, gestión de múltiples sucursales y plantillas configurables para adaptar la imagen de la marca como clínicas médicas, salones de belleza, talleres mecánicos u otros negocios de servicios.
A26: 2. Segunda Practica | E26: Ponderación | G26: Horas para realizarlo
A27: Optativa
A28: Competencia a desarrollar
A29: Competencia a desarrollar
A30: Competencia a desarrollar
A31: Titulo
A32: Qué tecnologías, lenguajes de programación, plataformas, hardware o software se utilizaran
A36: Descripción de lo que se realizara
A43: 3. Tercera Practica | E43: Ponderación | G43: Horas para realizarlo
A44: Optativa
A45: Competencia a desarrollar
A46: Competencia a desarrollar
A47: Competencia a desarrollar
A48: Titulo
A49: Qué tecnologías, lenguajes de programación, plataformas, hardware o software se utilizaran
A53: Descripción de lo que se realizara
A60: 4. Cuarta Practica | E60: Ponderación | G60: Horas para realizarlo
A61: Optativa
A62: Competencia a desarrollar
A63: Competencia a desarrollar
A64: Competencia a desarrollar
A65: Titulo
A66: Qué tecnologías, lenguajes de programación, plataformas, hardware o software se utilizaran
A70: Descripción de lo que se realizara
A77: 5. Quinta Practica | E77: Ponderación | G77: Horas para realizarlo
...

Sheet Tareas
B2: Tareas
B4: Curso | C4: ='Diseño'!C4 -> 283 - Análisis y Diseño de Sistemas 1
B5: Tiempo | C5: =H9+H26+H43+H60+H77+H94+H111 -> 8
B6: Ponderación | C6: =F9+F26+F43+F60+F77+F94+F111 -> 8
B7: La sumatoria de los puntos de los practicas debe no debe super el 20% de la nota
A9: 1. Primera Tarea | E9: Ponderación | F9: 2 | G9: Horas para realizarlo | H9: 2
A10: Obligatoria
A11: Competencia a desarrollar | B11: Genera soluciones de software aplicando buenas prácticas de análisis, control de versiones y metodologías ágiles para garantizar proyectos eficientes y colaborativos en entornos virtuales de trabajo
A12: Competencia a desarrollar
A13: Competencia a desarrollar
A14: Titulo | B14: Repositorios publicos y tags
A15: Qué tecnologías, lenguajes de programación, plataformas, hardware o software se utilizaran
A16: Gitkraken, GIt
A19: Descripción de lo que se realizara
A20: Realizar una Api Rest que muestre su nombre y el nombre de su cancion favorita, luego de eso realizar un tag version 1.0, crear una rama hotfix para corregir un error y en lugar de la cancion cambiar por album, crear el tag 2-0 y eliminar la rama hotfix. El tag debe de llevar release
A26: 2. Segunda Tarea | E26: Ponderación | F26: 2 | G26: Horas para realizarlo | H26: 2
A27: Obligatoria
A28: Competencia a desarrollar | B28: Identifica requerimientos funcionales y no funcionales mediante análisis de procesos actuales, revisión de documentación y elaboración de casos de uso para asegurar que el sistema cumpla con las necesidades del usuario
A29: Competencia a desarrollar
A30: Competencia a desarrollar
A31: Titulo | B31: Identificar requerimientos
A32: Qué tecnologías, lenguajes de programación, plataformas, hardware o software se utilizaran
A33: Lucidchart, draw.io
A36: Descripción de lo que se realizara
A37: Dado un sitio web famoso como ebay, amazon o walmart, realizar una lista de todos los requerimientos funcionales y no funcionales que se deben implementar para que esa pagina funciona correctamente
A43: 3. Tercera Tarea | E43: Ponderación | F43: 2 | G43: Horas para realizarlo | H43: 2
A44: Optativa
A45: Competencia a desarrollar | B45: Identifica requerimientos funcionales y no funcionales mediante análisis de procesos actuales, revisión de documentación y elaboración de casos de uso para asegurar que el sistema cumpla con las necesidades del usuario
A46: Competencia a desarrollar
A47: Competencia a desarrollar
A48: Titulo | B48: Conferencia del curso
A49: Qué tecnologías, lenguajes de programación, plataformas, hardware o software se utilizaran
A53: Descripción de lo que se realizara
A54: Realizar un resumen sobre la conferencia del curso y ademas adjuntar capturas de pantalla que validen su asistencia a la misma
A60: 4. Cuarta Tarea | E60: Ponderación | F60: 2 | G60: Horas para realizarlo | H60: 2
A61: Optativa
A62: Competencia a desarrollar | B62: Utiliza metodologias agiles como scrum y tableros Kanban para entregar software funcional en cortos periodos de tiempo
A63: Competencia a desarrollar
A64: Competencia a desarrollar
A65: Titulo | B65: Pruebas E2E
...

Sheet Resumen
B2: Resumen de Ponderacion y Horas para realizar las actividades
B4: Curso | C4: ='Diseño'!C4 -> 283 - Análisis y Diseño de Sistemas 1
B5: Periodo al que aplica | C5: Primer Semestre 2026
B6: Total de Puntos del Laboratorio
A9: Actividades Formativas | D9: Proyectos
A10: Debe abarcar entre el 20% y 30% de la Nota | D10: Debe abarcar entre el 60% y 70% de la Nota
A12: Tipo de Actividad | B12: Ponderacion | C12: Horas Aproximadas para realizarlo | D12: Observaciones
A13: Actividades durante el peridodo de laboratorio | B13: =S.2!C7+S.3!C7+S.4!C7+S.5!C7+S.6!C7+S.7!C7+S.8!C7+S.9!C7+S.10!C7+S.11!C7 -> 16 | E13: Sumatoria de todas las semas
A14: Proyectos | B14: =Proyectos!C6 -> 50 | C14: =Proyectos!C5 -> 160
A15: Practicas | B15: 16 | C15: =Practicas!C5 -> 40
A16: Tareas | B16: =Tareas!C6 -> 8 | C16: =Tareas!C5 -> 8
A17: Examen Final | B17: 10 | C17: 1
A18: Total | B18: =SUM(B13:B17) -> 100 | C18: =SUM(C13:C17) -> 209

Sheet METADATA
A1: =IFERROR(__xludf.DUMMYFUNCTION("IMPORTRANGE(""1j2lHEvOoZ_EPY086Qt7f7AFaZGVfiYKJxXlsnNfWCA0"",""Listado Cursos!H:L"")"),"#REF!") -> #REF! | H1: =IFERROR(__xludf.DUMMYFUNCTION("IMPORTRANGE(VLOOKUP('Diseño'!C4,A:E,4,FALSE), ""Competencias_1re_Sem_2026!B10:J23"")"),"#N/A") -> #N/A
I17: =I2
I18: =I4
I19: =I6
I20: =I8
I21: =I10
I22: =I12
I23: =I14
