Workbook

Sheet Diseño Curricular
A1: Curso | B1: 90 - Programacion de Computadoras 1 | F1: ⬅️ Seleccióna el curso.
A3: No. | B3: Competencia | C3: Unidad | D3: Tema | E3: Subtema | F3: Mes | G3: Semana
A4: 1 | B4: Aplica conceptos fundamentales de programación mediante ejercicios prácticos y análisis de código, en entornos virtuales de laboratorio para desarrollar el pensamiento lógico y computacional | C4: 1 | D4: Inicio y Diagnóstico | E4: ¿Qué es la programación? | F4: Julio | G4: 1
A5: 2 | B5: Aplica conceptos fundamentales de programación mediante ejercicios prácticos y análisis de código, en entornos virtuales de laboratorio para desarrollar el pensamiento lógico y computacional | C5: 1 | D5: Inicio y Diagnóstico | E5: ¿Qué es un lenguaje de programación? | F5: Julio | G5: 1
A6: 3 | B6: Aplica conceptos fundamentales de programación mediante ejercicios prácticos y análisis de código, en entornos virtuales de laboratorio para desarrollar el pensamiento lógico y computacional | C6: 1 | D6: Inicio y Diagnóstico | E6: Variables y tipos de variables | F6: Julio | G6: 1
A7: 4 | B7: Aplica conceptos fundamentales de programación mediante ejercicios prácticos y análisis de código, en entornos virtuales de laboratorio para desarrollar el pensamiento lógico y computacional | C7: 1 | D7: Inicio y Diagnóstico | E7: Tipos de variables | F7: Julio | G7: 1
A8: 5 | B8: Aplica conceptos fundamentales de programación mediante ejercicios prácticos y análisis de código, en entornos virtuales de laboratorio para desarrollar el pensamiento lógico y computacional | C8: 1 | D8: Inicio y Diagnóstico | E8: Estructuras de control | F8: Julio | G8: 1
A9: 6 | B9: Aplica conceptos fundamentales de programación mediante ejercicios prácticos y análisis de código, en entornos virtuales de laboratorio para desarrollar el pensamiento lógico y computacional | C9: 1 | D9: Inicio y Diagnóstico | E9: Condiciones en programación | F9: Julio | G9: 1
A10: 7 | B10: Aplica conceptos fundamentales de programación mediante ejercicios prácticos y análisis de código, en entornos virtuales de laboratorio para desarrollar el pensamiento lógico y computacional | C10: 1 | D10: Inicio y Diagnóstico | E10: Ejemplos prácticos de estructuras de control | F10: Julio | G10: 1
A11: 8 | B11: Aplica conceptos fundamentales de programación mediante ejercicios prácticos y análisis de código, en entornos virtuales de laboratorio para desarrollar el pensamiento lógico y computacional | C11: 1 | D11: Inicio y Diagnóstico | E11: Introducción a las máquinas virtuales | F11: Julio | G11: 2
A12: 9 | B12: Evalúa resultados obtenidos en procesos de programación y ofimática utilizando pruebas de funcionamiento, revisión crítica de errores y optimización de recursos bajo criterios de funcionalidad y eficiencia | C12: 2 | D12: Maquinas Virtuales | E12: Instalación de VirtualBox | F12: Julio | G12: 2
A13: 10 | B13: Evalúa resultados obtenidos en procesos de programación y ofimática utilizando pruebas de funcionamiento, revisión crítica de errores y optimización de recursos bajo criterios de funcionalidad y eficiencia | C13: 2 | D13: Maquinas Virtuales | E13: Configuración de la VM | F13: Julio | G13: 2
A14: 11 | B14: Evalúa resultados obtenidos en procesos de programación y ofimática utilizando pruebas de funcionamiento, revisión crítica de errores y optimización de recursos bajo criterios de funcionalidad y eficiencia | C14: 2 | D14: Maquinas Virtuales | E14: Requisitos mínimos para la VM | F14: Julio | G14: 2
A15: 12 | B15: Evalúa resultados obtenidos en procesos de programación y ofimática utilizando pruebas de funcionamiento, revisión crítica de errores y optimización de recursos bajo criterios de funcionalidad y eficiencia | C15: 2 | D15: Maquinas Virtuales | E15: Uso del DTT en el entorno de desarrollo | F15: Julio | G15: 2
... A87: 84 | B87: Evalúa resultados obtenidos en procesos de programación y ofimática utilizando pruebas de funcionamiento, revisión crítica de errores y optimización de recursos bajo criterios de funcionalidad y eficiencia | C87: 12 | D87: Final del Curso | E87: Retroalimentación de los estudiantes | F87: Octubre | G87: 12

Sheet S.Diagnostico
A1: Curso | B1: ='Diseño Curricular'!B1 -> 90 - Programacion de Computadoras 1
A3: Semana | B3: 0
A5: Valores | B5: Responsabilidad: Cumplir con tareas y tiempos establecidos. Honestidad: Realizar trabajos propios sin copiar. Colaboración: Trabajar en equipo y ayudar a otros. Disciplina: Usar correctamente las herramientas tecnológicas. Creatividad: Buscar soluciones originales y prácticas.
A6: * Recuerda que las competencias tambien forman valores identifica el valor o valores que transmitiras esa semana
A8: Nota | B8: En reunion del dia sabado 5 de abril de 2024 se tomo la decision por medio de un consenso entre los tutores que la primera semana se realizara el diagnistico del estudiante para ver los conocimientos con que cuenta
A10: No. | B10: Actividad | C10: Recurso Empleado | D10: Tiempo aproximado
A11: 1 | B11: Presentación Quien soy | C11: Presentacion | D11: 5
A12: 2 | B12: Conozco a los estudiantes | C12: Ruleta/ otros para escoger a 5 estudiantes para que se presenten | D12: 15
A13: 3 | B13: Diagnostico de conocimientos del curso anterior | C13: Cuestionario / Actividad | D13: 40
A14: 4 | B14: Exploramos el programa | C14: Lectura Explicativa | D14: 20
A15: 5 | B15: Diagnostico del nuevo contenido | C15: Cuestionario / Actividad | D15: 20

Sheet S.1
A1: Curso | B1: ='Diseño Curricular'!B1 -> 90 - Programacion de Computadoras 1
A3: Semana | B3: 1
A5: Valores | B5: Responsabilidad: Cumplir con tareas y tiempos establecidos. Honestidad: Realizar trabajos propios sin copiar. Colaboración: Trabajar en equipo y ayudar a otros. Disciplina: Usar correctamente las herramientas tecnológicas. Creatividad: Buscar soluciones originales y prácticas.
A6: * Recuerda que las competencias tambien forman valores identifica el valor o valores que transmitiras esa semana
A8: Cronograma | B8: Para mantener la atención, es recomendable variar la dinámica de la clase cada cierto tiempo, integrando actividades como preguntas, ejercicios prácticos o discusiones en grupo. Esto es clave para la educación por competencias, ya que el aprendizaje debe ser activo y aplicado.
A11: Ponderacion | B11: =SUM(C36:G36) -> 0 | F11: Total de tiempo | H11: =H25+H45+H53 -> 100
A13: Area de conocimiento
C14: Tipo de Recurso | D14: Presentacion | E14: Video | F14: Lectura Explicativa | G14: Otros
C15: Tiempo Max | D15: 25 | E15: 10 | F15: 25 | G15: 25
C16: Tiempo Planificado | D16: 25 | E16: 10 | F16: 25 | G16: 25
A17: No. | B17: Tema | C17: Subtema
A18: 1 | B18: =IFERROR(__xludf.DUMMYFUNCTION("FILTER('Diseño Curricular'!D:D,'Diseño Curricular'!G:G=$B$3)"),"Inicio y Diagnóstico") -> Inicio y Diagnóstico | C18: ¿Qué es la programación? | D18: 5 | E18: 2 | F18: 4
A19: 2 | B19: =IFERROR(__xludf.DUMMYFUNCTION("""COMPUTED_VALUE"""),"Inicio y Diagnóstico") -> Inicio y Diagnóstico | C19: ¿Qué es un lenguaje de programación? | D19: 5 | E19: 2 | F19: 4
A20: 3 | B20: =IFERROR(__xludf.DUMMYFUNCTION("""COMPUTED_VALUE"""),"Inicio y Diagnóstico") -> Inicio y Diagnóstico | C20: Variables y tipos de variables | D20: 5 | E20: 2 | F20: 4
A21: 4 | B21: =IFERROR(__xludf.DUMMYFUNCTION("""COMPUTED_VALUE"""),"Inicio y Diagnóstico") -> Inicio y Diagnóstico | C21: Tipos de variables | D21: 5 | E21: 2 | F21: 4
A22: 5 | B22: =IFERROR(__xludf.DUMMYFUNCTION("""COMPUTED_VALUE"""),"Inicio y Diagnóstico") -> Inicio y Diagnóstico | C22: Estructuras de control | D22: 5 | E22: 2 | F22: 4
A23: 6 | B23: =IFERROR(__xludf.DUMMYFUNCTION("""COMPUTED_VALUE"""),"Inicio y Diagnóstico") -> Inicio y Diagnóstico | C23: Condiciones en programación | F23: 4
A24: 7 | B24: =IFERROR(__xludf.DUMMYFUNCTION("""COMPUTED_VALUE"""),"Inicio y Diagnóstico") -> Inicio y Diagnóstico | C24: Ejemplos prácticos de estructuras de control | G24: 20
G25: Sub total de tiempo | H25: =SUM(D16:G16) -> 85
A26: Marca con una x en recurso que planificas usar para impartir el conocimiento
A27: Otros : puedes modificarlo e indicar que recurso usarias por ejemplo simuladores
A29: Area de Habilidades
A30: Recordatorio
A31: Dentro de los 100 minutos de clase toma en cuenta incluir un tiempo para formar la habilidad del estudiante. Aprender haciendo.
A33: No. | B33: Tipo | C33: Ejercicio | D33: Practica | E33: Actividad | F33: Otros | G33: Cuestionario
B34: Tiempo Maximo | C34: 25 | D34: 25 | E34: 25 | F34: 25 | G34: 15
B35: Tiempo Planificado | G35: 15
B36: Ponderacion
B37: Competencia
A38: 1 | B38: Crea soluciones digitales utilizando entornos de programación visual y aplicaciones de ofimática con estrategias de automatización básica y diseño de bases de datos para resolver problemas reales de forma efectiva | E38: 10
A39: 2 | B39: Aplica conceptos fundamentales de programación mediante ejercicios prácticos y análisis de código, en entornos virtuales de laboratorio para desarrollar el pensamiento lógico y computacional | E39: 5
A40: 3
A41: 4
A42: 5
A43: 6
A44: 7
G45: Sub total de tiempo | H45: =SUM(C35:G35) -> 15
A46: Marca con una x en recurso que planificas usar para impartir el conocimiento
A47: Otros : puedes modificarlo e indicar que recurso usarias por ejemplo exposiciones
A48: Cierre
...

Sheet S.2
A1: Curso | B1: ='Diseño Curricular'!B1 -> 90 - Programacion de Computadoras 1
A3: Semana | B3: 2
A5: Valores | B5: Responsabilidad: Cumplir con tareas y tiempos establecidos. Honestidad: Realizar trabajos propios sin copiar. Colaboración: Trabajar en equipo y ayudar a otros. Disciplina: Usar correctamente las herramientas tecnológicas. Creatividad: Buscar soluciones originales y prácticas.
A6: * Recuerda que las competencias tambien forman valores identifica el valor o valores que transmitiras esa semana
A8: Cronograma | B8: Para mantener la atención, es recomendable variar la dinámica de la clase cada cierto tiempo, integrando actividades como preguntas, ejercicios prácticos o discusiones en grupo. Esto es clave para la educación por competencias, ya que el aprendizaje debe ser activo y aplicado.
A11: Ponderacion | B11: =SUM(C36:G36) -> 0 | F11: Total de tiempo | H11: =H25+H45+H53 -> 105
A13: Area de conocimiento
C14: Tipo de Recurso | D14: Presentacion | E14: Video | F14: Lectura Explicativa | G14: Otros
C15: Tiempo Max | D15: 25 | E15: 10 | F15: 25 | G15: 25
C16: Tiempo Planificado | D16: 25 | E16: 10 | F16: 25 | G16: 20
A17: No. | B17: Tema | C17: Subtema
A18: 1 | B18: =IFERROR(__xludf.DUMMYFUNCTION("FILTER('Diseño Curricular'!D:D,'Diseño Curricular'!G:G=$B$3)"),"Inicio y Diagnóstico") -> Inicio y Diagnóstico | C18: Introducción a las máquinas virtuales | D18: 5 | E18: 2 | F18: 4
A19: 2 | B19: =IFERROR(__xludf.DUMMYFUNCTION("""COMPUTED_VALUE"""),"Maquinas Virtuales") -> Maquinas Virtuales | C19: Instalación de VirtualBox | D19: 5 | E19: 2 | F19: 4
A20: 3 | B20: =IFERROR(__xludf.DUMMYFUNCTION("""COMPUTED_VALUE"""),"Maquinas Virtuales") -> Maquinas Virtuales | C20: Configuración de la VM | D20: 5 | E20: 2 | F20: 4
A21: 4 | B21: =IFERROR(__xludf.DUMMYFUNCTION("""COMPUTED_VALUE"""),"Maquinas Virtuales") -> Maquinas Virtuales | C21: Requisitos mínimos para la VM | D21: 5 | E21: 2 | F21: 4
A22: 5 | B22: =IFERROR(__xludf.DUMMYFUNCTION("""COMPUTED_VALUE"""),"Maquinas Virtuales") -> Maquinas Virtuales | C22: Uso del DTT en el entorno de desarrollo | D22: 5 | E22: 2 | F22: 4
A23: 6 | B23: =IFERROR(__xludf.DUMMYFUNCTION("""COMPUTED_VALUE"""),"Maquinas Virtuales") -> Maquinas Virtuales | C23: Práctica en pareja con VM | F23: 4
A24: 7 | B24: =IFERROR(__xludf.DUMMYFUNCTION("""COMPUTED_VALUE"""),"Maquinas Virtuales") -> Maquinas Virtuales | C24: Resolución de dudas en foros | G24: 25
G25: Sub total de tiempo | H25: =SUM(D16:G16) -> 80
A26: Marca con una x en recurso que planificas usar para impartir el conocimiento
A27: Otros : puedes modificarlo e indicar que recurso usarias por ejemplo simuladores
A29: Area de Habilidades
A30: Recordatorio
A31: Dentro de los 100 minutos de clase toma en cuenta incluir un tiempo para formar la habilidad del estudiante. Aprender haciendo.
A33: No. | B33: Tipo | C33: Ejercicio | D33: Practica | E33: Actividad | F33: Otros | G33: Cuestionario
B34: Tiempo Maximo | C34: 25 | D34: 25 | E34: 25 | F34: 25 | G34: 15
B35: Tiempo Planificado | G35: 15
B36: Ponderacion
B37: Competencia
A38: 1 | B38: Crea soluciones digitales utilizando entornos de programación visual y aplicaciones de ofimática con estrategias de automatización básica y diseño de bases de datos para resolver problemas reales de forma efectiva | E38: 10
A39: 2 | B39: Aplica conceptos fundamentales de programación mediante ejercicios prácticos y análisis de código, en entornos virtuales de laboratorio para desarrollar el pensamiento lógico y computacional | E39: 5
A40: 3
A41: 4
A42: 5
A43: 6
A44: 7
G45: Sub total de tiempo | H45: =SUM(C35:G35) -> 15
A46: Marca con una x en recurso que planificas usar para impartir el conocimiento
A47: Otros : puedes modificarlo e indicar que recurso usarias por ejemplo exposiciones
A48: Cierre
...

Sheet S.3
A1: Curso | B1: ='Diseño Curricular'!B1 -> 90 - Programacion de Computadoras 1
A3: Semana | B3: 3
A5: Valores | B5: Responsabilidad: Cumplir con tareas y tiempos establecidos. Honestidad: Realizar trabajos propios sin copiar. Colaboración: Trabajar en equipo y ayudar a otros. Disciplina: Usar correctamente las herramientas tecnológicas. Creatividad: Buscar soluciones originales y prácticas.
A6: * Recuerda que las competencias tambien forman valores identifica el valor o valores que transmitiras esa semana
A8: Cronograma | B8: Para mantener la atención, es recomendable variar la dinámica de la clase cada cierto tiempo, integrando actividades como preguntas, ejercicios prácticos o discusiones en grupo. Esto es clave para la educación por competencias, ya que el aprendizaje debe ser activo y aplicado.
A11: Ponderacion | B11: =SUM(C36:G36) -> 0 | F11: Total de tiempo | H11: =H25+H45+H53 -> 100
A13: Area de conocimiento
C14: Tipo de Recurso | D14: Presentacion | E14: Video | F14: Lectura Explicativa | G14: Otros
C15: Tiempo Max | D15: 25 | E15: 10 | F15: 25 | G15: 20
C16: Tiempo Planificado | D16: 25 | E16: 10 | F16: 25 | G16: 20
A17: No. | B17: Tema | C17: Subtema
A18: 1 | B18: =IFERROR(__xludf.DUMMYFUNCTION("FILTER('Diseño Curricular'!D:D,'Diseño Curricular'!G:G=$B$3)"),"Introducción al Paquete Microsoft Office") -> Introducción al Paquete Microsoft Office | C18: =IFERROR(__xludf.DUMMYFUNCTION("FILTER('Diseño Curricular'!E:E,'Diseño Curricular'!G:G=$B$3)"),"Lectura General Microsoft Office") -> Lectura General Microsoft Office | D18: 5 | E18: 2 | F18: 4
A19: 2 | B19: =IFERROR(__xludf.DUMMYFUNCTION("""COMPUTED_VALUE"""),"Introducción al Paquete Microsoft Office") -> Introducción al Paquete Microsoft Office | C19: =IFERROR(__xludf.DUMMYFUNCTION("""COMPUTED_VALUE"""),"Lectura General Microsoft Word") -> Lectura General Microsoft Word | D19: 5 | E19: 2 | F19: 4
A20: 3 | B20: =IFERROR(__xludf.DUMMYFUNCTION("""COMPUTED_VALUE"""),"Introducción al Paquete Microsoft Office") -> Introducción al Paquete Microsoft Office | C20: =IFERROR(__xludf.DUMMYFUNCTION("""COMPUTED_VALUE"""),"Lectura General Microsoft Excel") -> Lectura General Microsoft Excel | D20: 5 | E20: 2 | F20: 4
A21: 4 | B21: =IFERROR(__xludf.DUMMYFUNCTION("""COMPUTED_VALUE"""),"Introducción al Paquete Microsoft Office") -> Introducción al Paquete Microsoft Office | C21: =IFERROR(__xludf.DUMMYFUNCTION("""COMPUTED_VALUE"""),"Lectura General Microsoft Power Point") -> Lectura General Microsoft Power Point | D21: 5 | E21: 2 | F21: 4
A22: 5 | B22: =IFERROR(__xludf.DUMMYFUNCTION("""COMPUTED_VALUE"""),"Introducción al Paquete Microsoft Office") -> Introducción al Paquete Microsoft Office | C22: =IFERROR(__xludf.DUMMYFUNCTION("""COMPUTED_VALUE"""),"Lectura General Microsoft Access") -> Lectura General Microsoft Access | D22: 5 | E22: 2 | F22: 4
A23: 6 | B23: =IFERROR(__xludf.DUMMYFUNCTION("""COMPUTED_VALUE"""),"Introducción al Paquete Microsoft Office") -> Introducción al Paquete Microsoft Office | C23: =IFERROR(__xludf.DUMMYFUNCTION("""COMPUTED_VALUE"""),"Lectura de la práctica única") -> Lectura de la práctica única | F23: 4
A24: 7 | B24: =IFERROR(__xludf.DUMMYFUNCTION("""COMPUTED_VALUE"""),"Introducción al Paquete Microsoft Office") -> Introducción al Paquete Microsoft Office | C24: =IFERROR(__xludf.DUMMYFUNCTION("""COMPUTED_VALUE"""),"preguntas y dudas") -> preguntas y dudas | G24: 25
G25: Sub total de tiempo | H25: =SUM(D16:G16) -> 80
A26: Marca con una x en recurso que planificas usar para impartir el conocimiento
A27: Otros : puedes modificarlo e indicar que recurso usarias por ejemplo simuladores
A29: Area de Habilidades
A30: Recordatorio
A31: Dentro de los 100 minutos de clase toma en cuenta incluir un tiempo para formar la habilidad del estudiante. Aprender haciendo.
A33: No. | B33: Tipo | C33: Ejercicio | D33: Practica | E33: Actividad | F33: Otros | G33: Cuestionario
B34: Tiempo Maximo | C34: 25 | D34: 25 | E34: 25 | F34: 25 | G34: 15
B35: Tiempo Planificado | G35: 15
B36: Ponderacion
B37: Competencia
A38: 1 | B38: Crea soluciones digitales utilizando entornos de programación visual y aplicaciones de ofimática con estrategias de automatización básica y diseño de bases de datos para resolver problemas reales de forma efectiva | C38: 10
A39: 2 | B39: Integra herramientas de ofimática como Word, Excel, PowerPoint y Access en la resolución de tareas y proyectos con base en situaciones académicas y laborales comunes | C39: 5
A40: 3
A41: 4
A42: 5
A43: 6
A44: 7
G45: Sub total de tiempo | H45: =SUM(C35:G35) -> 15
A46: Marca con una x en recurso que planificas usar para impartir el conocimiento
A47: Otros : puedes modificarlo e indicar que recurso usarias por ejemplo exposiciones
A48: Cierre
...

Sheet S.4
A1: Curso | B1: ='Diseño Curricular'!B1 -> 90 - Programacion de Computadoras 1
A3: Semana | B3: 4
A5: Valores | B5: Responsabilidad: Cumplir con tareas y tiempos establecidos. Honestidad: Realizar trabajos propios sin copiar. Colaboración: Trabajar en equipo y ayudar a otros. Disciplina: Usar correctamente las herramientas tecnológicas. Creatividad: Buscar soluciones originales y prácticas.
A6: * Recuerda que las competencias tambien forman valores identifica el valor o valores que transmitiras esa semana
A8: Cronograma | B8: Para mantener la atención, es recomendable variar la dinámica de la clase cada cierto tiempo, integrando actividades como preguntas, ejercicios prácticos o discusiones en grupo. Esto es clave para la educación por competencias, ya que el aprendizaje debe ser activo y aplicado.
A11: Ponderacion | B11: 5 | F11: Total de tiempo | H11: =H25+H45+H53 -> 100
A13: Area de conocimiento
C14: Tipo de Recurso | D14: Presentacion | E14: Video | F14: Lectura Explicativa | G14: Otros
C15: Tiempo Max | D15: 25 | E15: 10 | F15: 25 | G15: 25
C16: Tiempo Planificado | D16: 25 | E16: 10 | F16: 25 | G16: 20
A17: No. | B17: Tema | C17: Subtema
A18: 1 | B18: =IFERROR(__xludf.DUMMYFUNCTION("FILTER('Diseño Curricular'!D:D,'Diseño Curricular'!G:G=$B$3)"),"Herramientas de Excel") -> Herramientas de Excel | C18: =IFERROR(__xludf.DUMMYFUNCTION("FILTER('Diseño Curricular'!E:E,'Diseño Curricular'!G:G=$B$3)"),"Manipulación de celdas") -> Manipulación de celdas | D18: 5 | E18: 2 | F18: 4
A19: 2 | B19: =IFERROR(__xludf.DUMMYFUNCTION("""COMPUTED_VALUE"""),"Herramientas de Excel") -> Herramientas de Excel | C19: =IFERROR(__xludf.DUMMYFUNCTION("""COMPUTED_VALUE"""),"Fórmulas") -> Fórmulas | D19: 5 | E19: 2 | F19: 4
A20: 3 | B20: =IFERROR(__xludf.DUMMYFUNCTION("""COMPUTED_VALUE"""),"Herramientas de Excel") -> Herramientas de Excel | C20: =IFERROR(__xludf.DUMMYFUNCTION("""COMPUTED_VALUE"""),"Funciones") -> Funciones | D20: 5 | E20: 2 | F20: 4
A21: 4 | B21: =IFERROR(__xludf.DUMMYFUNCTION("""COMPUTED_VALUE"""),"Herramientas de Excel") -> Herramientas de Excel | C21: =IFERROR(__xludf.DUMMYFUNCTION("""COMPUTED_VALUE"""),"Creación de gráficos") -> Creación de gráficos | D21: 5 | E21: 2 | F21: 4
A22: 5 | B22: =IFERROR(__xludf.DUMMYFUNCTION("""COMPUTED_VALUE"""),"Herramientas de Excel") -> Herramientas de Excel | C22: =IFERROR(__xludf.DUMMYFUNCTION("""COMPUTED_VALUE"""),"Análisis de datos en Excel") -> Análisis de datos en Excel | D22: 5 | E22: 2 | F22: 4
A23: 6 | B23: =IFERROR(__xludf.DUMMYFUNCTION("""COMPUTED_VALUE"""),"Herramientas de Excel") -> Herramientas de Excel | C23: =IFERROR(__xludf.DUMMYFUNCTION("""COMPUTED_VALUE"""),"Uso de tablas dinámicas") -> Uso de tablas dinámicas | F23: 4
A24: 7 | B24: =IFERROR(__xludf.DUMMYFUNCTION("""COMPUTED_VALUE"""),"Herramientas de Excel") -> Herramientas de Excel | C24: =IFERROR(__xludf.DUMMYFUNCTION("""COMPUTED_VALUE"""),"Ejemplos practicos") -> Ejemplos practicos | G24: 20
G25: Sub total de tiempo | H25: 80
A26: Marca con una x en recurso que planificas usar para impartir el conocimiento
A27: Otros : puedes modificarlo e indicar que recurso usarias por ejemplo simuladores
A29: Area de Habilidades
A30: Recordatorio
A31: Dentro de los 100 minutos de clase toma en cuenta incluir un tiempo para formar la habilidad del estudiante. Aprender haciendo.
A33: No. | B33: Tipo | C33: Ejercicio | D33: Practica | E33: Actividad | F33: Otros | G33: Cuestionario
B34: Tiempo Maximo | C34: 25 | D34: 25 | E34: 25 | F34: 25 | G34: 15
B35: Tiempo Planificado | G35: 15
B36: Ponderacion
B37: Competencia
A38: 1 | B38: Crea soluciones digitales utilizando entornos de programación visual y aplicaciones de ofimática con estrategias de automatización básica y diseño de bases de datos para resolver problemas reales de forma efectiva | G38: 10
A39: 2 | B39: Integra herramientas de ofimática como Word, Excel, PowerPoint y Access en la resolución de tareas y proyectos con base en situaciones académicas y laborales comunes
A40: 3
A41: 4
A42: 5
A43: 6
A44: 7
G45: Sub total de tiempo | H45: 10
A46: Marca con una x en recurso que planificas usar para impartir el conocimiento
A47: Otros : puedes modificarlo e indicar que recurso usarias por ejemplo exposiciones
A48: Cierre
...

Sheet S.5
A1: Curso | B1: ='Diseño Curricular'!B1 -> 90 - Programacion de Computadoras 1
A3: Semana | B3: 5
A5: Valores | B5: Responsabilidad: Cumplir con tareas y tiempos establecidos. Honestidad: Realizar trabajos propios sin copiar. Colaboración: Trabajar en equipo y ayudar a otros. Disciplina: Usar correctamente las herramientas tecnológicas. Creatividad: Buscar soluciones originales y prácticas.
A6: * Recuerda que las competencias tambien forman valores identifica el valor o valores que transmitiras esa semana
A8: Cronograma | B8: Para mantener la atención, es recomendable variar la dinámica de la clase cada cierto tiempo, integrando actividades como preguntas, ejercicios prácticos o discusiones en grupo. Esto es clave para la educación por competencias, ya que el aprendizaje debe ser activo y aplicado.
A11: Ponderacion | B11: =SUM(C36:G36) -> 0 | F11: Total de tiempo | H11: =H25+H45+H53 -> 100
A13: Area de conocimiento
C14: Tipo de Recurso | D14: Presentacion | E14: Video | F14: Lectura Explicativa | G14: Otros
C15: Tiempo Max | D15: 25 | E15: 10 | F15: 25 | G15: 25
C16: Tiempo Planificado | D16: 25 | E16: 10 | F16: 25 | G16: 20
A17: No. | B17: Tema | C17: Subtema
A18: 1 | B18: =IFERROR(__xludf.DUMMYFUNCTION("FILTER('Diseño Curricular'!D:D,'Diseño Curricular'!G:G=$B$3)"),"Integración de formularios y tablas en VBA") -> Integración de formularios y tablas en VBA | C18: =IFERROR(__xludf.DUMMYFUNCTION("FILTER('Diseño Curricular'!E:E,'Diseño Curricular'!G:G=$B$3)"),"Importar y Exportar Excel con macros") -> Importar y Exportar Excel con macros | D18: 5 | E18: 2 | F18: 4
A19: 2 | B19: =IFERROR(__xludf.DUMMYFUNCTION("""COMPUTED_VALUE"""),"Integración de formularios y tablas en VBA") -> Integración de formularios y tablas en VBA | C19: =IFERROR(__xludf.DUMMYFUNCTION("""COMPUTED_VALUE"""),"Funcion de programador en Excel") -> Funcion de programador en Excel | D19: 5 | E19: 2 | F19: 4
A20: 3 | B20: =IFERROR(__xludf.DUMMYFUNCTION("""COMPUTED_VALUE"""),"Integración de formularios y tablas en VBA") -> Integración de formularios y tablas en VBA | C20: =IFERROR(__xludf.DUMMYFUNCTION("""COMPUTED_VALUE"""),"Formularios en excel con VBA") -> Formularios en excel con VBA | D20: 5 | E20: 2 | F20: 4
A21: 4 | B21: =IFERROR(__xludf.DUMMYFUNCTION("""COMPUTED_VALUE"""),"Integración de formularios y tablas en VBA") -> Integración de formularios y tablas en VBA | C21: =IFERROR(__xludf.DUMMYFUNCTION("""COMPUTED_VALUE"""),"Creación de macros en Excel") -> Creación de macros en Excel | D21: 5 | E21: 2 | F21: 4
A22: 5 | B22: =IFERROR(__xludf.DUMMYFUNCTION("""COMPUTED_VALUE"""),"Integración de formularios y tablas en VBA") -> Integración de formularios y tablas en VBA | C22: =IFERROR(__xludf.DUMMYFUNCTION("""COMPUTED_VALUE"""),"Automatización con macros") -> Automatización con macros | D22: 5 | E22: 2 | F22: 4
A23: 6 | B23: =IFERROR(__xludf.DUMMYFUNCTION("""COMPUTED_VALUE"""),"Integración de formularios y tablas en VBA") -> Integración de formularios y tablas en VBA | C23: =IFERROR(__xludf.DUMMYFUNCTION("""COMPUTED_VALUE"""),"Asignar macros a controles en excel") -> Asignar macros a controles en excel | F23: 4
A24: 7 | B24: =IFERROR(__xludf.DUMMYFUNCTION("""COMPUTED_VALUE"""),"Integración de formularios y tablas en VBA") -> Integración de formularios y tablas en VBA | C24: =IFERROR(__xludf.DUMMYFUNCTION("""COMPUTED_VALUE"""),"Ejemplos prácticos de formularios") -> Ejemplos prácticos de formularios | G24: 20
G25: Sub total de tiempo | H25: =SUM(D16:G16) -> 80
A26: Marca con una x en recurso que planificas usar para impartir el conocimiento
A27: Otros : puedes modificarlo e indicar que recurso usarias por ejemplo simuladores
A29: Area de Habilidades
A30: Recordatorio
A31: Dentro de los 100 minutos de clase toma en cuenta incluir un tiempo para formar la habilidad del estudiante. Aprender haciendo.
A33: No. | B33: Tipo | C33: Ejercicio | D33: Practica | E33: Actividad | F33: Otros | G33: Cuestionario
B34: Tiempo Maximo | C34: 25 | D34: 25 | E34: 25 | F34: 25 | G34: 15
B35: Tiempo Planificado | G35: 15
B36: Ponderacion
B37: Competencia
A38: 1 | B38: Crea soluciones digitales utilizando entornos de programación visual y aplicaciones de ofimática con estrategias de automatización básica y diseño de bases de datos para resolver problemas reales de forma efectiva | G38: 5
A39: 2 | B39: Integra herramientas de ofimática como Word, Excel, PowerPoint y Access en la resolución de tareas y proyectos con base en situaciones académicas y laborales comunes | G39: 5
A40: 3 | B40: Diseña macros automatizadas en hojas de cálculo utilizando Visual Basic para Aplicaciones (VBA) mediante la implementación de funciones y ciclos condicionales con conexión a bases de datos para optimizar tareas repetitivas | G40: 5
A41: 4
A42: 5
A43: 6
A44: 7
G45: Sub total de tiempo | H45: =SUM(C35:G35) -> 15
A46: Marca con una x en recurso que planificas usar para impartir el conocimiento
A47: Otros : puedes modificarlo e indicar que recurso usarias por ejemplo exposiciones
A48: Cierre
...

Sheet S.6
A1: Curso | B1: ='Diseño Curricular'!B1 -> 90 - Programacion de Computadoras 1
A3: Semana | B3: 6
A5: Valores | B5: Responsabilidad: Cumplir con tareas y tiempos establecidos. Honestidad: Realizar trabajos propios sin copiar. Colaboración: Trabajar en equipo y ayudar a otros. Disciplina: Usar correctamente las herramientas tecnológicas. Creatividad: Buscar soluciones originales y prácticas.
A6: * Recuerda que las competencias tambien forman valores identifica el valor o valores que transmitiras esa semana
A8: Cronograma | B8: Para mantener la atención, es recomendable variar la dinámica de la clase cada cierto tiempo, integrando actividades como preguntas, ejercicios prácticos o discusiones en grupo. Esto es clave para la educación por competencias, ya que el aprendizaje debe ser activo y aplicado.
A11: Ponderacion | B11: =SUM(C36:G36) -> 0 | F11: Total de tiempo | H11: =H25+H45+H53 -> 100
A13: Area de conocimiento
C14: Tipo de Recurso | D14: Presentacion | E14: Video | F14: Lectura Explicativa | G14: Otros
C15: Tiempo Max | D15: 25 | E15: 10 | F15: 25 | G15: 25
C16: Tiempo Planificado | D16: 25 | E16: 10 | F16: 25 | G16: 20
A17: No. | B17: Tema | C17: Subtema
A18: 1 | B18: =IFERROR(__xludf.DUMMYFUNCTION("FILTER('Diseño Curricular'!D:D,'Diseño Curricular'!G:G=$B$3)"),"Diseño de Bases de Datos") -> Diseño de Bases de Datos | C18: =IFERROR(__xludf.DUMMYFUNCTION("FILTER('Diseño Curricular'!E:E,'Diseño Curricular'!G:G=$B$3)"),"¿Qué es un diagrama ER?") -> ¿Qué es un diagrama ER? | D18: 5 | E18: 2 | F18: 4
A19: 2 | B19: =IFERROR(__xludf.DUMMYFUNCTION("""COMPUTED_VALUE"""),"Diseño de Bases de Datos") -> Diseño de Bases de Datos | C19: =IFERROR(__xludf.DUMMYFUNCTION("""COMPUTED_VALUE"""),"Propósito de los diagramas ER") -> Propósito de los diagramas ER | D19: 5 | E19: 2 | F19: 4
A20: 3 | B20: =IFERROR(__xludf.DUMMYFUNCTION("""COMPUTED_VALUE"""),"Diseño de Bases de Datos") -> Diseño de Bases de Datos | C20: =IFERROR(__xludf.DUMMYFUNCTION("""COMPUTED_VALUE"""),"Entidades y atributos") -> Entidades y atributos | D20: 5 | E20: 2 | F20: 4
A21: 4 | B21: =IFERROR(__xludf.DUMMYFUNCTION("""COMPUTED_VALUE"""),"Diseño de Bases de Datos") -> Diseño de Bases de Datos | C21: =IFERROR(__xludf.DUMMYFUNCTION("""COMPUTED_VALUE"""),"Relaciones entre entidades") -> Relaciones entre entidades | D21: 5 | E21: 2 | F21: 4
A22: 5 | B22: =IFERROR(__xludf.DUMMYFUNCTION("""COMPUTED_VALUE"""),"Diseño de Bases de Datos") -> Diseño de Bases de Datos | C22: =IFERROR(__xludf.DUMMYFUNCTION("""COMPUTED_VALUE"""),"Cardinalidad de las relaciones") -> Cardinalidad de las relaciones | D22: 5 | E22: 2 | F22: 4
A23: 6 | B23: =IFERROR(__xludf.DUMMYFUNCTION("""COMPUTED_VALUE"""),"Diseño de Bases de Datos") -> Diseño de Bases de Datos | C23: =IFERROR(__xludf.DUMMYFUNCTION("""COMPUTED_VALUE"""),"Tipos de relaciones (uno a uno, uno a muchos, etc.)") -> Tipos de relaciones (uno a uno, uno a muchos, etc.) | F23: 4
A24: 7 | B24: =IFERROR(__xludf.DUMMYFUNCTION("""COMPUTED_VALUE"""),"Diseño de Bases de Datos") -> Diseño de Bases de Datos | C24: =IFERROR(__xludf.DUMMYFUNCTION("""COMPUTED_VALUE"""),"Ejemplo práctico de un diagrama ER") -> Ejemplo práctico de un diagrama ER | G24: 20
G25: Sub total de tiempo | H25: =SUM(D16:G16) -> 80
A26: Marca con una x en recurso que planificas usar para impartir el conocimiento
A27: Otros : puedes modificarlo e indicar que recurso usarias por ejemplo simuladores
A29: Area de Habilidades
A30: Recordatorio
A31: Dentro de los 100 minutos de clase toma en cuenta incluir un tiempo para formar la habilidad del estudiante. Aprender haciendo.
A33: No. | B33: Tipo | C33: Ejercicio | D33: Practica | E33: Actividad | F33: Otros | G33: Cuestionario
B34: Tiempo Maximo | C34: 25 | D34: 25 | E34: 25 | F34: 25 | G34: 15
B35: Tiempo Planificado | G35: 15
B36: Ponderacion
B37: Competencia
A38: 1 | B38: Crea soluciones digitales utilizando entornos de programación visual y aplicaciones de ofimática con estrategias de automatización básica y diseño de bases de datos para resolver problemas reales de forma efectiva | G38: 10
A39: 2 | B39: Integra herramientas de ofimática como Word, Excel, PowerPoint y Access en la resolución de tareas y proyectos con base en situaciones académicas y laborales comunes | G39: 5
A40: 3
A41: 4
A42: 5
A43: 6
A44: 7
G45: Sub total de tiempo | H45: =SUM(C35:G35) -> 15
A46: Marca con una x en recurso que planificas usar para impartir el conocimiento
A47: Otros : puedes modificarlo e indicar que recurso usarias por ejemplo exposiciones
A48: Cierre
...

Sheet S.7
A1: Curso | B1: ='Diseño Curricular'!B1 -> 90 - Programacion de Computadoras 1
A3: Semana | B3: 7
A5: Valores | B5: Responsabilidad: Cumplir con tareas y tiempos establecidos. Honestidad: Realizar trabajos propios sin copiar. Colaboración: Trabajar en equipo y ayudar a otros. Disciplina: Usar correctamente las herramientas tecnológicas. Creatividad: Buscar soluciones originales y prácticas.
A6: * Recuerda que las competencias tambien forman valores identifica el valor o valores que transmitiras esa semana
A8: Cronograma | B8: Para mantener la atención, es recomendable variar la dinámica de la clase cada cierto tiempo, integrando actividades como preguntas, ejercicios prácticos o discusiones en grupo. Esto es clave para la educación por competencias, ya que el aprendizaje debe ser activo y aplicado.
A11: Ponderacion | B11: =SUM(C36:G36) -> 0 | F11: Total de tiempo | H11: =H25+H45+H53 -> 100
A13: Area de conocimiento
C14: Tipo de Recurso | D14: Presentacion | E14: Video | F14: Lectura Explicativa | G14: Otros
C15: Tiempo Max | D15: 25 | E15: 10 | F15: 25 | G15: 25
C16: Tiempo Planificado | D16: 25 | E16: 10 | F16: 25 | G16: 20
A17: No. | B17: Tema | C17: Subtema
A18: 1 | B18: =IFERROR(__xludf.DUMMYFUNCTION("FILTER('Diseño Curricular'!D:D,'Diseño Curricular'!G:G=$B$3)"),"Introduccion a SQL") -> Introduccion a SQL | C18: =IFERROR(__xludf.DUMMYFUNCTION("FILTER('Diseño Curricular'!E:E,'Diseño Curricular'!G:G=$B$3)"),"Que es una sentencia de SQL ") -> Que es una sentencia de SQL | D18: 5 | E18: 2 | F18: 4
A19: 2 | B19: =IFERROR(__xludf.DUMMYFUNCTION("""COMPUTED_VALUE"""),"Introduccion a SQL") -> Introduccion a SQL | C19: =IFERROR(__xludf.DUMMYFUNCTION("""COMPUTED_VALUE"""),"Cuales categorías se divide las sentencias") -> Cuales categorías se divide las sentencias | D19: 5 | E19: 2 | F19: 4
A20: 3 | B20: =IFERROR(__xludf.DUMMYFUNCTION("""COMPUTED_VALUE"""),"Introduccion a SQL") -> Introduccion a SQL | C20: =IFERROR(__xludf.DUMMYFUNCTION("""COMPUTED_VALUE"""),"Lectura de SQL General") -> Lectura de SQL General | D20: 5 | E20: 2 | F20: 4
A21: 4 | B21: =IFERROR(__xludf.DUMMYFUNCTION("""COMPUTED_VALUE"""),"Introduccion a SQL") -> Introduccion a SQL | C21: =IFERROR(__xludf.DUMMYFUNCTION("""COMPUTED_VALUE"""),"Ejemplos de sentencias DDL") -> Ejemplos de sentencias DDL | D21: 5 | E21: 2 | F21: 4
A22: 5 | B22: =IFERROR(__xludf.DUMMYFUNCTION("""COMPUTED_VALUE"""),"Introduccion a SQL") -> Introduccion a SQL | C22: =IFERROR(__xludf.DUMMYFUNCTION("""COMPUTED_VALUE"""),"Ejemplos de sentencias DML") -> Ejemplos de sentencias DML | D22: 5 | E22: 2 | F22: 4
A23: 6 | B23: =IFERROR(__xludf.DUMMYFUNCTION("""COMPUTED_VALUE"""),"Introduccion a SQL") -> Introduccion a SQL | C23: =IFERROR(__xludf.DUMMYFUNCTION("""COMPUTED_VALUE"""),"Estructuras de las sentecias") -> Estructuras de las sentecias | F23: 4
A24: 7 | B24: =IFERROR(__xludf.DUMMYFUNCTION("""COMPUTED_VALUE"""),"Introduccion a SQL") -> Introduccion a SQL | C24: =IFERROR(__xludf.DUMMYFUNCTION("""COMPUTED_VALUE"""),"Ejemplo practico de una base de datos basado en el ER") -> Ejemplo practico de una base de datos basado en el ER | G24: 20
G25: Sub total de tiempo | H25: =SUM(D16:G16) -> 80
A26: Marca con una x en recurso que planificas usar para impartir el conocimiento
A27: Otros : puedes modificarlo e indicar que recurso usarias por ejemplo simuladores
A29: Area de Habilidades
A30: Recordatorio
A31: Dentro de los 100 minutos de clase toma en cuenta incluir un tiempo para formar la habilidad del estudiante. Aprender haciendo.
A33: No. | B33: Tipo | C33: Ejercicio | D33: Practica | E33: Actividad | F33: Otros | G33: Cuestionario
B34: Tiempo Maximo | C34: 25 | D34: 25 | E34: 25 | F34: 25 | G34: 15
B35: Tiempo Planificado | G35: 15
B36: Ponderacion
B37: Competencia
A38: 1 | B38: Crea soluciones digitales utilizando entornos de programación visual y aplicaciones de ofimática con estrategias de automatización básica y diseño de bases de datos para resolver problemas reales de forma efectiva | G38: 5
A39: 2 | B39: Integra herramientas de ofimática como Word, Excel, PowerPoint y Access en la resolución de tareas y proyectos con base en situaciones académicas y laborales comunes | G39: 5
A40: 3 | B40: Formula consultas en bases de datos relacionales empleando herramientas de Access y modelos entidad-relación bajo criterios de integridad y relaciones correctas para organizar y extraer información relevante | G40: 5
A41: 4
A42: 5
A43: 6
A44: 7
G45: Sub total de tiempo | H45: =SUM(C35:G35) -> 15
A46: Marca con una x en recurso que planificas usar para impartir el conocimiento
A47: Otros : puedes modificarlo e indicar que recurso usarias por ejemplo exposiciones
A48: Cierre
...

Sheet S.8
A1: Curso | B1: ='Diseño Curricular'!B1 -> 90 - Programacion de Computadoras 1
A3: Semana | B3: 8
A5: Valores | B5: Responsabilidad: Cumplir con tareas y tiempos establecidos. Honestidad: Realizar trabajos propios sin copiar. Colaboración: Trabajar en equipo y ayudar a otros. Disciplina: Usar correctamente las herramientas tecnológicas. Creatividad: Buscar soluciones originales y prácticas.
A6: * Recuerda que las competencias tambien forman valores identifica el valor o valores que transmitiras esa semana
A8: Cronograma | B8: Para mantener la atención, es recomendable variar la dinámica de la clase cada cierto tiempo, integrando actividades como preguntas, ejercicios prácticos o discusiones en grupo. Esto es clave para la educación por competencias, ya que el aprendizaje debe ser activo y aplicado.
A11: Ponderacion | B11: 5 | F11: Total de tiempo | H11: =H25+H45+H53 -> 100
A13: Area de conocimiento
C14: Tipo de Recurso | D14: Presentacion | E14: Video | F14: Lectura Explicativa | G14: Otros
C15: Tiempo Max | D15: 25 | E15: 10 | F15: 25 | G15: 25
C16: Tiempo Planificado | D16: 25 | E16: 10 | F16: 25 | G16: 20
A17: No. | B17: Tema | C17: Subtema
A18: 1 | B18: =IFERROR(__xludf.DUMMYFUNCTION("FILTER('Diseño Curricular'!D:D,'Diseño Curricular'!G:G=$B$3)"),"Implementación en Access") -> Implementación en Access | C18: =IFERROR(__xludf.DUMMYFUNCTION("FILTER('Diseño Curricular'!E:E,'Diseño Curricular'!G:G=$B$3)"),"Importancia de diagramas ER") -> Importancia de diagramas ER | D18: 5 | E18: 2 | F18: 4
A19: 2 | B19: =IFERROR(__xludf.DUMMYFUNCTION("""COMPUTED_VALUE"""),"Implementación en Access") -> Implementación en Access | C19: =IFERROR(__xludf.DUMMYFUNCTION("""COMPUTED_VALUE"""),"Creación de tablas") -> Creación de tablas | D19: 5 | E19: 2 | F19: 4
A20: 3 | B20: =IFERROR(__xludf.DUMMYFUNCTION("""COMPUTED_VALUE"""),"Implementación en Access") -> Implementación en Access | C20: =IFERROR(__xludf.DUMMYFUNCTION("""COMPUTED_VALUE"""),"Definición de campos y tipos de datos") -> Definición de campos y tipos de datos | D20: 5 | E20: 2 | F20: 4
A21: 4 | B21: =IFERROR(__xludf.DUMMYFUNCTION("""COMPUTED_VALUE"""),"Implementación en Access") -> Implementación en Access | C21: =IFERROR(__xludf.DUMMYFUNCTION("""COMPUTED_VALUE"""),"Relaciones entre tablas") -> Relaciones entre tablas | D21: 5 | E21: 2 | F21: 4
A22: 5 | B22: =IFERROR(__xludf.DUMMYFUNCTION("""COMPUTED_VALUE"""),"Implementación en Access") -> Implementación en Access | C22: =IFERROR(__xludf.DUMMYFUNCTION("""COMPUTED_VALUE"""),"Creación de consultas en Access") -> Creación de consultas en Access | D22: 5 | E22: 2 | F22: 4
A23: 6 | B23: =IFERROR(__xludf.DUMMYFUNCTION("""COMPUTED_VALUE"""),"Implementación en Access") -> Implementación en Access | C23: =IFERROR(__xludf.DUMMYFUNCTION("""COMPUTED_VALUE"""),"Formularios en Access") -> Formularios en Access | F23: 4
A24: 7 | B24: =IFERROR(__xludf.DUMMYFUNCTION("""COMPUTED_VALUE"""),"Implementación en Access") -> Implementación en Access | C24: =IFERROR(__xludf.DUMMYFUNCTION("""COMPUTED_VALUE"""),"Lectura de la proyecto único") -> Lectura de la proyecto único | G24: 20
G25: Sub total de tiempo | H25: =SUM(D16:G16) -> 80
A26: Marca con una x en recurso que planificas usar para impartir el conocimiento
A27: Otros : puedes modificarlo e indicar que recurso usarias por ejemplo simuladores
A29: Area de Habilidades
A30: Recordatorio
A31: Dentro de los 100 minutos de clase toma en cuenta incluir un tiempo para formar la habilidad del estudiante. Aprender haciendo.
A33: No. | B33: Tipo | C33: Ejercicio | D33: Practica | E33: Actividad | F33: Otros | G33: Cuestionario
B34: Tiempo Maximo | C34: 25 | D34: 25 | E34: 25 | F34: 25 | G34: 15
B35: Tiempo Planificado | G35: 15
B36: Ponderacion
B37: Competencia
A38: 1 | B38: Crea soluciones digitales utilizando entornos de programación visual y aplicaciones de ofimática con estrategias de automatización básica y diseño de bases de datos para resolver problemas reales de forma efectiva | G38: 5
A39: 2 | B39: Integra herramientas de ofimática como Word, Excel, PowerPoint y Access en la resolución de tareas y proyectos con base en situaciones académicas y laborales comunes | G39: 5
A40: 3 | B40: Formula consultas en bases de datos relacionales empleando herramientas de Access y modelos entidad-relación bajo criterios de integridad y relaciones correctas para organizar y extraer información relevante | G40: 5
A41: 4
A42: 5
A43: 6
A44: 7
G45: Sub total de tiempo | H45: =SUM(C35:G35) -> 15
A46: Marca con una x en recurso que planificas usar para impartir el conocimiento
A47: Otros : puedes modificarlo e indicar que recurso usarias por ejemplo exposiciones
A48: Cierre
...

Sheet S.9
A1: Curso | B1: ='Diseño Curricular'!B1 -> 90 - Programacion de Computadoras 1
A3: Semana | B3: 9
A5: Valores | B5: Responsabilidad: Cumplir con tareas y tiempos establecidos. Honestidad: Realizar trabajos propios sin copiar. Colaboración: Trabajar en equipo y ayudar a otros. Disciplina: Usar correctamente las herramientas tecnológicas. Creatividad: Buscar soluciones originales y prácticas.
A6: * Recuerda que las competencias tambien forman valores identifica el valor o valores que transmitiras esa semana
A8: Cronograma | B8: Para mantener la atención, es recomendable variar la dinámica de la clase cada cierto tiempo, integrando actividades como preguntas, ejercicios prácticos o discusiones en grupo. Esto es clave para la educación por competencias, ya que el aprendizaje debe ser activo y aplicado.
A11: Ponderacion | B11: 0 | F11: Total de tiempo | H11: =H25+H45+H53 -> 100
A13: Area de conocimiento
C14: Tipo de Recurso | D14: Presentacion | E14: Video | F14: Lectura Explicativa | G14: Otros
C15: Tiempo Max | D15: 25 | E15: 10 | F15: 25 | G15: 25
C16: Tiempo Planificado | D16: 25 | E16: 10 | F16: 25 | G16: 20
A17: No. | B17: Tema | C17: Subtema
A18: 1 | B18: =IFERROR(__xludf.DUMMYFUNCTION("FILTER('Diseño Curricular'!D:D,'Diseño Curricular'!G:G=$B$3)"),"Introduccion a programacion en Visual Basic App ") -> Introduccion a programacion en Visual Basic App | C18: =IFERROR(__xludf.DUMMYFUNCTION("FILTER('Diseño Curricular'!E:E,'Diseño Curricular'!G:G=$B$3)"),"¿Qué visual basic aplication?") -> ¿Qué visual basic aplication? | D18: 5 | E18: 2 | F18: 4
A19: 2 | B19: =IFERROR(__xludf.DUMMYFUNCTION("""COMPUTED_VALUE"""),"Introduccion a programacion en Visual Basic App ") -> Introduccion a programacion en Visual Basic App | C19: =IFERROR(__xludf.DUMMYFUNCTION("""COMPUTED_VALUE"""),"¿Para qué visual basic aplication?") -> ¿Para qué visual basic aplication? | D19: 5 | E19: 2 | F19: 4
A20: 3 | B20: =IFERROR(__xludf.DUMMYFUNCTION("""COMPUTED_VALUE"""),"Introduccion a programacion en Visual Basic App ") -> Introduccion a programacion en Visual Basic App | C20: =IFERROR(__xludf.DUMMYFUNCTION("""COMPUTED_VALUE"""),"Variables y tipos de variables") -> Variables y tipos de variables | D20: 5 | E20: 2 | F20: 4
A21: 4 | B21: =IFERROR(__xludf.DUMMYFUNCTION("""COMPUTED_VALUE"""),"Introduccion a programacion en Visual Basic App ") -> Introduccion a programacion en Visual Basic App | C21: =IFERROR(__xludf.DUMMYFUNCTION("""COMPUTED_VALUE"""),"Que es la logica booleana") -> Que es la logica booleana | D21: 5 | E21: 2 | F21: 4
A22: 5 | B22: =IFERROR(__xludf.DUMMYFUNCTION("""COMPUTED_VALUE"""),"Introduccion a programacion en Visual Basic App ") -> Introduccion a programacion en Visual Basic App | C22: =IFERROR(__xludf.DUMMYFUNCTION("""COMPUTED_VALUE"""),"Condicionales y estructuras de control") -> Condicionales y estructuras de control | D22: 5 | E22: 2 | F22: 4
A23: 6 | B23: =IFERROR(__xludf.DUMMYFUNCTION("""COMPUTED_VALUE"""),"Introduccion a programacion en Visual Basic App ") -> Introduccion a programacion en Visual Basic App | C23: =IFERROR(__xludf.DUMMYFUNCTION("""COMPUTED_VALUE"""),"Definicion de funciones, metodos y sus ambitos") -> Definicion de funciones, metodos y sus ambitos | F23: 4
A24: 7 | B24: =IFERROR(__xludf.DUMMYFUNCTION("""COMPUTED_VALUE"""),"Introduccion a programacion en Visual Basic App ") -> Introduccion a programacion en Visual Basic App | C24: =IFERROR(__xludf.DUMMYFUNCTION("""COMPUTED_VALUE"""),"Ejemplo práctico") -> Ejemplo práctico | G24: 20
G25: Sub total de tiempo | H25: =SUM(D16:G16) -> 80
A26: Marca con una x en recurso que planificas usar para impartir el conocimiento
A27: Otros : puedes modificarlo e indicar que recurso usarias por ejemplo simuladores
A29: Area de Habilidades
A30: Recordatorio
A31: Dentro de los 100 minutos de clase toma en cuenta incluir un tiempo para formar la habilidad del estudiante. Aprender haciendo.
A33: No. | B33: Tipo | C33: Ejercicio | D33: Practica | E33: Actividad | F33: Otros | G33: Cuestionario
B34: Tiempo Maximo | C34: 25 | D34: 25 | E34: 25 | F34: 25 | G34: 15
B35: Tiempo Planificado | G35: 15
B36: Ponderacion
B37: Competencia
A38: 1 | B38: Crea soluciones digitales utilizando entornos de programación visual y aplicaciones de ofimática con estrategias de automatización básica y diseño de bases de datos para resolver problemas reales de forma efectiva | G38: 5
A39: 2 | B39: Aplica conceptos fundamentales de programación mediante ejercicios prácticos y análisis de código, en entornos virtuales de laboratorio para desarrollar el pensamiento lógico y computacional | G39: 5
A40: 3 | B40: Diseña macros automatizadas en hojas de cálculo utilizando Visual Basic para Aplicaciones (VBA) mediante la implementación de funciones y ciclos condicionales con conexión a bases de datos para optimizar tareas repetitivas | G40: 5
A41: 4
A42: 5
A43: 6
A44: 7
G45: Sub total de tiempo | H45: =SUM(C35:G35) -> 15
A46: Marca con una x en recurso que planificas usar para impartir el conocimiento
A47: Otros : puedes modificarlo e indicar que recurso usarias por ejemplo exposiciones
A48: Cierre
...

Sheet S.10
A1: Curso | B1: ='Diseño Curricular'!B1 -> 90 - Programacion de Computadoras 1
A3: Semana | B3: 10
A5: Valores | B5: Responsabilidad: Cumplir con tareas y tiempos establecidos. Honestidad: Realizar trabajos propios sin copiar. Colaboración: Trabajar en equipo y ayudar a otros. Disciplina: Usar correctamente las herramientas tecnológicas. Creatividad: Buscar soluciones originales y prácticas.
A6: * Recuerda que las competencias tambien forman valores identifica el valor o valores que transmitiras esa semana
A8: Cronograma | B8: Para mantener la atención, es recomendable variar la dinámica de la clase cada cierto tiempo, integrando actividades como preguntas, ejercicios prácticos o discusiones en grupo. Esto es clave para la educación por competencias, ya que el aprendizaje debe ser activo y aplicado.
A11: Ponderacion | B11: 5 | F11: Total de tiempo | H11: =H25+H45+H53 -> 100
A13: Area de conocimiento
C14: Tipo de Recurso | D14: Presentacion | E14: Video | F14: Lectura Explicativa | G14: Otros
C15: Tiempo Max | D15: 25 | E15: 10 | F15: 25 | G15: 25
C16: Tiempo Planificado | D16: 25 | E16: 10 | F16: 25 | G16: 25
A17: No. | B17: Tema | C17: Subtema
A18: 1 | B18: =IFERROR(__xludf.DUMMYFUNCTION("FILTER('Diseño Curricular'!D:D,'Diseño Curricular'!G:G=$B$3)"),"Integracion de Acces con Excel por VBA") -> Integracion de Acces con Excel por VBA | C18: =IFERROR(__xludf.DUMMYFUNCTION("FILTER('Diseño Curricular'!E:E,'Diseño Curricular'!G:G=$B$3)"),"Comunicion entre aplicaciones de microsoft") -> Comunicion entre aplicaciones de microsoft | D18: 5 | E18: 2 | F18: 4
A19: 2 | B19: =IFERROR(__xludf.DUMMYFUNCTION("""COMPUTED_VALUE"""),"Integracion de Acces con Excel por VBA") -> Integracion de Acces con Excel por VBA | C19: =IFERROR(__xludf.DUMMYFUNCTION("""COMPUTED_VALUE"""),"Arq. Cliente servidor.") -> Arq. Cliente servidor. | D19: 5 | E19: 2 | F19: 4
A20: 3 | B20: =IFERROR(__xludf.DUMMYFUNCTION("""COMPUTED_VALUE"""),"Integracion de Acces con Excel por VBA") -> Integracion de Acces con Excel por VBA | C20: =IFERROR(__xludf.DUMMYFUNCTION("""COMPUTED_VALUE"""),"Lectura conexion Excel y access") -> Lectura conexion Excel y access | D20: 5 | E20: 2 | F20: 4
A21: 4 | B21: =IFERROR(__xludf.DUMMYFUNCTION("""COMPUTED_VALUE"""),"Integracion de Acces con Excel por VBA") -> Integracion de Acces con Excel por VBA | C21: =IFERROR(__xludf.DUMMYFUNCTION("""COMPUTED_VALUE"""),"Gestion de librerias") -> Gestion de librerias | D21: 5 | E21: 2 | F21: 4
A22: 5 | B22: =IFERROR(__xludf.DUMMYFUNCTION("""COMPUTED_VALUE"""),"Integracion de Acces con Excel por VBA") -> Integracion de Acces con Excel por VBA | C22: =IFERROR(__xludf.DUMMYFUNCTION("""COMPUTED_VALUE"""),"Ejmplo Practico de conexion ") -> Ejmplo Practico de conexion | D22: 5 | E22: 2 | F22: 4
A23: 6 | B23: =IFERROR(__xludf.DUMMYFUNCTION("""COMPUTED_VALUE"""),"Integracion de Acces con Excel por VBA") -> Integracion de Acces con Excel por VBA | C23: =IFERROR(__xludf.DUMMYFUNCTION("""COMPUTED_VALUE"""),"Conferencia del Curso") -> Conferencia del Curso | F23: 4
A24: 7 | B24: =IFERROR(__xludf.DUMMYFUNCTION("""COMPUTED_VALUE"""),"Integracion de Acces con Excel por VBA") -> Integracion de Acces con Excel por VBA | C24: =IFERROR(__xludf.DUMMYFUNCTION("""COMPUTED_VALUE"""),"Cuestionario sobre Conferencia") -> Cuestionario sobre Conferencia | G24: 25
G25: Sub total de tiempo | H25: =SUM(D16:G16) -> 85
A26: Marca con una x en recurso que planificas usar para impartir el conocimiento
A27: Otros : puedes modificarlo e indicar que recurso usarias por ejemplo simuladores
A29: Area de Habilidades
A30: Recordatorio
A31: Dentro de los 100 minutos de clase toma en cuenta incluir un tiempo para formar la habilidad del estudiante. Aprender haciendo.
A33: No. | B33: Tipo | C33: Ejercicio | D33: Practica | E33: Actividad | F33: Otros | G33: Cuestionario
B34: Tiempo Maximo | C34: 25 | D34: 25 | E34: 25 | F34: 25 | G34: 15
B35: Tiempo Planificado | G35: 15
B36: Ponderacion
B37: Competencia
A38: 1 | B38: Aplica conceptos fundamentales de programación mediante ejercicios prácticos y análisis de código, en entornos virtuales de laboratorio para desarrollar el pensamiento lógico y computacional | G38: 10
A39: 2 | B39: Evalúa resultados obtenidos en procesos de programación y ofimática utilizando pruebas de funcionamiento, revisión crítica de errores y optimización de recursos bajo criterios de funcionalidad y eficiencia | G39: 5
A40: 3
A41: 4
A42: 5
A43: 6
A44: 7
G45: Sub total de tiempo | H45: =SUM(C35:G35) -> 15
A46: Marca con una x en recurso que planificas usar para impartir el conocimiento
A47: Otros : puedes modificarlo e indicar que recurso usarias por ejemplo exposiciones
A48: Cierre
...

Sheet S.11
A1: Curso | B1: ='Diseño Curricular'!B1 -> 90 - Programacion de Computadoras 1
A3: Semana | B3: 11
A5: Valores | B5: Responsabilidad: Cumplir con tareas y tiempos establecidos. Honestidad: Realizar trabajos propios sin copiar. Colaboración: Trabajar en equipo y ayudar a otros. Disciplina: Usar correctamente las herramientas tecnológicas. Creatividad: Buscar soluciones originales y prácticas.
A6: * Recuerda que las competencias tambien forman valores identifica el valor o valores que transmitiras esa semana
A8: Cronograma | B8: Para mantener la atención, es recomendable variar la dinámica de la clase cada cierto tiempo, integrando actividades como preguntas, ejercicios prácticos o discusiones en grupo. Esto es clave para la educación por competencias, ya que el aprendizaje debe ser activo y aplicado.
A11: Ponderacion | B11: 0 | F11: Total de tiempo | H11: =H25+H45+H53 -> 100
A13: Area de conocimiento
C14: Tipo de Recurso | D14: Presentacion | E14: Video | F14: Lectura Explicativa | G14: Otros
C15: Tiempo Max | D15: 25 | E15: 10 | F15: 25 | G15: 25
C16: Tiempo Planificado | D16: 25 | E16: 10 | F16: 25 | G16: 0
A17: No. | B17: Tema | C17: Subtema
A18: 1 | B18: =IFERROR(__xludf.DUMMYFUNCTION("FILTER('Diseño Curricular'!D:D,'Diseño Curricular'!G:G=$B$3)"),"Herramientas de Power BI") -> Herramientas de Power BI | C18: =IFERROR(__xludf.DUMMYFUNCTION("FILTER('Diseño Curricular'!E:E,'Diseño Curricular'!G:G=$B$3)"),"¿Qué es Power BI?") -> ¿Qué es Power BI? | D18: 5 | E18: 2 | F18: 4
A19: 2 | B19: =IFERROR(__xludf.DUMMYFUNCTION("""COMPUTED_VALUE"""),"Herramientas de Power BI") -> Herramientas de Power BI | C19: =IFERROR(__xludf.DUMMYFUNCTION("""COMPUTED_VALUE"""),"Conexión con orígenes de datos (Excel/Access)") -> Conexión con orígenes de datos (Excel/Access) | D19: 5 | E19: 2 | F19: 4
A20: 3 | B20: =IFERROR(__xludf.DUMMYFUNCTION("""COMPUTED_VALUE"""),"Herramientas de Power BI") -> Herramientas de Power BI | C20: =IFERROR(__xludf.DUMMYFUNCTION("""COMPUTED_VALUE"""),"Visualizaciones básicas") -> Visualizaciones básicas | D20: 5 | E20: 2 | F20: 4
A21: 4 | B21: =IFERROR(__xludf.DUMMYFUNCTION("""COMPUTED_VALUE"""),"Herramientas de Power BI") -> Herramientas de Power BI | C21: =IFERROR(__xludf.DUMMYFUNCTION("""COMPUTED_VALUE"""),"Creación de informes interactivos") -> Creación de informes interactivos | D21: 5 | E21: 2 | F21: 4
A22: 5 | B22: =IFERROR(__xludf.DUMMYFUNCTION("""COMPUTED_VALUE"""),"Herramientas de Power BI") -> Herramientas de Power BI | C22: =IFERROR(__xludf.DUMMYFUNCTION("""COMPUTED_VALUE"""),"Conexiones con access") -> Conexiones con access | D22: 5 | E22: 2 | F22: 4
A23: 6 | B23: =IFERROR(__xludf.DUMMYFUNCTION("""COMPUTED_VALUE"""),"Herramientas de Power BI") -> Herramientas de Power BI | C23: =IFERROR(__xludf.DUMMYFUNCTION("""COMPUTED_VALUE"""),"Creacion de reportes") -> Creacion de reportes | F23: 4
A24: 7 | B24: =IFERROR(__xludf.DUMMYFUNCTION("""COMPUTED_VALUE"""),"Herramientas de Power BI") -> Herramientas de Power BI | C24: =IFERROR(__xludf.DUMMYFUNCTION("""COMPUTED_VALUE"""),"Ejemplo práctico") -> Ejemplo práctico
G25: Sub total de tiempo | H25: =SUM(D16:G16) -> 60
A26: Marca con una x en recurso que planificas usar para impartir el conocimiento
A27: Otros : puedes modificarlo e indicar que recurso usarias por ejemplo simuladores
A29: Area de Habilidades
A30: Recordatorio
A31: Dentro de los 100 minutos de clase toma en cuenta incluir un tiempo para formar la habilidad del estudiante. Aprender haciendo.
A33: No. | B33: Tipo | C33: Ejercicio | D33: Practica | E33: Actividad | F33: Otros | G33: Cuestionario
B34: Tiempo Maximo | C34: 25 | D34: 25 | E34: 25 | F34: 25 | G34: 15
B35: Tiempo Planificado | E35: 15 | G35: 15
B36: Ponderacion
B37: Competencia
A38: 1 | B38: Evalúa resultados obtenidos en procesos de programación y ofimática utilizando pruebas de funcionamiento, revisión crítica de errores y optimización de recursos bajo criterios de funcionalidad y eficiencia | E38: 5 | G38: 10
A39: 2 | B39: Crea soluciones digitales utilizando entornos de programación visual y aplicaciones de ofimática con estrategias de automatización básica y diseño de bases de datos para resolver problemas reales de forma efectiva | E39: 10 | G39: 5
A40: 3
A41: 4
A42: 5
A43: 6
A44: 7
G45: Sub total de tiempo | H45: =SUM(C35:G35) -> 30
A46: Marca con una x en recurso que planificas usar para impartir el conocimiento
A47: Otros : puedes modificarlo e indicar que recurso usarias por ejemplo exposiciones
A48: Cierre
...

Sheet Metadata
A1: =IFERROR(__xludf.DUMMYFUNCTION("IMPORTRANGE(""1--DGkU5oDw3gpAa_rQkeu1olWCf2iv8Pm7BNjqiyiuY"", ""Listado Cursos!H:J"")"),"Codigo - Nombre") -> Codigo - Nombre | B1: =IFERROR(__xludf.DUMMYFUNCTION("""COMPUTED_VALUE"""),"Diseño Curricular") -> Diseño Curricular | C1: =IFERROR(__xludf.DUMMYFUNCTION("""COMPUTED_VALUE"""),"Analisis de contexto") -> Analisis de contexto | D1: =IFERROR(__xludf.DUMMYFUNCTION("IMPORTRANGE(VLOOKUP('Diseño Curricular'!B1,A:C,3,FALSE), ""Competencias!B21:J35"")"),"No") -> No | E1: =IFERROR(__xludf.DUMMYFUNCTION("""COMPUTED_VALUE"""),"Tipo") -> Tipo | F1: =IFERROR(__xludf.DUMMYFUNCTION("""COMPUTED_VALUE"""),"Verbo en Presente") -> Verbo en Presente | G1: =IFERROR(__xludf.DUMMYFUNCTION("""COMPUTED_VALUE"""),"Objeto de la acción") -> Objeto de la acción | I1: =IFERROR(__xludf.DUMMYFUNCTION("""COMPUTED_VALUE"""),"[Palabras conectoreas] Herramientas o metodología") -> [Palabras conectoreas] Herramientas o metodología | J1: =IFERROR(__xludf.DUMMYFUNCTION("""COMPUTED_VALUE"""),"[Palabras conectoreas] Condiciones específicas") -> [Palabras conectoreas] Condiciones específicas | L1: =IFERROR(__xludf.DUMMYFUNCTION("""COMPUTED_VALUE"""),"Nivel") -> Nivel
A2: =IFERROR(__xludf.DUMMYFUNCTION("""COMPUTED_VALUE"""),"17 - Área Social Humanística 1") -> 17 - Área Social Humanística 1 | D2: =IFERROR(__xludf.DUMMYFUNCTION("""COMPUTED_VALUE"""),1.0) -> 1 | E2: =IFERROR(__xludf.DUMMYFUNCTION("""COMPUTED_VALUE"""),"Especifica") -> Especifica | F2: =IFERROR(__xludf.DUMMYFUNCTION("""COMPUTED_VALUE"""),"Aplica") -> Aplica | G2: =IFERROR(__xludf.DUMMYFUNCTION("""COMPUTED_VALUE"""),"conceptos fundamentales de programación") -> conceptos fundamentales de programación | I2: =IFERROR(__xludf.DUMMYFUNCTION("""COMPUTED_VALUE"""),"mediante ejercicios prácticos y análisis de código, en entornos virtuales de laboratorio") -> mediante ejercicios prácticos y análisis de código, en entornos virtuales de laboratorio | J2: =IFERROR(__xludf.DUMMYFUNCTION("""COMPUTED_VALUE"""),"para desarrollar el pensamiento lógico y computacional") -> para desarrollar el pensamiento lógico y computacional | L2: =IFERROR(__xludf.DUMMYFUNCTION("""COMPUTED_VALUE"""),"Aplicar") -> Aplicar
A3: =IFERROR(__xludf.DUMMYFUNCTION("""COMPUTED_VALUE"""),"101 - Área Matemática Básica 1") -> 101 - Área Matemática Básica 1 | E3: =IFERROR(__xludf.DUMMYFUNCTION("""COMPUTED_VALUE"""),"Aplica conceptos fundamentales de programación mediante ejercicios prácticos y análisis de código, en entornos virtuales de laboratorio para desarrollar el pensamiento lógico y computacional ") -> Aplica conceptos fundamentales de programación mediante ejercicios prácticos y análisis de código, en entornos virtuales de laboratorio para desarrollar el pensamiento lógico y computacional
A4: =IFERROR(__xludf.DUMMYFUNCTION("""COMPUTED_VALUE"""),"5 - Técnicas de Estudio e Investigación") -> 5 - Técnicas de Estudio e Investigación | D4: =IFERROR(__xludf.DUMMYFUNCTION("""COMPUTED_VALUE"""),2.0) -> 2 | E4: =IFERROR(__xludf.DUMMYFUNCTION("""COMPUTED_VALUE"""),"General") -> General | F4: =IFERROR(__xludf.DUMMYFUNCTION("""COMPUTED_VALUE"""),"Integra ") -> Integra | G4: =IFERROR(__xludf.DUMMYFUNCTION("""COMPUTED_VALUE"""),"herramientas de ofimática ") -> herramientas de ofimática | I4: =IFERROR(__xludf.DUMMYFUNCTION("""COMPUTED_VALUE"""),"como Word, Excel, PowerPoint y Access") -> como Word, Excel, PowerPoint y Access | J4: =IFERROR(__xludf.DUMMYFUNCTION("""COMPUTED_VALUE"""),"en la resolución de tareas y proyectos con base en situaciones académicas y laborales comunes") -> en la resolución de tareas y proyectos con base en situaciones académicas y laborales comunes | L4: =IFERROR(__xludf.DUMMYFUNCTION("""COMPUTED_VALUE"""),"Analizar") -> Analizar
A5: =IFERROR(__xludf.DUMMYFUNCTION("""COMPUTED_VALUE"""),"39 - Deportes 1") -> 39 - Deportes 1 | E5: =IFERROR(__xludf.DUMMYFUNCTION("""COMPUTED_VALUE"""),"Integra herramientas de ofimática como Word, Excel, PowerPoint y Access en la resolución de tareas y proyectos con base en situaciones académicas y laborales comunes ") -> Integra herramientas de ofimática como Word, Excel, PowerPoint y Access en la resolución de tareas y proyectos con base en situaciones académicas y laborales comunes
